Workbook

Sheet Resumo
A1: Mesários — 1º turno 04/10/2026 · RDS Hall 2 · presença, situação em 30/09/2026 13:42
A3: Total de mesários | B3: =COUNTA(Mesarios!D2:D112) -> 111
A4: Presentes (SIM) | B4: =COUNTIF(Mesarios!$E$2:$E$112,"SIM") -> 82
A5: Ausentes (NAO) | B5: =COUNTIF(Mesarios!$E$2:$E$112,"NAO") -> 13
A6: Marcados "0006/2026" | B6: =COUNTIF(Mesarios!$E$2:$E$112,"0006/2026") -> 13
A7: Sem registro ("-") | B7: =COUNTIF(Mesarios!$E$2:$E$112,"-") -> 3
A8: Não presentes (NAO + 0006/2026 + "-") | B8: =B5+B6+B7 -> 29
A9: Conferência: soma das 4 categorias = total | B9: =IF(B4+B5+B6+B7=B3,"OK","DIVERGE") -> OK
A10: Seções (mesas) | B10: =COUNTA('Por secao'!A2:A29) -> 28
A11: Mesas com os 4 presentes | B11: =COUNTIF('Por secao'!G2:G29,4) -> 15
A12: Mesas com só 3 presentes | B12: =COUNTIF('Por secao'!G2:G29,3) -> 4
A13: Mesas com 2 ou menos presentes | B13: =COUNTIF('Por secao'!G2:G29,"<=2") -> 9
A14: Mesas com só 3 designados | B14: =COUNTIF('Por secao'!B2:B29,3) -> 1
A15: Mesas sem Presidente designado | B15: ='Por secao'!C30 -> 0
A16: Nota | B16: A coluna "Situação" (Confirmado / Sem resposta / Pedido de dispensa) do relatório Elo/Convoca+ de 30/09 foi substituída na aba Mesarios pela coluna "Presença" (SIM / NAO / 0006/2026 / -). As contagens acima e na aba "Por secao" passaram a ler essa coluna. Totais do PDF original: Total 111 · Confirmados 98 · Sem resposta 12 · Pedido de dispensa 1.
A18: Comparecimento — BUs de 04/10/2026
A19: Comparecimento efetivo (28 BUs) | B19: ='Por secao'!Q30 -> 8417
A20: Comparecimento esperado (base B) | B20: ='Por secao'!N30 -> 11499
A21: Efetivo / esperado | B21: ='Por secao'!Q30/'Por secao'!N30 -> 0.73197669
A22: Taxa de comparecimento (efetivo / aptos no BU) | B22: ='Por secao'!S30 -> 0.50340909
A23: Urna mais movimentada (seção) | B23: =INDEX('Por secao'!A2:A29,MATCH(1,'Por secao'!V2:V29,0)) -> 3315

Sheet Mesarios
A1: Seção | B1: Função | C1: E-mail | D1: Nome | E1: Presença | F1: Chave (auxiliar)
A2: 511 | B2: Presidente | C2: Felipegustavo.ie@outlook.com | D2: FELIPE PEREIRA DE SOUZA GUSTAVO | E2: SIM | F2: =A2&"|"&B2 -> 511|Presidente
A3: 511 | B3: 1º Mesário | C3: Ericcount19@hotmail.com | D3: ERIC DA SILVA MEDEIROS | E3: SIM | F3: =A3&"|"&B3 -> 511|1º Mesário
A4: 511 | B4: 2º Mesário | C4: ludmilamaiamaciel@gmail.com | D4: LUDMILA MAIA MACIEL | E4: SIM | F4: =A4&"|"&B4 -> 511|2º Mesário
A5: 511 | B5: 1º Secretário | C5: beabertocco@gmail.com | D5: BEATRIZ CARACANHA BERTOCCO | E5: SIM | F5: =A5&"|"&B5 -> 511|1º Secretário
A6: 512 | B6: Presidente | C6: anaclaudiamazurok@gmail.com | D6: ANA CLAUDIA MAZUROK | E6: NAO | F6: =A6&"|"&B6 -> 512|Presidente
A7: 512 | B7: 1º Mesário | C7: caiorossiter@gmail.com | D7: CAIO CESAR ROSSITER | E7: SIM | F7: =A7&"|"&B7 -> 512|1º Mesário
A8: 512 | B8: 2º Mesário | C8: camilamouramartins1987@gmail.com | D8: CAMILA MOURA MARTINS | E8: SIM | F8: =A8&"|"&B8 -> 512|2º Mesário
A9: 512 | B9: 1º Secretário | C9: tbbfelix@gmail.com | D9: THAISA BERNARDES BUENO FELIX | E9: SIM | F9: =A9&"|"&B9 -> 512|1º Secretário
A10: 513 | B10: Presidente | C10: bianca.goulart@itamaraty.gov.br | D10: BIANCA ARAGONE RODRIGUES GOULART | E10: SIM | F10: =A10&"|"&B10 -> 513|Presidente
A11: 513 | B11: 1º Mesário | C11: Luizsmania1@gmail.com | D11: LUIZ HENRIQUE DE SOUSA SMANIA | E11: SIM | F11: =A11&"|"&B11 -> 513|1º Mesário
A12: 513 | B12: 2º Mesário | C12: isabelabattisti@gmail.com | D12: ISABELA FERNANDES BATTISTI PETRIS | E12: SIM | F12: =A12&"|"&B12 -> 513|2º Mesário
A13: 513 | B13: 1º Secretário | C13: aline.barros@outlook.com | D13: ALINE BARROS DE LIRA | E13: NAO | F13: =A13&"|"&B13 -> 513|1º Secretário
... A80: 3309 | B80: 2º Mesário | C80: luamdmoreira@gmail.com | D80: LUAM DUANE ANDRADE MOREIRA | E80: SIM | F80: =A80&"|"&B80 -> 3309|2º Mesário
A81: 3309 | B81: 1º Secretário | D81: SARA SOBRAL DIAS | E81: SIM | F81: =A81&"|"&B81 -> 3309|1º Secretário
A82: 3311 | B82: Presidente | C82: saradias1@gmail.com | D82: FLAVIA NASCIMENTO DE SOUZA | E82: - | F82: =A82&"|"&B82 -> 3311|Presidente
A83: 3311 | B83: 1º Mesário | C83: rodrigoerasmobarboza@gmail.com | D83: RODRIGO ERASMO BARBOZA | E83: - | F83: =A83&"|"&B83 -> 3311|1º Mesário
A84: 3311 | B84: 2º Mesário | C84: ednaldo283@gmail.com | D84: EDNALDO AZEVEDO DE NORONHA | E84: 0006/2026 | F84: =A84&"|"&B84 -> 3311|2º Mesário
A85: 3311 | B85: 1º Secretário | C85: thaisterencio@hotmail.com | D85: THAÍS TERÊNCIO PEREIRA | E85: 0006/2026 | F85: =A85&"|"&B85 -> 3311|1º Secretário
A86: 3313 | B86: Presidente | C86: vanessa.barbosa@itamaraty.gov.br | D86: VANESSA ROCHA BARBOSA BARBALHO | E86: SIM | F86: =A86&"|"&B86 -> 3313|Presidente
A87: 3313 | B87: 1º Mesário | C87: leilarosaria@yahoo.com.br | D87: LEILA ROSARIA LIOTTA | E87: SIM | F87: =A87&"|"&B87 -> 3313|1º Mesário
A88: 3313 | B88: 2º Mesário | C88: danielpessoa.cardeal@gmail.com | D88: DANIEL PESSOA CARDEAL | E88: SIM | F88: =A88&"|"&B88 -> 3313|2º Mesário
A89: 3313 | B89: 1º Secretário | C89: sandro.cunha2008@gmail.com | D89: SANDRO CUNHA DA SILVA | E89: SIM | F89: =A89&"|"&B89 -> 3313|1º Secretário
A90: 3315 | B90: Presidente | C90: jair.correia@itamaraty.gov.br | D90: JAIR DE ASSUNÇÃO CORREIA FILHO | E90: SIM | F90: =A90&"|"&B90 -> 3315|Presidente
A91: 3315 | B91: 1º Mesário | C91: alaf.ribeiro.965@gmail.com | D91: HUMBERTO ALAF RIBEIRO MARTINS | E91: SIM | F91: =A91&"|"&B91 -> 3315|1º Mesário
A92: 3315 | B92: 2º Mesário | C92: jmendes_mendes@live.com | D92: JESSICA MENDES | E92: SIM | F92: =A92&"|"&B92 -> 3315|2º Mesário
A93: 3315 | B93: 1º Secretário | C93: alanegerssicaandrade@gmail.com | D93: ALANE GERSSICA DE ANDRADE DO NASCIMENTO | E93: SIM | F93: =A93&"|"&B93 -> 3315|1º Secretário
... A95: 3322 | B95: 1º Mesário | C95: alves.brenda65@gmail.com | D95: BRENDA ALVES DA SILVA | E95: NAO | F95: =A95&"|"&B95 -> 3322|1º Mesário
A96: 3322 | B96: 2º Mesário | D96: RUDINEI CORDEIRO | E96: NAO | F96: =A96&"|"&B96 -> 3322|2º Mesário
A97: 3322 | B97: 1º Secretário | C97: nadiaweber12@yahoo.com.br | D97: NADIA FERNANDA WEBER | E97: SIM | F97: =A97&"|"&B97 -> 3322|1º Secretário
A98: 3442 | B98: Presidente | C98: danferrareis@hotmail.com | D98: DANILO ANDERSON FERRAREIS | E98: SIM | F98: =A98&"|"&B98 -> 3442|Presidente
A99: 3442 | B99: 1º Mesário | C99: tstrhgt@gmail.com | D99: GUSTAVO DAVID LOPES | E99: NAO | F99: =A99&"|"&B99 -> 3442|1º Mesário
A100: 3442 | B100: 2º Mesário | C100: tifanyazuma@outlook.com | D100: TIFANY AZUMA TROMBINO XANDÚ | E100: NAO | F100: =A100&"|"&B100 -> 3442|2º Mesário
A101: 3442 | B101: 1º Secretário | C101: Nicolicamilo@hotmail.com | D101: NICOLI CAMPOS CAMILO | E101: SIM | F101: =A101&"|"&B101 -> 3442|1º Secretário
A102: 3688 | B102: Presidente | C102: juliana.nunes2010@hotmail.com | D102: JULIANA NUNES DE MENDONÇA | E102: SIM | F102: =A102&"|"&B102 -> 3688|Presidente
A103: 3688 | B103: 1º Mesário | C103: laurabvieiras@gmail.com | D103: LAURA BEATRIZ VIEIRA SANTOS | E103: NAO | F103: =A103&"|"&B103 -> 3688|1º Mesário
A104: 3688 | B104: 2º Mesário | D104: DIEGO MENDANHA DA SILVA MAIA | E104: SIM | F104: =A104&"|"&B104 -> 3688|2º Mesário
A105: 3688 | B105: 1º Secretário | C105: lauroramos@outlook.com | D105: LAURO SILVA RAMOS | E105: NAO | F105: =A105&"|"&B105 -> 3688|1º Secretário
A106: 3832 | B106: Presidente | C106: sem contato | D106: GILMAR BARBOSA DE SOUZA | E106: SIM | F106: =A106&"|"&B106 -> 3832|Presidente
A107: 3832 | B107: 1º Mesário | C107: marinacoutor@gmail.com | D107: MARINA RODRIGUES COUTO | E107: SIM | F107: =A107&"|"&B107 -> 3832|1º Mesário
...

Sheet Presenca por secao
A1: Seção | B1: Presidente | C1: Pres. | D1: 1º Mesário | E1: Pres. | F1: 2º Mesário | G1: Pres. | H1: 1º Secretário | I1: Pres. | J1: Presentes | K1: Ausentes | L1: Outros | M1: Alerta | N1: Eleitores esperados | O1: Faixa
A2: ='Por secao'!A2 -> 511 | B2: =IFERROR(INDEX(Mesarios!$D$2:$D$112,MATCH($A2&"|"&B$1,Mesarios!$F$2:$F$112,0)),"VAGO") -> FELIPE PEREIRA DE SOUZA GUSTAVO | C2: =IFERROR(INDEX(Mesarios!$E$2:$E$112,MATCH($A2&"|"&B$1,Mesarios!$F$2:$F$112,0)),"VAGO") -> SIM | D2: =IFERROR(INDEX(Mesarios!$D$2:$D$112,MATCH($A2&"|"&D$1,Mesarios!$F$2:$F$112,0)),"VAGO") -> ERIC DA SILVA MEDEIROS | E2: =IFERROR(INDEX(Mesarios!$E$2:$E$112,MATCH($A2&"|"&D$1,Mesarios!$F$2:$F$112,0)),"VAGO") -> SIM | F2: =IFERROR(INDEX(Mesarios!$D$2:$D$112,MATCH($A2&"|"&F$1,Mesarios!$F$2:$F$112,0)),"VAGO") -> LUDMILA MAIA MACIEL | G2: =IFERROR(INDEX(Mesarios!$E$2:$E$112,MATCH($A2&"|"&F$1,Mesarios!$F$2:$F$112,0)),"VAGO") -> SIM | H2: =IFERROR(INDEX(Mesarios!$D$2:$D$112,MATCH($A2&"|"&H$1,Mesarios!$F$2:$F$112,0)),"VAGO") -> BEATRIZ CARACANHA BERTOCCO | I2: =IFERROR(INDEX(Mesarios!$E$2:$E$112,MATCH($A2&"|"&H$1,Mesarios!$F$2:$F$112,0)),"VAGO") -> SIM | J2: =COUNTIF(C2:I2,"SIM") -> 4 | K2: =COUNTIF(C2:I2,"NAO") -> 0 | L2: =COUNTIF(C2:I2,"0006/2026")+COUNTIF(C2:I2,"-") -> 0 | M2: =IF(J2>=4,"Mesa completa",IF(J2=3,"Falta 1","ATENÇÃO: só "&J2&" presentes")) -> Mesa completa | N2: ='Por secao'!N2 -> 375 | O2: ='Por secao'!O2 -> Baixo
A3: ='Por secao'!A3 -> 512 | B3: =IFERROR(INDEX(Mesarios!$D$2:$D$112,MATCH($A3&"|"&B$1,Mesarios!$F$2:$F$112,0)),"VAGO") -> ANA CLAUDIA MAZUROK | C3: =IFERROR(INDEX(Mesarios!$E$2:$E$112,MATCH($A3&"|"&B$1,Mesarios!$F$2:$F$112,0)),"VAGO") -> NAO | D3: =IFERROR(INDEX(Mesarios!$D$2:$D$112,MATCH($A3&"|"&D$1,Mesarios!$F$2:$F$112,0)),"VAGO") -> CAIO CESAR ROSSITER | E3: =IFERROR(INDEX(Mesarios!$E$2:$E$112,MATCH($A3&"|"&D$1,Mesarios!$F$2:$F$112,0)),"VAGO") -> SIM | F3: =IFERROR(INDEX(Mesarios!$D$2:$D$112,MATCH($A3&"|"&F$1,Mesarios!$F$2:$F$112,0)),"VAGO") -> CAMILA MOURA MARTINS | G3: =IFERROR(INDEX(Mesarios!$E$2:$E$112,MATCH($A3&"|"&F$1,Mesarios!$F$2:$F$112,0)),"VAGO") -> SIM | H3: =IFERROR(INDEX(Mesarios!$D$2:$D$112,MATCH($A3&"|"&H$1,Mesarios!$F$2:$F$112,0)),"VAGO") -> THAISA BERNARDES BUENO FELIX | I3: =IFERROR(INDEX(Mesarios!$E$2:$E$112,MATCH($A3&"|"&H$1,Mesarios!$F$2:$F$112,0)),"VAGO") -> SIM | J3: =COUNTIF(C3:I3,"SIM") -> 3 | K3: =COUNTIF(C3:I3,"NAO") -> 1 | L3: =COUNTIF(C3:I3,"0006/2026")+COUNTIF(C3:I3,"-") -> 0 | M3: =IF(J3>=4,"Mesa completa",IF(J3=3,"Falta 1","ATENÇÃO: só "&J3&" presentes")) -> Falta 1 | N3: ='Por secao'!N3 -> 355 | O3: ='Por secao'!O3 -> Baixo
A4: ='Por secao'!A4 -> 513 | B4: =IFERROR(INDEX(Mesarios!$D$2:$D$112,MATCH($A4&"|"&B$1,Mesarios!$F$2:$F$112,0)),"VAGO") -> BIANCA ARAGONE RODRIGUES GOULART | C4: =IFERROR(INDEX(Mesarios!$E$2:$E$112,MATCH($A4&"|"&B$1,Mesarios!$F$2:$F$112,0)),"VAGO") -> SIM | D4: =IFERROR(INDEX(Mesarios!$D$2:$D$112,MATCH($A4&"|"&D$1,Mesarios!$F$2:$F$112,0)),"VAGO") -> LUIZ HENRIQUE DE SOUSA SMANIA | E4: =IFERROR(INDEX(Mesarios!$E$2:$E$112,MATCH($A4&"|"&D$1,Mesarios!$F$2:$F$112,0)),"VAGO") -> SIM | F4: =IFERROR(INDEX(Mesarios!$D$2:$D$112,MATCH($A4&"|"&F$1,Mesarios!$F$2:$F$112,0)),"VAGO") -> ISABELA FERNANDES BATTISTI PETRIS | G4: =IFERROR(INDEX(Mesarios!$E$2:$E$112,MATCH($A4&"|"&F$1,Mesarios!$F$2:$F$112,0)),"VAGO") -> SIM | H4: =IFERROR(INDEX(Mesarios!$D$2:$D$112,MATCH($A4&"|"&H$1,Mesarios!$F$2:$F$112,0)),"VAGO") -> ALINE BARROS DE LIRA | I4: =IFERROR(INDEX(Mesarios!$E$2:$E$112,MATCH($A4&"|"&H$1,Mesarios!$F$2:$F$112,0)),"VAGO") -> NAO | J4: =COUNTIF(C4:I4,"SIM") -> 3 | K4: =COUNTIF(C4:I4,"NAO") -> 1 | L4: =COUNTIF(C4:I4,"0006/2026")+COUNTIF(C4:I4,"-") -> 0 | M4: =IF(J4>=4,"Mesa completa",IF(J4=3,"Falta 1","ATENÇÃO: só "&J4&" presentes")) -> Falta 1 | N4: ='Por secao'!N4 -> 351 | O4: ='Por secao'!O4 -> Baixo
A5: ='Por secao'!A5 -> 517 | B5: =IFERROR(INDEX(Mesarios!$D$2:$D$112,MATCH($A5&"|"&B$1,Mesarios!$F$2:$F$112,0)),"VAGO") -> DAIANE LEAL GOMES | C5: =IFERROR(INDEX(Mesarios!$E$2:$E$112,MATCH($A5&"|"&B$1,Mesarios!$F$2:$F$112,0)),"VAGO") -> SIM | D5: =IFERROR(INDEX(Mesarios!$D$2:$D$112,MATCH($A5&"|"&D$1,Mesarios!$F$2:$F$112,0)),"VAGO") -> CINTHIA RODRIGUES DE ALMEIDA | E5: =IFERROR(INDEX(Mesarios!$E$2:$E$112,MATCH($A5&"|"&D$1,Mesarios!$F$2:$F$112,0)),"VAGO") -> SIM | F5: =IFERROR(INDEX(Mesarios!$D$2:$D$112,MATCH($A5&"|"&F$1,Mesarios!$F$2:$F$112,0)),"VAGO") -> RAFAEL DRUMMOND RODRIGUES | G5: =IFERROR(INDEX(Mesarios!$E$2:$E$112,MATCH($A5&"|"&F$1,Mesarios!$F$2:$F$112,0)),"VAGO") -> SIM | H5: =IFERROR(INDEX(Mesarios!$D$2:$D$112,MATCH($A5&"|"&H$1,Mesarios!$F$2:$F$112,0)),"VAGO") -> MARIANA MACIEL DOS SANTOS SOUZA | I5: =IFERROR(INDEX(Mesarios!$E$2:$E$112,MATCH($A5&"|"&H$1,Mesarios!$F$2:$F$112,0)),"VAGO") -> SIM | J5: =COUNTIF(C5:I5,"SIM") -> 4 | K5: =COUNTIF(C5:I5,"NAO") -> 0 | L5: =COUNTIF(C5:I5,"0006/2026")+COUNTIF(C5:I5,"-") -> 0 | M5: =IF(J5>=4,"Mesa completa",IF(J5=3,"Falta 1","ATENÇÃO: só "&J5&" presentes")) -> Mesa completa | N5: ='Por secao'!N5 -> 348 | O5: ='Por secao'!O5 -> Baixo
A6: ='Por secao'!A6 -> 1160 | B6: =IFERROR(INDEX(Mesarios!$D$2:$D$112,MATCH($A6&"|"&B$1,Mesarios!$F$2:$F$112,0)),"VAGO") -> PAMELA NASCIMENTO DA SILVA | C6: =IFERROR(INDEX(Mesarios!$E$2:$E$112,MATCH($A6&"|"&B$1,Mesarios!$F$2:$F$112,0)),"VAGO") -> 0006/2026 | D6: =IFERROR(INDEX(Mesarios!$D$2:$D$112,MATCH($A6&"|"&D$1,Mesarios!$F$2:$F$112,0)),"VAGO") -> ARTHUR GRIZ FERREIRA | E6: =IFERROR(INDEX(Mesarios!$E$2:$E$112,MATCH($A6&"|"&D$1,Mesarios!$F$2:$F$112,0)),"VAGO") -> 0006/2026 | F6: =IFERROR(INDEX(Mesarios!$D$2:$D$112,MATCH($A6&"|"&F$1,Mesarios!$F$2:$F$112,0)),"VAGO") -> CRISLAINE DE SOUZA ALMEIDA | G6: =IFERROR(INDEX(Mesarios!$E$2:$E$112,MATCH($A6&"|"&F$1,Mesarios!$F$2:$F$112,0)),"VAGO") -> 0006/2026 | H6: =IFERROR(INDEX(Mesarios!$D$2:$D$112,MATCH($A6&"|"&H$1,Mesarios!$F$2:$F$112,0)),"VAGO") -> CINTIA DOS SANTOS | I6: =IFERROR(INDEX(Mesarios!$E$2:$E$112,MATCH($A6&"|"&H$1,Mesarios!$F$2:$F$112,0)),"VAGO") -> 0006/2026 | J6: =COUNTIF(C6:I6,"SIM") -> 0 | K6: =COUNTIF(C6:I6,"NAO") -> 0 | L6: =COUNTIF(C6:I6,"0006/2026")+COUNTIF(C6:I6,"-") -> 4 | M6: =IF(J6>=4,"Mesa completa",IF(J6=3,"Falta 1","ATENÇÃO: só "&J6&" presentes")) -> ATENÇÃO: só 0 presentes | N6: ='Por secao'!N6 -> 328 | O6: ='Por secao'!O6 -> Baixo
A7: ='Por secao'!A7 -> 1352 | B7: =IFERROR(INDEX(Mesarios!$D$2:$D$112,MATCH($A7&"|"&B$1,Mesarios!$F$2:$F$112,0)),"VAGO") -> NAYARA GIROTO MENDES | C7: =IFERROR(INDEX(Mesarios!$E$2:$E$112,MATCH($A7&"|"&B$1,Mesarios!$F$2:$F$112,0)),"VAGO") -> SIM | D7: =IFERROR(INDEX(Mesarios!$D$2:$D$112,MATCH($A7&"|"&D$1,Mesarios!$F$2:$F$112,0)),"VAGO") -> JESSICA DE OLIVEIRA | E7: =IFERROR(INDEX(Mesarios!$E$2:$E$112,MATCH($A7&"|"&D$1,Mesarios!$F$2:$F$112,0)),"VAGO") -> SIM | F7: =IFERROR(INDEX(Mesarios!$D$2:$D$112,MATCH($A7&"|"&F$1,Mesarios!$F$2:$F$112,0)),"VAGO") -> ANA PAULA DA SILVA ELIAS | G7: =IFERROR(INDEX(Mesarios!$E$2:$E$112,MATCH($A7&"|"&F$1,Mesarios!$F$2:$F$112,0)),"VAGO") -> SIM | H7: =IFERROR(INDEX(Mesarios!$D$2:$D$112,MATCH($A7&"|"&H$1,Mesarios!$F$2:$F$112,0)),"VAGO") -> DENER AUGUSTO SALES MACHADO | I7: =IFERROR(INDEX(Mesarios!$E$2:$E$112,MATCH($A7&"|"&H$1,Mesarios!$F$2:$F$112,0)),"VAGO") -> SIM | J7: =COUNTIF(C7:I7,"SIM") -> 4 | K7: =COUNTIF(C7:I7,"NAO") -> 0 | L7: =COUNTIF(C7:I7,"0006/2026")+COUNTIF(C7:I7,"-") -> 0 | M7: =IF(J7>=4,"Mesa completa",IF(J7=3,"Falta 1","ATENÇÃO: só "&J7&" presentes")) -> Mesa completa | N7: ='Por secao'!N7 -> 328 | O7: ='Por secao'!O7 -> Baixo
A8: ='Por secao'!A8 -> 3054 | B8: =IFERROR(INDEX(Mesarios!$D$2:$D$112,MATCH($A8&"|"&B$1,Mesarios!$F$2:$F$112,0)),"VAGO") -> FABIOLA CRISTIANE DA SILVA MALTA | C8: =IFERROR(INDEX(Mesarios!$E$2:$E$112,MATCH($A8&"|"&B$1,Mesarios!$F$2:$F$112,0)),"VAGO") -> SIM | D8: =IFERROR(INDEX(Mesarios!$D$2:$D$112,MATCH($A8&"|"&D$1,Mesarios!$F$2:$F$112,0)),"VAGO") -> WELLINGTON DOS SANTOS | E8: =IFERROR(INDEX(Mesarios!$E$2:$E$112,MATCH($A8&"|"&D$1,Mesarios!$F$2:$F$112,0)),"VAGO") -> SIM | F8: =IFERROR(INDEX(Mesarios!$D$2:$D$112,MATCH($A8&"|"&F$1,Mesarios!$F$2:$F$112,0)),"VAGO") -> EDINEIA DE ALMEIDA GOMES | G8: =IFERROR(INDEX(Mesarios!$E$2:$E$112,MATCH($A8&"|"&F$1,Mesarios!$F$2:$F$112,0)),"VAGO") -> NAO | H8: =IFERROR(INDEX(Mesarios!$D$2:$D$112,MATCH($A8&"|"&H$1,Mesarios!$F$2:$F$112,0)),"VAGO") -> GABRIEL SOARES DE CARVALHO | I8: =IFERROR(INDEX(Mesarios!$E$2:$E$112,MATCH($A8&"|"&H$1,Mesarios!$F$2:$F$112,0)),"VAGO") -> NAO | J8: =COUNTIF(C8:I8,"SIM") -> 2 | K8: =COUNTIF(C8:I8,"NAO") -> 2 | L8: =COUNTIF(C8:I8,"0006/2026")+COUNTIF(C8:I8,"-") -> 0 | M8: =IF(J8>=4,"Mesa completa",IF(J8=3,"Falta 1","ATENÇÃO: só "&J8&" presentes")) -> ATENÇÃO: só 2 presentes | N8: ='Por secao'!N8 -> 325 | O8: ='Por secao'!O8 -> Baixo
A9: ='Por secao'!A9 -> 3078 | B9: =IFERROR(INDEX(Mesarios!$D$2:$D$112,MATCH($A9&"|"&B$1,Mesarios!$F$2:$F$112,0)),"VAGO") -> TULIO CARLOS DE MOURA NEVES | C9: =IFERROR(INDEX(Mesarios!$E$2:$E$112,MATCH($A9&"|"&B$1,Mesarios!$F$2:$F$112,0)),"VAGO") -> SIM | D9: =IFERROR(INDEX(Mesarios!$D$2:$D$112,MATCH($A9&"|"&D$1,Mesarios!$F$2:$F$112,0)),"VAGO") -> TATIANE CRISTINA FREGNANI | E9: =IFERROR(INDEX(Mesarios!$E$2:$E$112,MATCH($A9&"|"&D$1,Mesarios!$F$2:$F$112,0)),"VAGO") -> SIM | F9: =IFERROR(INDEX(Mesarios!$D$2:$D$112,MATCH($A9&"|"&F$1,Mesarios!$F$2:$F$112,0)),"VAGO") -> DANIELA LIMA DE MELO CARETTE | G9: =IFERROR(INDEX(Mesarios!$E$2:$E$112,MATCH($A9&"|"&F$1,Mesarios!$F$2:$F$112,0)),"VAGO") -> SIM | H9: =IFERROR(INDEX(Mesarios!$D$2:$D$112,MATCH($A9&"|"&H$1,Mesarios!$F$2:$F$112,0)),"VAGO") -> MATHEUS PASSOS MENDES | I9: =IFERROR(INDEX(Mesarios!$E$2:$E$112,MATCH($A9&"|"&H$1,Mesarios!$F$2:$F$112,0)),"VAGO") -> SIM | J9: =COUNTIF(C9:I9,"SIM") -> 4 | K9: =COUNTIF(C9:I9,"NAO") -> 0 | L9: =COUNTIF(C9:I9,"0006/2026")+COUNTIF(C9:I9,"-") -> 0 | M9: =IF(J9>=4,"Mesa completa",IF(J9=3,"Falta 1","ATENÇÃO: só "&J9&" presentes")) -> Mesa completa | N9: ='Por secao'!N9 -> 311 | O9: ='Por secao'!O9 -> Baixo
A10: ='Por secao'!A10 -> 3108 | B10: =IFERROR(INDEX(Mesarios!$D$2:$D$112,MATCH($A10&"|"&B$1,Mesarios!$F$2:$F$112,0)),"VAGO") -> FERNANDA LIMA HERMANSON CARVALHO LOPES | C10: =IFERROR(INDEX(Mesarios!$E$2:$E$112,MATCH($A10&"|"&B$1,Mesarios!$F$2:$F$112,0)),"VAGO") -> SIM | D10: =IFERROR(INDEX(Mesarios!$D$2:$D$112,MATCH($A10&"|"&D$1,Mesarios!$F$2:$F$112,0)),"VAGO") -> DANIEL DOS SANTOS JORGE | E10: =IFERROR(INDEX(Mesarios!$E$2:$E$112,MATCH($A10&"|"&D$1,Mesarios!$F$2:$F$112,0)),"VAGO") -> SIM | F10: =IFERROR(INDEX(Mesarios!$D$2:$D$112,MATCH($A10&"|"&F$1,Mesarios!$F$2:$F$112,0)),"VAGO") -> INGRID MACHADO DOS REIS | G10: =IFERROR(INDEX(Mesarios!$E$2:$E$112,MATCH($A10&"|"&F$1,Mesarios!$F$2:$F$112,0)),"VAGO") -> SIM | H10: =IFERROR(INDEX(Mesarios!$D$2:$D$112,MATCH($A10&"|"&H$1,Mesarios!$F$2:$F$112,0)),"VAGO") -> DANIELA HADWIG DULLIUS | I10: =IFERROR(INDEX(Mesarios!$E$2:$E$112,MATCH($A10&"|"&H$1,Mesarios!$F$2:$F$112,0)),"VAGO") -> SIM | J10: =COUNTIF(C10:I10,"SIM") -> 4 | K10: =COUNTIF(C10:I10,"NAO") -> 0 | L10: =COUNTIF(C10:I10,"0006/2026")+COUNTIF(C10:I10,"-") -> 0 | M10: =IF(J10>=4,"Mesa completa",IF(J10=3,"Falta 1","ATENÇÃO: só "&J10&" presentes")) -> Mesa completa | N10: ='Por secao'!N10 -> 467 | O10: ='Por secao'!O10 -> Médio
A11: ='Por secao'!A11 -> 3142 | B11: =IFERROR(INDEX(Mesarios!$D$2:$D$112,MATCH($A11&"|"&B$1,Mesarios!$F$2:$F$112,0)),"VAGO") -> BEATRIZ GILLI HADG KARKACHI | C11: =IFERROR(INDEX(Mesarios!$E$2:$E$112,MATCH($A11&"|"&B$1,Mesarios!$F$2:$F$112,0)),"VAGO") -> SIM | D11: =IFERROR(INDEX(Mesarios!$D$2:$D$112,MATCH($A11&"|"&D$1,Mesarios!$F$2:$F$112,0)),"VAGO") -> ANABELLA ALVES DE CASTRO | E11: =IFERROR(INDEX(Mesarios!$E$2:$E$112,MATCH($A11&"|"&D$1,Mesarios!$F$2:$F$112,0)),"VAGO") -> SIM | F11: =IFERROR(INDEX(Mesarios!$D$2:$D$112,MATCH($A11&"|"&F$1,Mesarios!$F$2:$F$112,0)),"VAGO") -> JULIANA CASSIA TAVARES DE SOUSA | G11: =IFERROR(INDEX(Mesarios!$E$2:$E$112,MATCH($A11&"|"&F$1,Mesarios!$F$2:$F$112,0)),"VAGO") -> SIM | H11: =IFERROR(INDEX(Mesarios!$D$2:$D$112,MATCH($A11&"|"&H$1,Mesarios!$F$2:$F$112,0)),"VAGO") -> LINCOLN CUBAS GUEDES | I11: =IFERROR(INDEX(Mesarios!$E$2:$E$112,MATCH($A11&"|"&H$1,Mesarios!$F$2:$F$112,0)),"VAGO") -> SIM | J11: =COUNTIF(C11:I11,"SIM") -> 4 | K11: =COUNTIF(C11:I11,"NAO") -> 0 | L11: =COUNTIF(C11:I11,"0006/2026")+COUNTIF(C11:I11,"-") -> 0 | M11: =IF(J11>=4,"Mesa completa",IF(J11=3,"Falta 1","ATENÇÃO: só "&J11&" presentes")) -> Mesa completa | N11: ='Por secao'!N11 -> 466 | O11: ='Por secao'!O11 -> Médio
A12: ='Por secao'!A12 -> 3161 | B12: =IFERROR(INDEX(Mesarios!$D$2:$D$112,MATCH($A12&"|"&B$1,Mesarios!$F$2:$F$112,0)),"VAGO") -> MARCELA TIYOKO PASSOS KONDO | C12: =IFERROR(INDEX(Mesarios!$E$2:$E$112,MATCH($A12&"|"&B$1,Mesarios!$F$2:$F$112,0)),"VAGO") -> NAO | D12: =IFERROR(INDEX(Mesarios!$D$2:$D$112,MATCH($A12&"|"&D$1,Mesarios!$F$2:$F$112,0)),"VAGO") -> TALITA MORTARI MONTYSUMA | E12: =IFERROR(INDEX(Mesarios!$E$2:$E$112,MATCH($A12&"|"&D$1,Mesarios!$F$2:$F$112,0)),"VAGO") -> SIM | F12: =IFERROR(INDEX(Mesarios!$D$2:$D$112,MATCH($A12&"|"&F$1,Mesarios!$F$2:$F$112,0)),"VAGO") -> NASTASSJA VERONICA LOUSADA GOMES | G12: =IFERROR(INDEX(Mesarios!$E$2:$E$112,MATCH($A12&"|"&F$1,Mesarios!$F$2:$F$112,0)),"VAGO") -> SIM | H12: =IFERROR(INDEX(Mesarios!$D$2:$D$112,MATCH($A12&"|"&H$1,Mesarios!$F$2:$F$112,0)),"VAGO") -> ANTHONY EDWARD DA SILVA AGAPITO | I12: =IFERROR(INDEX(Mesarios!$E$2:$E$112,MATCH($A12&"|"&H$1,Mesarios!$F$2:$F$112,0)),"VAGO") -> SIM | J12: =COUNTIF(C12:I12,"SIM") -> 3 | K12: =COUNTIF(C12:I12,"NAO") -> 1 | L12: =COUNTIF(C12:I12,"0006/2026")+COUNTIF(C12:I12,"-") -> 0 | M12: =IF(J12>=4,"Mesa completa",IF(J12=3,"Falta 1","ATENÇÃO: só "&J12&" presentes")) -> Falta 1 | N12: ='Por secao'!N12 -> 504 | O12: ='Por secao'!O12 -> Médio
A13: ='Por secao'!A13 -> 3179 | B13: =IFERROR(INDEX(Mesarios!$D$2:$D$112,MATCH($A13&"|"&B$1,Mesarios!$F$2:$F$112,0)),"VAGO") -> ELTON APARECIDO ROCHA | C13: =IFERROR(INDEX(Mesarios!$E$2:$E$112,MATCH($A13&"|"&B$1,Mesarios!$F$2:$F$112,0)),"VAGO") -> SIM | D13: =IFERROR(INDEX(Mesarios!$D$2:$D$112,MATCH($A13&"|"&D$1,Mesarios!$F$2:$F$112,0)),"VAGO") -> ANDERSON SILVERIO DE OLIVEIRA | E13: =IFERROR(INDEX(Mesarios!$E$2:$E$112,MATCH($A13&"|"&D$1,Mesarios!$F$2:$F$112,0)),"VAGO") -> NAO | F13: =IFERROR(INDEX(Mesarios!$D$2:$D$112,MATCH($A13&"|"&F$1,Mesarios!$F$2:$F$112,0)),"VAGO") -> JUSSARA VENEZA SOARES | G13: =IFERROR(INDEX(Mesarios!$E$2:$E$112,MATCH($A13&"|"&F$1,Mesarios!$F$2:$F$112,0)),"VAGO") -> NAO | H13: =IFERROR(INDEX(Mesarios!$D$2:$D$112,MATCH($A13&"|"&H$1,Mesarios!$F$2:$F$112,0)),"VAGO") -> TAYNA STETELI PERON LOPES SILVA | I13: =IFERROR(INDEX(Mesarios!$E$2:$E$112,MATCH($A13&"|"&H$1,Mesarios!$F$2:$F$112,0)),"VAGO") -> SIM | J13: =COUNTIF(C13:I13,"SIM") -> 2 | K13: =COUNTIF(C13:I13,"NAO") -> 2 | L13: =COUNTIF(C13:I13,"0006/2026")+COUNTIF(C13:I13,"-") -> 0 | M13: =IF(J13>=4,"Mesa completa",IF(J13=3,"Falta 1","ATENÇÃO: só "&J13&" presentes")) -> ATENÇÃO: só 2 presentes | N13: ='Por secao'!N13 -> 423 | O13: ='Por secao'!O13 -> Baixo
... A29: ='Por secao'!A29 -> 3862 | B29: =IFERROR(INDEX(Mesarios!$D$2:$D$112,MATCH($A29&"|"&B$1,Mesarios!$F$2:$F$112,0)),"VAGO") -> EMILLY LAÍSE PARDO XAVIER | C29: =IFERROR(INDEX(Mesarios!$E$2:$E$112,MATCH($A29&"|"&B$1,Mesarios!$F$2:$F$112,0)),"VAGO") -> SIM | D29: =IFERROR(INDEX(Mesarios!$D$2:$D$112,MATCH($A29&"|"&D$1,Mesarios!$F$2:$F$112,0)),"VAGO") -> BRUNA MARIA DE ALMEIDA CABRAL | E29: =IFERROR(INDEX(Mesarios!$E$2:$E$112,MATCH($A29&"|"&D$1,Mesarios!$F$2:$F$112,0)),"VAGO") -> SIM | F29: =IFERROR(INDEX(Mesarios!$D$2:$D$112,MATCH($A29&"|"&F$1,Mesarios!$F$2:$F$112,0)),"VAGO") -> VAGO | G29: =IFERROR(INDEX(Mesarios!$E$2:$E$112,MATCH($A29&"|"&F$1,Mesarios!$F$2:$F$112,0)),"VAGO") -> VAGO | H29: =IFERROR(INDEX(Mesarios!$D$2:$D$112,MATCH($A29&"|"&H$1,Mesarios!$F$2:$F$112,0)),"VAGO") -> IVANI BATISTA DE FREITAS MONTEIRO | I29: =IFERROR(INDEX(Mesarios!$E$2:$E$112,MATCH($A29&"|"&H$1,Mesarios!$F$2:$F$112,0)),"VAGO") -> SIM | J29: =COUNTIF(C29:I29,"SIM") -> 3 | K29: =COUNTIF(C29:I29,"NAO") -> 0 | L29: =COUNTIF(C29:I29,"0006/2026")+COUNTIF(C29:I29,"-") -> 0 | M29: =IF(J29>=4,"Mesa completa",IF(J29=3,"Falta 1","ATENÇÃO: só "&J29&" presentes")) -> Falta 1 | N29: ='Por secao'!N29 -> 296 | O29: ='Por secao'!O29 -> Baixo
A30: Total | J30: =SUM(J2:J29) -> 82 | K30: =SUM(K2:K29) -> 13 | L30: =SUM(L2:L29) -> 16 | M30: =COUNTIF(M2:M29,"Mesa completa")&" completas · "&COUNTIF(M2:M29,"Falta 1")&" falta 1 · "&COUNTIF(M2:M29,"ATENÇÃO*")&" em atenção" -> 15 completas · 4 falta 1 · 9 em atenção
A32: Leitura: nomes e presença vêm da aba Mesarios (coluna Presença). SIM = presente (verde) · NAO = ausente (vermelho) · 0006/2026 (amarelo) · "-" = sem registro (cinza) · VAGO = função sem mesário designado. Editar só a aba Mesarios; esta aba recalcula sozinha.

Sheet Por secao
A1: Seção | B1: Designados | C1: Presidente | D1: 1º Mesário | E1: 2º Mesário | F1: 1º Secretário | G1: Presentes (SIM) | H1: Ausentes (NAO) | I1: Outros (0006/2026 ou -) | J1: Função vaga | K1: Alerta | L1: Seção agregada | M1: Aptos na urna | N1: Eleitores esperados | O1: Faixa | P1: Aptos (BU) | Q1: Comparecimento efetivo (BU) | R1: Faltosos (BU) | S1: Taxa de comparecimento | T1: Efetivo − esperado | U1: Desvio vs esperado | V1: Posição (efetivo) | W1: Faixa efetiva
A2: 511 | B2: =COUNTIFS(Mesarios!$A$2:$A$112,$A2) -> 4 | C2: =IF(COUNTIFS(Mesarios!$A$2:$A$112,$A2,Mesarios!$B$2:$B$112,C$1)>0,"✓","VAGO") -> ✓ | D2: =IF(COUNTIFS(Mesarios!$A$2:$A$112,$A2,Mesarios!$B$2:$B$112,D$1)>0,"✓","VAGO") -> ✓ | E2: =IF(COUNTIFS(Mesarios!$A$2:$A$112,$A2,Mesarios!$B$2:$B$112,E$1)>0,"✓","VAGO") -> ✓ | F2: =IF(COUNTIFS(Mesarios!$A$2:$A$112,$A2,Mesarios!$B$2:$B$112,F$1)>0,"✓","VAGO") -> ✓ | G2: =COUNTIFS(Mesarios!$A$2:$A$112,$A2,Mesarios!$E$2:$E$112,"SIM") -> 4 | H2: =COUNTIFS(Mesarios!$A$2:$A$112,$A2,Mesarios!$E$2:$E$112,"NAO") -> 0 | I2: =COUNTIFS(Mesarios!$A$2:$A$112,$A2,Mesarios!$E$2:$E$112,"0006/2026")+COUNTIFS(Mesarios!$A$2:$A$112,$A2,Mesarios!$E$2:$E$112,"-") -> 0 | J2: =COUNTIF(C2:F2,"VAGO") -> 0 | K2: =IF(B2<4,"Mesa com "&B2&" designados","")&IF(AND(B2<4,G2<3)," · ","")&IF(G2<3,"Só "&G2&" presentes","") | L2: 1100 | M2: 582 | N2: 375 | O2: =IF(N2>=$N$34,"Alto",IF(N2>=$N$35,"Médio","Baixo")) -> Baixo | P2: 582 | Q2: 226 | R2: =P2-Q2 -> 356 | S2: =Q2/P2 -> 0.38831615 | T2: =Q2-N2 -> -149 | U2: =Q2/N2-1 -> -0.39733333 | V2: =RANK(Q2,$Q$2:$Q$29)+COUNTIF($Q$2:Q2,Q2)-1 -> 22 | W2: =IF(Q2>=$W$34,"Alto",IF(Q2>=$W$35,"Médio","Baixo")) -> Baixo
A3: 512 | B3: =COUNTIFS(Mesarios!$A$2:$A$112,$A3) -> 4 | C3: =IF(COUNTIFS(Mesarios!$A$2:$A$112,$A3,Mesarios!$B$2:$B$112,C$1)>0,"✓","VAGO") -> ✓ | D3: =IF(COUNTIFS(Mesarios!$A$2:$A$112,$A3,Mesarios!$B$2:$B$112,D$1)>0,"✓","VAGO") -> ✓ | E3: =IF(COUNTIFS(Mesarios!$A$2:$A$112,$A3,Mesarios!$B$2:$B$112,E$1)>0,"✓","VAGO") -> ✓ | F3: =IF(COUNTIFS(Mesarios!$A$2:$A$112,$A3,Mesarios!$B$2:$B$112,F$1)>0,"✓","VAGO") -> ✓ | G3: =COUNTIFS(Mesarios!$A$2:$A$112,$A3,Mesarios!$E$2:$E$112,"SIM") -> 3 | H3: =COUNTIFS(Mesarios!$A$2:$A$112,$A3,Mesarios!$E$2:$E$112,"NAO") -> 1 | I3: =COUNTIFS(Mesarios!$A$2:$A$112,$A3,Mesarios!$E$2:$E$112,"0006/2026")+COUNTIFS(Mesarios!$A$2:$A$112,$A3,Mesarios!$E$2:$E$112,"-") -> 0 | J3: =COUNTIF(C3:F3,"VAGO") -> 0 | K3: =IF(B3<4,"Mesa com "&B3&" designados","")&IF(AND(B3<4,G3<3)," · ","")&IF(G3<3,"Só "&G3&" presentes","") | L3: 2855 | M3: 476 | N3: 355 | O3: =IF(N3>=$N$34,"Alto",IF(N3>=$N$35,"Médio","Baixo")) -> Baixo | P3: 476 | Q3: 204 | R3: =P3-Q3 -> 272 | S3: =Q3/P3 -> 0.42857143 | T3: =Q3-N3 -> -151 | U3: =Q3/N3-1 -> -0.42535211 | V3: =RANK(Q3,$Q$2:$Q$29)+COUNTIF($Q$2:Q3,Q3)-1 -> 24 | W3: =IF(Q3>=$W$34,"Alto",IF(Q3>=$W$35,"Médio","Baixo")) -> Baixo
A4: 513 | B4: =COUNTIFS(Mesarios!$A$2:$A$112,$A4) -> 4 | C4: =IF(COUNTIFS(Mesarios!$A$2:$A$112,$A4,Mesarios!$B$2:$B$112,C$1)>0,"✓","VAGO") -> ✓ | D4: =IF(COUNTIFS(Mesarios!$A$2:$A$112,$A4,Mesarios!$B$2:$B$112,D$1)>0,"✓","VAGO") -> ✓ | E4: =IF(COUNTIFS(Mesarios!$A$2:$A$112,$A4,Mesarios!$B$2:$B$112,E$1)>0,"✓","VAGO") -> ✓ | F4: =IF(COUNTIFS(Mesarios!$A$2:$A$112,$A4,Mesarios!$B$2:$B$112,F$1)>0,"✓","VAGO") -> ✓ | G4: =COUNTIFS(Mesarios!$A$2:$A$112,$A4,Mesarios!$E$2:$E$112,"SIM") -> 3 | H4: =COUNTIFS(Mesarios!$A$2:$A$112,$A4,Mesarios!$E$2:$E$112,"NAO") -> 1 | I4: =COUNTIFS(Mesarios!$A$2:$A$112,$A4,Mesarios!$E$2:$E$112,"0006/2026")+COUNTIFS(Mesarios!$A$2:$A$112,$A4,Mesarios!$E$2:$E$112,"-") -> 0 | J4: =COUNTIF(C4:F4,"VAGO") -> 0 | K4: =IF(B4<4,"Mesa com "&B4&" designados","")&IF(AND(B4<4,G4<3)," · ","")&IF(G4<3,"Só "&G4&" presentes","") | L4: 1105 | M4: 502 | N4: 351 | O4: =IF(N4>=$N$34,"Alto",IF(N4>=$N$35,"Médio","Baixo")) -> Baixo | P4: 501 | Q4: 190 | R4: =P4-Q4 -> 311 | S4: =Q4/P4 -> 0.37924152 | T4: =Q4-N4 -> -161 | U4: =Q4/N4-1 -> -0.45868946 | V4: =RANK(Q4,$Q$2:$Q$29)+COUNTIF($Q$2:Q4,Q4)-1 -> 27 | W4: =IF(Q4>=$W$34,"Alto",IF(Q4>=$W$35,"Médio","Baixo")) -> Baixo
A5: 517 | B5: =COUNTIFS(Mesarios!$A$2:$A$112,$A5) -> 4 | C5: =IF(COUNTIFS(Mesarios!$A$2:$A$112,$A5,Mesarios!$B$2:$B$112,C$1)>0,"✓","VAGO") -> ✓ | D5: =IF(COUNTIFS(Mesarios!$A$2:$A$112,$A5,Mesarios!$B$2:$B$112,D$1)>0,"✓","VAGO") -> ✓ | E5: =IF(COUNTIFS(Mesarios!$A$2:$A$112,$A5,Mesarios!$B$2:$B$112,E$1)>0,"✓","VAGO") -> ✓ | F5: =IF(COUNTIFS(Mesarios!$A$2:$A$112,$A5,Mesarios!$B$2:$B$112,F$1)>0,"✓","VAGO") -> ✓ | G5: =COUNTIFS(Mesarios!$A$2:$A$112,$A5,Mesarios!$E$2:$E$112,"SIM") -> 4 | H5: =COUNTIFS(Mesarios!$A$2:$A$112,$A5,Mesarios!$E$2:$E$112,"NAO") -> 0 | I5: =COUNTIFS(Mesarios!$A$2:$A$112,$A5,Mesarios!$E$2:$E$112,"0006/2026")+COUNTIFS(Mesarios!$A$2:$A$112,$A5,Mesarios!$E$2:$E$112,"-") -> 0 | J5: =COUNTIF(C5:F5,"VAGO") -> 0 | K5: =IF(B5<4,"Mesa com "&B5&" designados","")&IF(AND(B5<4,G5<3)," · ","")&IF(G5<3,"Só "&G5&" presentes","") | L5: 1292 | M5: 513 | N5: 348 | O5: =IF(N5>=$N$34,"Alto",IF(N5>=$N$35,"Médio","Baixo")) -> Baixo | P5: 512 | Q5: 220 | R5: =P5-Q5 -> 292 | S5: =Q5/P5 -> 0.4296875 | T5: =Q5-N5 -> -128 | U5: =Q5/N5-1 -> -0.36781609 | V5: =RANK(Q5,$Q$2:$Q$29)+COUNTIF($Q$2:Q5,Q5)-1 -> 23 | W5: =IF(Q5>=$W$34,"Alto",IF(Q5>=$W$35,"Médio","Baixo")) -> Baixo
A6: 1160 | B6: =COUNTIFS(Mesarios!$A$2:$A$112,$A6) -> 4 | C6: =IF(COUNTIFS(Mesarios!$A$2:$A$112,$A6,Mesarios!$B$2:$B$112,C$1)>0,"✓","VAGO") -> ✓ | D6: =IF(COUNTIFS(Mesarios!$A$2:$A$112,$A6,Mesarios!$B$2:$B$112,D$1)>0,"✓","VAGO") -> ✓ | E6: =IF(COUNTIFS(Mesarios!$A$2:$A$112,$A6,Mesarios!$B$2:$B$112,E$1)>0,"✓","VAGO") -> ✓ | F6: =IF(COUNTIFS(Mesarios!$A$2:$A$112,$A6,Mesarios!$B$2:$B$112,F$1)>0,"✓","VAGO") -> ✓ | G6: =COUNTIFS(Mesarios!$A$2:$A$112,$A6,Mesarios!$E$2:$E$112,"SIM") -> 0 | H6: =COUNTIFS(Mesarios!$A$2:$A$112,$A6,Mesarios!$E$2:$E$112,"NAO") -> 0 | I6: =COUNTIFS(Mesarios!$A$2:$A$112,$A6,Mesarios!$E$2:$E$112,"0006/2026")+COUNTIFS(Mesarios!$A$2:$A$112,$A6,Mesarios!$E$2:$E$112,"-") -> 4 | J6: =COUNTIF(C6:F6,"VAGO") -> 0 | K6: =IF(B6<4,"Mesa com "&B6&" designados","")&IF(AND(B6<4,G6<3)," · ","")&IF(G6<3,"Só "&G6&" presentes","") -> Só 0 presentes | L6: 3845 | M6: 473 | N6: 328 | O6: =IF(N6>=$N$34,"Alto",IF(N6>=$N$35,"Médio","Baixo")) -> Baixo | P6: 472 | Q6: 239 | R6: =P6-Q6 -> 233 | S6: =Q6/P6 -> 0.50635593 | T6: =Q6-N6 -> -89 | U6: =Q6/N6-1 -> -0.27134146 | V6: =RANK(Q6,$Q$2:$Q$29)+COUNTIF($Q$2:Q6,Q6)-1 -> 21 | W6: =IF(Q6>=$W$34,"Alto",IF(Q6>=$W$35,"Médio","Baixo")) -> Baixo
A7: 1352 | B7: =COUNTIFS(Mesarios!$A$2:$A$112,$A7) -> 4 | C7: =IF(COUNTIFS(Mesarios!$A$2:$A$112,$A7,Mesarios!$B$2:$B$112,C$1)>0,"✓","VAGO") -> ✓ | D7: =IF(COUNTIFS(Mesarios!$A$2:$A$112,$A7,Mesarios!$B$2:$B$112,D$1)>0,"✓","VAGO") -> ✓ | E7: =IF(COUNTIFS(Mesarios!$A$2:$A$112,$A7,Mesarios!$B$2:$B$112,E$1)>0,"✓","VAGO") -> ✓ | F7: =IF(COUNTIFS(Mesarios!$A$2:$A$112,$A7,Mesarios!$B$2:$B$112,F$1)>0,"✓","VAGO") -> ✓ | G7: =COUNTIFS(Mesarios!$A$2:$A$112,$A7,Mesarios!$E$2:$E$112,"SIM") -> 4 | H7: =COUNTIFS(Mesarios!$A$2:$A$112,$A7,Mesarios!$E$2:$E$112,"NAO") -> 0 | I7: =COUNTIFS(Mesarios!$A$2:$A$112,$A7,Mesarios!$E$2:$E$112,"0006/2026")+COUNTIFS(Mesarios!$A$2:$A$112,$A7,Mesarios!$E$2:$E$112,"-") -> 0 | J7: =COUNTIF(C7:F7,"VAGO") -> 0 | K7: =IF(B7<4,"Mesa com "&B7&" designados","")&IF(AND(B7<4,G7<3)," · ","")&IF(G7<3,"Só "&G7&" presentes","") | L7: 522 | M7: 462 | N7: 328 | O7: =IF(N7>=$N$34,"Alto",IF(N7>=$N$35,"Médio","Baixo")) -> Baixo | P7: 462 | Q7: 203 | R7: =P7-Q7 -> 259 | S7: =Q7/P7 -> 0.43939394 | T7: =Q7-N7 -> -125 | U7: =Q7/N7-1 -> -0.38109756 | V7: =RANK(Q7,$Q$2:$Q$29)+COUNTIF($Q$2:Q7,Q7)-1 -> 26 | W7: =IF(Q7>=$W$34,"Alto",IF(Q7>=$W$35,"Médio","Baixo")) -> Baixo
A8: 3054 | B8: =COUNTIFS(Mesarios!$A$2:$A$112,$A8) -> 4 | C8: =IF(COUNTIFS(Mesarios!$A$2:$A$112,$A8,Mesarios!$B$2:$B$112,C$1)>0,"✓","VAGO") -> ✓ | D8: =IF(COUNTIFS(Mesarios!$A$2:$A$112,$A8,Mesarios!$B$2:$B$112,D$1)>0,"✓","VAGO") -> ✓ | E8: =IF(COUNTIFS(Mesarios!$A$2:$A$112,$A8,Mesarios!$B$2:$B$112,E$1)>0,"✓","VAGO") -> ✓ | F8: =IF(COUNTIFS(Mesarios!$A$2:$A$112,$A8,Mesarios!$B$2:$B$112,F$1)>0,"✓","VAGO") -> ✓ | G8: =COUNTIFS(Mesarios!$A$2:$A$112,$A8,Mesarios!$E$2:$E$112,"SIM") -> 2 | H8: =COUNTIFS(Mesarios!$A$2:$A$112,$A8,Mesarios!$E$2:$E$112,"NAO") -> 2 | I8: =COUNTIFS(Mesarios!$A$2:$A$112,$A8,Mesarios!$E$2:$E$112,"0006/2026")+COUNTIFS(Mesarios!$A$2:$A$112,$A8,Mesarios!$E$2:$E$112,"-") -> 0 | J8: =COUNTIF(C8:F8,"VAGO") -> 0 | K8: =IF(B8<4,"Mesa com "&B8&" designados","")&IF(AND(B8<4,G8<3)," · ","")&IF(G8<3,"Só "&G8&" presentes","") -> Só 2 presentes | L8: 1099 | M8: 454 | N8: 325 | O8: =IF(N8>=$N$34,"Alto",IF(N8>=$N$35,"Médio","Baixo")) -> Baixo | P8: 452 | Q8: 256 | R8: =P8-Q8 -> 196 | S8: =Q8/P8 -> 0.56637168 | T8: =Q8-N8 -> -69 | U8: =Q8/N8-1 -> -0.21230769 | V8: =RANK(Q8,$Q$2:$Q$29)+COUNTIF($Q$2:Q8,Q8)-1 -> 20 | W8: =IF(Q8>=$W$34,"Alto",IF(Q8>=$W$35,"Médio","Baixo")) -> Baixo
A9: 3078 | B9: =COUNTIFS(Mesarios!$A$2:$A$112,$A9) -> 4 | C9: =IF(COUNTIFS(Mesarios!$A$2:$A$112,$A9,Mesarios!$B$2:$B$112,C$1)>0,"✓","VAGO") -> ✓ | D9: =IF(COUNTIFS(Mesarios!$A$2:$A$112,$A9,Mesarios!$B$2:$B$112,D$1)>0,"✓","VAGO") -> ✓ | E9: =IF(COUNTIFS(Mesarios!$A$2:$A$112,$A9,Mesarios!$B$2:$B$112,E$1)>0,"✓","VAGO") -> ✓ | F9: =IF(COUNTIFS(Mesarios!$A$2:$A$112,$A9,Mesarios!$B$2:$B$112,F$1)>0,"✓","VAGO") -> ✓ | G9: =COUNTIFS(Mesarios!$A$2:$A$112,$A9,Mesarios!$E$2:$E$112,"SIM") -> 4 | H9: =COUNTIFS(Mesarios!$A$2:$A$112,$A9,Mesarios!$E$2:$E$112,"NAO") -> 0 | I9: =COUNTIFS(Mesarios!$A$2:$A$112,$A9,Mesarios!$E$2:$E$112,"0006/2026")+COUNTIFS(Mesarios!$A$2:$A$112,$A9,Mesarios!$E$2:$E$112,"-") -> 0 | J9: =COUNTIF(C9:F9,"VAGO") -> 0 | K9: =IF(B9<4,"Mesa com "&B9&" designados","")&IF(AND(B9<4,G9<3)," · ","")&IF(G9<3,"Só "&G9&" presentes","") | L9: 2847 | M9: 429 | N9: 311 | O9: =IF(N9>=$N$34,"Alto",IF(N9>=$N$35,"Médio","Baixo")) -> Baixo | P9: 427 | Q9: 259 | R9: =P9-Q9 -> 168 | S9: =Q9/P9 -> 0.60655738 | T9: =Q9-N9 -> -52 | U9: =Q9/N9-1 -> -0.16720257 | V9: =RANK(Q9,$Q$2:$Q$29)+COUNTIF($Q$2:Q9,Q9)-1 -> 19 | W9: =IF(Q9>=$W$34,"Alto",IF(Q9>=$W$35,"Médio","Baixo")) -> Baixo
A10: 3108 | B10: =COUNTIFS(Mesarios!$A$2:$A$112,$A10) -> 4 | C10: =IF(COUNTIFS(Mesarios!$A$2:$A$112,$A10,Mesarios!$B$2:$B$112,C$1)>0,"✓","VAGO") -> ✓ | D10: =IF(COUNTIFS(Mesarios!$A$2:$A$112,$A10,Mesarios!$B$2:$B$112,D$1)>0,"✓","VAGO") -> ✓ | E10: =IF(COUNTIFS(Mesarios!$A$2:$A$112,$A10,Mesarios!$B$2:$B$112,E$1)>0,"✓","VAGO") -> ✓ | F10: =IF(COUNTIFS(Mesarios!$A$2:$A$112,$A10,Mesarios!$B$2:$B$112,F$1)>0,"✓","VAGO") -> ✓ | G10: =COUNTIFS(Mesarios!$A$2:$A$112,$A10,Mesarios!$E$2:$E$112,"SIM") -> 4 | H10: =COUNTIFS(Mesarios!$A$2:$A$112,$A10,Mesarios!$E$2:$E$112,"NAO") -> 0 | I10: =COUNTIFS(Mesarios!$A$2:$A$112,$A10,Mesarios!$E$2:$E$112,"0006/2026")+COUNTIFS(Mesarios!$A$2:$A$112,$A10,Mesarios!$E$2:$E$112,"-") -> 0 | J10: =COUNTIF(C10:F10,"VAGO") -> 0 | K10: =IF(B10<4,"Mesa com "&B10&" designados","")&IF(AND(B10<4,G10<3)," · ","")&IF(G10<3,"Só "&G10&" presentes","") | L10: 3422 | M10: 756 | N10: 467 | O10: =IF(N10>=$N$34,"Alto",IF(N10>=$N$35,"Médio","Baixo")) -> Médio | P10: 752 | Q10: 320 | R10: =P10-Q10 -> 432 | S10: =Q10/P10 -> 0.42553191 | T10: =Q10-N10 -> -147 | U10: =Q10/N10-1 -> -0.31477516 | V10: =RANK(Q10,$Q$2:$Q$29)+COUNTIF($Q$2:Q10,Q10)-1 -> 10 | W10: =IF(Q10>=$W$34,"Alto",IF(Q10>=$W$35,"Médio","Baixo")) -> Baixo
A11: 3142 | B11: =COUNTIFS(Mesarios!$A$2:$A$112,$A11) -> 4 | C11: =IF(COUNTIFS(Mesarios!$A$2:$A$112,$A11,Mesarios!$B$2:$B$112,C$1)>0,"✓","VAGO") -> ✓ | D11: =IF(COUNTIFS(Mesarios!$A$2:$A$112,$A11,Mesarios!$B$2:$B$112,D$1)>0,"✓","VAGO") -> ✓ | E11: =IF(COUNTIFS(Mesarios!$A$2:$A$112,$A11,Mesarios!$B$2:$B$112,E$1)>0,"✓","VAGO") -> ✓ | F11: =IF(COUNTIFS(Mesarios!$A$2:$A$112,$A11,Mesarios!$B$2:$B$112,F$1)>0,"✓","VAGO") -> ✓ | G11: =COUNTIFS(Mesarios!$A$2:$A$112,$A11,Mesarios!$E$2:$E$112,"SIM") -> 4 | H11: =COUNTIFS(Mesarios!$A$2:$A$112,$A11,Mesarios!$E$2:$E$112,"NAO") -> 0 | I11: =COUNTIFS(Mesarios!$A$2:$A$112,$A11,Mesarios!$E$2:$E$112,"0006/2026")+COUNTIFS(Mesarios!$A$2:$A$112,$A11,Mesarios!$E$2:$E$112,"-") -> 0 | J11: =COUNTIF(C11:F11,"VAGO") -> 0 | K11: =IF(B11<4,"Mesa com "&B11&" designados","")&IF(AND(B11<4,G11<3)," · ","")&IF(G11<3,"Só "&G11&" presentes","") | L11: 1278 | M11: 793 | N11: 466 | O11: =IF(N11>=$N$34,"Alto",IF(N11>=$N$35,"Médio","Baixo")) -> Médio | P11: 787 | Q11: 318 | R11: =P11-Q11 -> 469 | S11: =Q11/P11 -> 0.40406607 | T11: =Q11-N11 -> -148 | U11: =Q11/N11-1 -> -0.31759657 | V11: =RANK(Q11,$Q$2:$Q$29)+COUNTIF($Q$2:Q11,Q11)-1 -> 11 | W11: =IF(Q11>=$W$34,"Alto",IF(Q11>=$W$35,"Médio","Baixo")) -> Baixo
A12: 3161 | B12: =COUNTIFS(Mesarios!$A$2:$A$112,$A12) -> 4 | C12: =IF(COUNTIFS(Mesarios!$A$2:$A$112,$A12,Mesarios!$B$2:$B$112,C$1)>0,"✓","VAGO") -> ✓ | D12: =IF(COUNTIFS(Mesarios!$A$2:$A$112,$A12,Mesarios!$B$2:$B$112,D$1)>0,"✓","VAGO") -> ✓ | E12: =IF(COUNTIFS(Mesarios!$A$2:$A$112,$A12,Mesarios!$B$2:$B$112,E$1)>0,"✓","VAGO") -> ✓ | F12: =IF(COUNTIFS(Mesarios!$A$2:$A$112,$A12,Mesarios!$B$2:$B$112,F$1)>0,"✓","VAGO") -> ✓ | G12: =COUNTIFS(Mesarios!$A$2:$A$112,$A12,Mesarios!$E$2:$E$112,"SIM") -> 3 | H12: =COUNTIFS(Mesarios!$A$2:$A$112,$A12,Mesarios!$E$2:$E$112,"NAO") -> 1 | I12: =COUNTIFS(Mesarios!$A$2:$A$112,$A12,Mesarios!$E$2:$E$112,"0006/2026")+COUNTIFS(Mesarios!$A$2:$A$112,$A12,Mesarios!$E$2:$E$112,"-") -> 0 | J12: =COUNTIF(C12:F12,"VAGO") -> 0 | K12: =IF(B12<4,"Mesa com "&B12&" designados","")&IF(AND(B12<4,G12<3)," · ","")&IF(G12<3,"Só "&G12&" presentes","") | L12: 3307 | M12: 791 | N12: 504 | O12: =IF(N12>=$N$34,"Alto",IF(N12>=$N$35,"Médio","Baixo")) -> Médio | P12: 787 | Q12: 328 | R12: =P12-Q12 -> 459 | S12: =Q12/P12 -> 0.41677255 | T12: =Q12-N12 -> -176 | U12: =Q12/N12-1 -> -0.34920635 | V12: =RANK(Q12,$Q$2:$Q$29)+COUNTIF($Q$2:Q12,Q12)-1 -> 8 | W12: =IF(Q12>=$W$34,"Alto",IF(Q12>=$W$35,"Médio","Baixo")) -> Baixo
A13: 3179 | B13: =COUNTIFS(Mesarios!$A$2:$A$112,$A13) -> 4 | C13: =IF(COUNTIFS(Mesarios!$A$2:$A$112,$A13,Mesarios!$B$2:$B$112,C$1)>0,"✓","VAGO") -> ✓ | D13: =IF(COUNTIFS(Mesarios!$A$2:$A$112,$A13,Mesarios!$B$2:$B$112,D$1)>0,"✓","VAGO") -> ✓ | E13: =IF(COUNTIFS(Mesarios!$A$2:$A$112,$A13,Mesarios!$B$2:$B$112,E$1)>0,"✓","VAGO") -> ✓ | F13: =IF(COUNTIFS(Mesarios!$A$2:$A$112,$A13,Mesarios!$B$2:$B$112,F$1)>0,"✓","VAGO") -> ✓ | G13: =COUNTIFS(Mesarios!$A$2:$A$112,$A13,Mesarios!$E$2:$E$112,"SIM") -> 2 | H13: =COUNTIFS(Mesarios!$A$2:$A$112,$A13,Mesarios!$E$2:$E$112,"NAO") -> 2 | I13: =COUNTIFS(Mesarios!$A$2:$A$112,$A13,Mesarios!$E$2:$E$112,"0006/2026")+COUNTIFS(Mesarios!$A$2:$A$112,$A13,Mesarios!$E$2:$E$112,"-") -> 0 | J13: =COUNTIF(C13:F13,"VAGO") -> 0 | K13: =IF(B13<4,"Mesa com "&B13&" designados","")&IF(AND(B13<4,G13<3)," · ","")&IF(G13<3,"Só "&G13&" presentes","") -> Só 2 presentes | L13: 530 | M13: 676 | N13: 423 | O13: =IF(N13>=$N$34,"Alto",IF(N13>=$N$35,"Médio","Baixo")) -> Baixo | P13: 670 | Q13: 349 | R13: =P13-Q13 -> 321 | S13: =Q13/P13 -> 0.52089552 | T13: =Q13-N13 -> -74 | U13: =Q13/N13-1 -> -0.1749409 | V13: =RANK(Q13,$Q$2:$Q$29)+COUNTIF($Q$2:Q13,Q13)-1 -> 6 | W13: =IF(Q13>=$W$34,"Alto",IF(Q13>=$W$35,"Médio","Baixo")) -> Médio
... A19: 3306 | B19: =COUNTIFS(Mesarios!$A$2:$A$112,$A19) -> 4 | C19: =IF(COUNTIFS(Mesarios!$A$2:$A$112,$A19,Mesarios!$B$2:$B$112,C$1)>0,"✓","VAGO") -> ✓ | D19: =IF(COUNTIFS(Mesarios!$A$2:$A$112,$A19,Mesarios!$B$2:$B$112,D$1)>0,"✓","VAGO") -> ✓ | E19: =IF(COUNTIFS(Mesarios!$A$2:$A$112,$A19,Mesarios!$B$2:$B$112,E$1)>0,"✓","VAGO") -> ✓ | F19: =IF(COUNTIFS(Mesarios!$A$2:$A$112,$A19,Mesarios!$B$2:$B$112,F$1)>0,"✓","VAGO") -> ✓ | G19: =COUNTIFS(Mesarios!$A$2:$A$112,$A19,Mesarios!$E$2:$E$112,"SIM") -> 4 | H19: =COUNTIFS(Mesarios!$A$2:$A$112,$A19,Mesarios!$E$2:$E$112,"NAO") -> 0 | I19: =COUNTIFS(Mesarios!$A$2:$A$112,$A19,Mesarios!$E$2:$E$112,"0006/2026")+COUNTIFS(Mesarios!$A$2:$A$112,$A19,Mesarios!$E$2:$E$112,"-") -> 0 | J19: =COUNTIF(C19:F19,"VAGO") -> 0 | K19: =IF(B19<4,"Mesa com "&B19&" designados","")&IF(AND(B19<4,G19<3)," · ","")&IF(G19<3,"Só "&G19&" presentes","") | L19: 518 | M19: 766 | N19: 515 | O19: =IF(N19>=$N$34,"Alto",IF(N19>=$N$35,"Médio","Baixo")) -> Médio | P19: 761 | Q19: 345 | R19: =P19-Q19 -> 416 | S19: =Q19/P19 -> 0.45335085 | T19: =Q19-N19 -> -170 | U19: =Q19/N19-1 -> -0.33009709 | V19: =RANK(Q19,$Q$2:$Q$29)+COUNTIF($Q$2:Q19,Q19)-1 -> 7 | W19: =IF(Q19>=$W$34,"Alto",IF(Q19>=$W$35,"Médio","Baixo")) -> Médio
A20: 3308 | B20: =COUNTIFS(Mesarios!$A$2:$A$112,$A20) -> 4 | C20: =IF(COUNTIFS(Mesarios!$A$2:$A$112,$A20,Mesarios!$B$2:$B$112,C$1)>0,"✓","VAGO") -> ✓ | D20: =IF(COUNTIFS(Mesarios!$A$2:$A$112,$A20,Mesarios!$B$2:$B$112,D$1)>0,"✓","VAGO") -> ✓ | E20: =IF(COUNTIFS(Mesarios!$A$2:$A$112,$A20,Mesarios!$B$2:$B$112,E$1)>0,"✓","VAGO") -> ✓ | F20: =IF(COUNTIFS(Mesarios!$A$2:$A$112,$A20,Mesarios!$B$2:$B$112,F$1)>0,"✓","VAGO") -> ✓ | G20: =COUNTIFS(Mesarios!$A$2:$A$112,$A20,Mesarios!$E$2:$E$112,"SIM") -> 4 | H20: =COUNTIFS(Mesarios!$A$2:$A$112,$A20,Mesarios!$E$2:$E$112,"NAO") -> 0 | I20: =COUNTIFS(Mesarios!$A$2:$A$112,$A20,Mesarios!$E$2:$E$112,"0006/2026")+COUNTIFS(Mesarios!$A$2:$A$112,$A20,Mesarios!$E$2:$E$112,"-") -> 0 | J20: =COUNTIF(C20:F20,"VAGO") -> 0 | K20: =IF(B20<4,"Mesa com "&B20&" designados","")&IF(AND(B20<4,G20<3)," · ","")&IF(G20<3,"Só "&G20&" presentes","") | M20: 399 | N20: 295 | O20: =IF(N20>=$N$34,"Alto",IF(N20>=$N$35,"Médio","Baixo")) -> Baixo | P20: 396 | Q20: 204 | R20: =P20-Q20 -> 192 | S20: =Q20/P20 -> 0.51515152 | T20: =Q20-N20 -> -91 | U20: =Q20/N20-1 -> -0.30847458 | V20: =RANK(Q20,$Q$2:$Q$29)+COUNTIF($Q$2:Q20,Q20)-1 -> 25 | W20: =IF(Q20>=$W$34,"Alto",IF(Q20>=$W$35,"Médio","Baixo")) -> Baixo
A21: 3309 | B21: =COUNTIFS(Mesarios!$A$2:$A$112,$A21) -> 4 | C21: =IF(COUNTIFS(Mesarios!$A$2:$A$112,$A21,Mesarios!$B$2:$B$112,C$1)>0,"✓","VAGO") -> ✓ | D21: =IF(COUNTIFS(Mesarios!$A$2:$A$112,$A21,Mesarios!$B$2:$B$112,D$1)>0,"✓","VAGO") -> ✓ | E21: =IF(COUNTIFS(Mesarios!$A$2:$A$112,$A21,Mesarios!$B$2:$B$112,E$1)>0,"✓","VAGO") -> ✓ | F21: =IF(COUNTIFS(Mesarios!$A$2:$A$112,$A21,Mesarios!$B$2:$B$112,F$1)>0,"✓","VAGO") -> ✓ | G21: =COUNTIFS(Mesarios!$A$2:$A$112,$A21,Mesarios!$E$2:$E$112,"SIM") -> 4 | H21: =COUNTIFS(Mesarios!$A$2:$A$112,$A21,Mesarios!$E$2:$E$112,"NAO") -> 0 | I21: =COUNTIFS(Mesarios!$A$2:$A$112,$A21,Mesarios!$E$2:$E$112,"0006/2026")+COUNTIFS(Mesarios!$A$2:$A$112,$A21,Mesarios!$E$2:$E$112,"-") -> 0 | J21: =COUNTIF(C21:F21,"VAGO") -> 0 | K21: =IF(B21<4,"Mesa com "&B21&" designados","")&IF(AND(B21<4,G21<3)," · ","")&IF(G21<3,"Só "&G21&" presentes","") | L21: 1314 | M21: 615 | N21: 395 | O21: =IF(N21>=$N$34,"Alto",IF(N21>=$N$35,"Médio","Baixo")) -> Baixo | P21: 614 | Q21: 278 | R21: =P21-Q21 -> 336 | S21: =Q21/P21 -> 0.45276873 | T21: =Q21-N21 -> -117 | U21: =Q21/N21-1 -> -0.29620253 | V21: =RANK(Q21,$Q$2:$Q$29)+COUNTIF($Q$2:Q21,Q21)-1 -> 16 | W21: =IF(Q21>=$W$34,"Alto",IF(Q21>=$W$35,"Médio","Baixo")) -> Baixo
A22: 3311 | B22: =COUNTIFS(Mesarios!$A$2:$A$112,$A22) -> 4 | C22: =IF(COUNTIFS(Mesarios!$A$2:$A$112,$A22,Mesarios!$B$2:$B$112,C$1)>0,"✓","VAGO") -> ✓ | D22: =IF(COUNTIFS(Mesarios!$A$2:$A$112,$A22,Mesarios!$B$2:$B$112,D$1)>0,"✓","VAGO") -> ✓ | E22: =IF(COUNTIFS(Mesarios!$A$2:$A$112,$A22,Mesarios!$B$2:$B$112,E$1)>0,"✓","VAGO") -> ✓ | F22: =IF(COUNTIFS(Mesarios!$A$2:$A$112,$A22,Mesarios!$B$2:$B$112,F$1)>0,"✓","VAGO") -> ✓ | G22: =COUNTIFS(Mesarios!$A$2:$A$112,$A22,Mesarios!$E$2:$E$112,"SIM") -> 0 | H22: =COUNTIFS(Mesarios!$A$2:$A$112,$A22,Mesarios!$E$2:$E$112,"NAO") -> 0 | I22: =COUNTIFS(Mesarios!$A$2:$A$112,$A22,Mesarios!$E$2:$E$112,"0006/2026")+COUNTIFS(Mesarios!$A$2:$A$112,$A22,Mesarios!$E$2:$E$112,"-") -> 4 | J22: =COUNTIF(C22:F22,"VAGO") -> 0 | K22: =IF(B22<4,"Mesa com "&B22&" designados","")&IF(AND(B22<4,G22<3)," · ","")&IF(G22<3,"Só "&G22&" presentes","") -> Só 0 presentes | L22: 3913 | M22: 630 | N22: 466 | O22: =IF(N22>=$N$34,"Alto",IF(N22>=$N$35,"Médio","Baixo")) -> Médio | P22: 626 | Q22: 384 | R22: =P22-Q22 -> 242 | S22: =Q22/P22 -> 0.61341853 | T22: =Q22-N22 -> -82 | U22: =Q22/N22-1 -> -0.17596567 | V22: =RANK(Q22,$Q$2:$Q$29)+COUNTIF($Q$2:Q22,Q22)-1 -> 4 | W22: =IF(Q22>=$W$34,"Alto",IF(Q22>=$W$35,"Médio","Baixo")) -> Médio
A23: 3313 | B23: =COUNTIFS(Mesarios!$A$2:$A$112,$A23) -> 4 | C23: =IF(COUNTIFS(Mesarios!$A$2:$A$112,$A23,Mesarios!$B$2:$B$112,C$1)>0,"✓","VAGO") -> ✓ | D23: =IF(COUNTIFS(Mesarios!$A$2:$A$112,$A23,Mesarios!$B$2:$B$112,D$1)>0,"✓","VAGO") -> ✓ | E23: =IF(COUNTIFS(Mesarios!$A$2:$A$112,$A23,Mesarios!$B$2:$B$112,E$1)>0,"✓","VAGO") -> ✓ | F23: =IF(COUNTIFS(Mesarios!$A$2:$A$112,$A23,Mesarios!$B$2:$B$112,F$1)>0,"✓","VAGO") -> ✓ | G23: =COUNTIFS(Mesarios!$A$2:$A$112,$A23,Mesarios!$E$2:$E$112,"SIM") -> 4 | H23: =COUNTIFS(Mesarios!$A$2:$A$112,$A23,Mesarios!$E$2:$E$112,"NAO") -> 0 | I23: =COUNTIFS(Mesarios!$A$2:$A$112,$A23,Mesarios!$E$2:$E$112,"0006/2026")+COUNTIFS(Mesarios!$A$2:$A$112,$A23,Mesarios!$E$2:$E$112,"-") -> 0 | J23: =COUNTIF(C23:F23,"VAGO") -> 0 | K23: =IF(B23<4,"Mesa com "&B23&" designados","")&IF(AND(B23<4,G23<3)," · ","")&IF(G23<3,"Só "&G23&" presentes","") | L23: 3889 | M23: 797 | N23: 590 | O23: =IF(N23>=$N$34,"Alto",IF(N23>=$N$35,"Médio","Baixo")) -> Alto | P23: 792 | Q23: 492 | R23: =P23-Q23 -> 300 | S23: =Q23/P23 -> 0.62121212 | T23: =Q23-N23 -> -98 | U23: =Q23/N23-1 -> -0.16610169 | V23: =RANK(Q23,$Q$2:$Q$29)+COUNTIF($Q$2:Q23,Q23)-1 -> 3 | W23: =IF(Q23>=$W$34,"Alto",IF(Q23>=$W$35,"Médio","Baixo")) -> Alto
A24: 3315 | B24: =COUNTIFS(Mesarios!$A$2:$A$112,$A24) -> 4 | C24: =IF(COUNTIFS(Mesarios!$A$2:$A$112,$A24,Mesarios!$B$2:$B$112,C$1)>0,"✓","VAGO") -> ✓ | D24: =IF(COUNTIFS(Mesarios!$A$2:$A$112,$A24,Mesarios!$B$2:$B$112,D$1)>0,"✓","VAGO") -> ✓ | E24: =IF(COUNTIFS(Mesarios!$A$2:$A$112,$A24,Mesarios!$B$2:$B$112,E$1)>0,"✓","VAGO") -> ✓ | F24: =IF(COUNTIFS(Mesarios!$A$2:$A$112,$A24,Mesarios!$B$2:$B$112,F$1)>0,"✓","VAGO") -> ✓ | G24: =COUNTIFS(Mesarios!$A$2:$A$112,$A24,Mesarios!$E$2:$E$112,"SIM") -> 4 | H24: =COUNTIFS(Mesarios!$A$2:$A$112,$A24,Mesarios!$E$2:$E$112,"NAO") -> 0 | I24: =COUNTIFS(Mesarios!$A$2:$A$112,$A24,Mesarios!$E$2:$E$112,"0006/2026")+COUNTIFS(Mesarios!$A$2:$A$112,$A24,Mesarios!$E$2:$E$112,"-") -> 0 | J24: =COUNTIF(C24:F24,"VAGO") -> 0 | K24: =IF(B24<4,"Mesa com "&B24&" designados","")&IF(AND(B24<4,G24<3)," · ","")&IF(G24<3,"Só "&G24&" presentes","") | L24: 3778 | M24: 792 | N24: 586 | O24: =IF(N24>=$N$34,"Alto",IF(N24>=$N$35,"Médio","Baixo")) -> Alto | P24: 790 | Q24: 536 | R24: =P24-Q24 -> 254 | S24: =Q24/P24 -> 0.67848101 | T24: =Q24-N24 -> -50 | U24: =Q24/N24-1 -> -0.085324232 | V24: =RANK(Q24,$Q$2:$Q$29)+COUNTIF($Q$2:Q24,Q24)-1 -> 1 | W24: =IF(Q24>=$W$34,"Alto",IF(Q24>=$W$35,"Médio","Baixo")) -> Alto
A25: 3322 | B25: =COUNTIFS(Mesarios!$A$2:$A$112,$A25) -> 4 | C25: =IF(COUNTIFS(Mesarios!$A$2:$A$112,$A25,Mesarios!$B$2:$B$112,C$1)>0,"✓","VAGO") -> ✓ | D25: =IF(COUNTIFS(Mesarios!$A$2:$A$112,$A25,Mesarios!$B$2:$B$112,D$1)>0,"✓","VAGO") -> ✓ | E25: =IF(COUNTIFS(Mesarios!$A$2:$A$112,$A25,Mesarios!$B$2:$B$112,E$1)>0,"✓","VAGO") -> ✓ | F25: =IF(COUNTIFS(Mesarios!$A$2:$A$112,$A25,Mesarios!$B$2:$B$112,F$1)>0,"✓","VAGO") -> ✓ | G25: =COUNTIFS(Mesarios!$A$2:$A$112,$A25,Mesarios!$E$2:$E$112,"SIM") -> 2 | H25: =COUNTIFS(Mesarios!$A$2:$A$112,$A25,Mesarios!$E$2:$E$112,"NAO") -> 2 | I25: =COUNTIFS(Mesarios!$A$2:$A$112,$A25,Mesarios!$E$2:$E$112,"0006/2026")+COUNTIFS(Mesarios!$A$2:$A$112,$A25,Mesarios!$E$2:$E$112,"-") -> 0 | J25: =COUNTIF(C25:F25,"VAGO") -> 0 | K25: =IF(B25<4,"Mesa com "&B25&" designados","")&IF(AND(B25<4,G25<3)," · ","")&IF(G25<3,"Só "&G25&" presentes","") -> Só 2 presentes | L25: 3752 | M25: 794 | N25: 588 | O25: =IF(N25>=$N$34,"Alto",IF(N25>=$N$35,"Médio","Baixo")) -> Alto | P25: 792 | Q25: 503 | R25: =P25-Q25 -> 289 | S25: =Q25/P25 -> 0.63510101 | T25: =Q25-N25 -> -85 | U25: =Q25/N25-1 -> -0.14455782 | V25: =RANK(Q25,$Q$2:$Q$29)+COUNTIF($Q$2:Q25,Q25)-1 -> 2 | W25: =IF(Q25>=$W$34,"Alto",IF(Q25>=$W$35,"Médio","Baixo")) -> Alto
A26: 3442 | B26: =COUNTIFS(Mesarios!$A$2:$A$112,$A26) -> 4 | C26: =IF(COUNTIFS(Mesarios!$A$2:$A$112,$A26,Mesarios!$B$2:$B$112,C$1)>0,"✓","VAGO") -> ✓ | D26: =IF(COUNTIFS(Mesarios!$A$2:$A$112,$A26,Mesarios!$B$2:$B$112,D$1)>0,"✓","VAGO") -> ✓ | E26: =IF(COUNTIFS(Mesarios!$A$2:$A$112,$A26,Mesarios!$B$2:$B$112,E$1)>0,"✓","VAGO") -> ✓ | F26: =IF(COUNTIFS(Mesarios!$A$2:$A$112,$A26,Mesarios!$B$2:$B$112,F$1)>0,"✓","VAGO") -> ✓ | G26: =COUNTIFS(Mesarios!$A$2:$A$112,$A26,Mesarios!$E$2:$E$112,"SIM") -> 2 | H26: =COUNTIFS(Mesarios!$A$2:$A$112,$A26,Mesarios!$E$2:$E$112,"NAO") -> 2 | I26: =COUNTIFS(Mesarios!$A$2:$A$112,$A26,Mesarios!$E$2:$E$112,"0006/2026")+COUNTIFS(Mesarios!$A$2:$A$112,$A26,Mesarios!$E$2:$E$112,"-") -> 0 | J26: =COUNTIF(C26:F26,"VAGO") -> 0 | K26: =IF(B26<4,"Mesa com "&B26&" designados","")&IF(AND(B26<4,G26<3)," · ","")&IF(G26<3,"Só "&G26&" presentes","") -> Só 2 presentes | M26: 398 | N26: 295 | O26: =IF(N26>=$N$34,"Alto",IF(N26>=$N$35,"Médio","Baixo")) -> Baixo | P26: 397 | Q26: 134 | R26: =P26-Q26 -> 263 | S26: =Q26/P26 -> 0.33753149 | T26: =Q26-N26 -> -161 | U26: =Q26/N26-1 -> -0.54576271 | V26: =RANK(Q26,$Q$2:$Q$29)+COUNTIF($Q$2:Q26,Q26)-1 -> 28 | W26: =IF(Q26>=$W$34,"Alto",IF(Q26>=$W$35,"Médio","Baixo")) -> Baixo
A27: 3688 | B27: =COUNTIFS(Mesarios!$A$2:$A$112,$A27) -> 4 | C27: =IF(COUNTIFS(Mesarios!$A$2:$A$112,$A27,Mesarios!$B$2:$B$112,C$1)>0,"✓","VAGO") -> ✓ | D27: =IF(COUNTIFS(Mesarios!$A$2:$A$112,$A27,Mesarios!$B$2:$B$112,D$1)>0,"✓","VAGO") -> ✓ | E27: =IF(COUNTIFS(Mesarios!$A$2:$A$112,$A27,Mesarios!$B$2:$B$112,E$1)>0,"✓","VAGO") -> ✓ | F27: =IF(COUNTIFS(Mesarios!$A$2:$A$112,$A27,Mesarios!$B$2:$B$112,F$1)>0,"✓","VAGO") -> ✓ | G27: =COUNTIFS(Mesarios!$A$2:$A$112,$A27,Mesarios!$E$2:$E$112,"SIM") -> 2 | H27: =COUNTIFS(Mesarios!$A$2:$A$112,$A27,Mesarios!$E$2:$E$112,"NAO") -> 2 | I27: =COUNTIFS(Mesarios!$A$2:$A$112,$A27,Mesarios!$E$2:$E$112,"0006/2026")+COUNTIFS(Mesarios!$A$2:$A$112,$A27,Mesarios!$E$2:$E$112,"-") -> 0 | J27: =COUNTIF(C27:F27,"VAGO") -> 0 | K27: =IF(B27<4,"Mesa com "&B27&" designados","")&IF(AND(B27<4,G27<3)," · ","")&IF(G27<3,"Só "&G27&" presentes","") -> Só 2 presentes | M27: 400 | N27: 296 | O27: =IF(N27>=$N$34,"Alto",IF(N27>=$N$35,"Médio","Baixo")) -> Baixo | P27: 399 | Q27: 265 | R27: =P27-Q27 -> 134 | S27: =Q27/P27 -> 0.6641604 | T27: =Q27-N27 -> -31 | U27: =Q27/N27-1 -> -0.10472973 | V27: =RANK(Q27,$Q$2:$Q$29)+COUNTIF($Q$2:Q27,Q27)-1 -> 18 | W27: =IF(Q27>=$W$34,"Alto",IF(Q27>=$W$35,"Médio","Baixo")) -> Baixo
A28: 3832 | B28: =COUNTIFS(Mesarios!$A$2:$A$112,$A28) -> 4 | C28: =IF(COUNTIFS(Mesarios!$A$2:$A$112,$A28,Mesarios!$B$2:$B$112,C$1)>0,"✓","VAGO") -> ✓ | D28: =IF(COUNTIFS(Mesarios!$A$2:$A$112,$A28,Mesarios!$B$2:$B$112,D$1)>0,"✓","VAGO") -> ✓ | E28: =IF(COUNTIFS(Mesarios!$A$2:$A$112,$A28,Mesarios!$B$2:$B$112,E$1)>0,"✓","VAGO") -> ✓ | F28: =IF(COUNTIFS(Mesarios!$A$2:$A$112,$A28,Mesarios!$B$2:$B$112,F$1)>0,"✓","VAGO") -> ✓ | G28: =COUNTIFS(Mesarios!$A$2:$A$112,$A28,Mesarios!$E$2:$E$112,"SIM") -> 4 | H28: =COUNTIFS(Mesarios!$A$2:$A$112,$A28,Mesarios!$E$2:$E$112,"NAO") -> 0 | I28: =COUNTIFS(Mesarios!$A$2:$A$112,$A28,Mesarios!$E$2:$E$112,"0006/2026")+COUNTIFS(Mesarios!$A$2:$A$112,$A28,Mesarios!$E$2:$E$112,"-") -> 0 | J28: =COUNTIF(C28:F28,"VAGO") -> 0 | K28: =IF(B28<4,"Mesa com "&B28&" designados","")&IF(AND(B28<4,G28<3)," · ","")&IF(G28<3,"Só "&G28&" presentes","") | M28: 400 | N28: 296 | O28: =IF(N28>=$N$34,"Alto",IF(N28>=$N$35,"Médio","Baixo")) -> Baixo | P28: 399 | Q28: 306 | R28: =P28-Q28 -> 93 | S28: =Q28/P28 -> 0.76691729 | T28: =Q28-N28 -> 10 | U28: =Q28/N28-1 -> 0.033783784 | V28: =RANK(Q28,$Q$2:$Q$29)+COUNTIF($Q$2:Q28,Q28)-1 -> 13 | W28: =IF(Q28>=$W$34,"Alto",IF(Q28>=$W$35,"Médio","Baixo")) -> Baixo
A29: 3862 | B29: =COUNTIFS(Mesarios!$A$2:$A$112,$A29) -> 3 | C29: =IF(COUNTIFS(Mesarios!$A$2:$A$112,$A29,Mesarios!$B$2:$B$112,C$1)>0,"✓","VAGO") -> ✓ | D29: =IF(COUNTIFS(Mesarios!$A$2:$A$112,$A29,Mesarios!$B$2:$B$112,D$1)>0,"✓","VAGO") -> ✓ | E29: =IF(COUNTIFS(Mesarios!$A$2:$A$112,$A29,Mesarios!$B$2:$B$112,E$1)>0,"✓","VAGO") -> VAGO | F29: =IF(COUNTIFS(Mesarios!$A$2:$A$112,$A29,Mesarios!$B$2:$B$112,F$1)>0,"✓","VAGO") -> ✓ | G29: =COUNTIFS(Mesarios!$A$2:$A$112,$A29,Mesarios!$E$2:$E$112,"SIM") -> 3 | H29: =COUNTIFS(Mesarios!$A$2:$A$112,$A29,Mesarios!$E$2:$E$112,"NAO") -> 0 | I29: =COUNTIFS(Mesarios!$A$2:$A$112,$A29,Mesarios!$E$2:$E$112,"0006/2026")+COUNTIFS(Mesarios!$A$2:$A$112,$A29,Mesarios!$E$2:$E$112,"-") -> 0 | J29: =COUNTIF(C29:F29,"VAGO") -> 1 | K29: =IF(B29<4,"Mesa com "&B29&" designados","")&IF(AND(B29<4,G29<3)," · ","")&IF(G29<3,"Só "&G29&" presentes","") -> Mesa com 3 designados | M29: 400 | N29: 296 | O29: =IF(N29>=$N$34,"Alto",IF(N29>=$N$35,"Médio","Baixo")) -> Baixo | P29: 400 | Q29: 302 | R29: =P29-Q29 -> 98 | S29: =Q29/P29 -> 0.755 | T29: =Q29-N29 -> 6 | U29: =Q29/N29-1 -> 0.02027027 | V29: =RANK(Q29,$Q$2:$Q$29)+COUNTIF($Q$2:Q29,Q29)-1 -> 14 | W29: =IF(Q29>=$W$34,"Alto",IF(Q29>=$W$35,"Médio","Baixo")) -> Baixo
A30: Total | B30: =SUM(B2:B29) -> 111 | C30: =COUNTIF(C2:C29,"VAGO") -> 0 | D30: =COUNTIF(D2:D29,"VAGO") -> 0 | E30: =COUNTIF(E2:E29,"VAGO") -> 1 | F30: =COUNTIF(F2:F29,"VAGO") -> 0 | G30: =SUM(G2:G29) -> 82 | H30: =SUM(H2:H29) -> 13 | I30: =SUM(I2:I29) -> 16 | J30: =SUM(J2:J29) -> 1 | M30: =SUM(M2:M29) -> 16794 | N30: =SUM(N2:N29) -> 11499 | O30: =COUNTIF(O2:O29,"Alto")&" A · "&COUNTIF(O2:O29,"Médio")&" M · "&COUNTIF(O2:O29,"Baixo")&" B" -> 3 A · 8 M · 17 B | P30: =SUM(P2:P29) -> 16720 | Q30: =SUM(Q2:Q29) -> 8417 | R30: =P30-Q30 -> 8303 | S30: =Q30/P30 -> 0.50340909 | T30: =Q30-N30 -> -3082 | U30: =Q30/N30-1 -> -0.26802331 | W30: =COUNTIF(W2:W29,"Alto")&" A · "&COUNTIF(W2:W29,"Médio")&" M · "&COUNTIF(W2:W29,"Baixo")&" B" -> 3 A · 4 M · 21 B
A32: Fonte: Justiça Eleitoral, Elo/Convoca+ — "Relatório de Mesários por Situação", Zona 001/ZZ, Local 1015 RDS Hall 2, emitido 30/09/2026 13:42. Colunas G–I lidas da coluna "Presença" da aba Mesarios (SIM / NAO / 0006/2026 / -); linhas NAO, 0006/2026 e "-" destacadas naquela aba.
A33: Eleitores esperados: comparecimento esperado por urna (seção principal + agregada), já descontada a abstenção — base B do projeto (taxa de 2022 do condado de origem de cada seção), total 11.499 sobre 16.794 aptos. Fonte: repositório hamadmkalaf/dublineleicoesfinal, data/decisoes.json ("mesas"), de saidas/dados.json (CSVs oficiais do TSE). Premissa não oficial: não é previsão do TSE.
A34: Faixa: regra de classes do projeto (decisoes.json → "classes"): as 3 maiores urnas = Alto (vermelho); esperado ≥ 450 = Médio (amarelo); abaixo = Baixo (verde). Limiares editáveis em N34:N35. | M34: Limiar "Alto" (3ª maior urna) | N34: =LARGE(N2:N29,3) -> 586 | V34: Limiar "Alto" (3ª maior urna, efetivo) | W34: =LARGE(Q2:Q29,3) -> 492
M35: Limiar "Médio" | N35: 450 | V35: Limiar "Médio" (450 × efetivo/esperado) | W35: =ROUND(N35*Q30/N30,0) -> 329
A37: Colunas P–W: Boletins de Urna (BU) do 1º turno, 04/10/2026, Zona 001 · Local 1015 RDS Hall 2 — 28 BUs, um por urna, conferidos pela seção agregada impressa no BU. Transcritos das fotos (P e Q em azul); R = P − Q confere com o "Eleitores faltosos" impresso em todos os 28; em 3305 o comparecimento foi confirmado pela soma de votos (261 nominais + 3 brancos + 1 nulo = 265).
A38: Aptos (BU) é menor que "Aptos na urna" (col. M) em 24 das 28 urnas, igual nas outras 4 (−74 no total: 16.720 vs 16.794) — o BU é o dado do dia; M vem dos CSVs do TSE. Faixa efetiva: mesma regra da col. O, aplicada ao comparecimento efetivo; o limiar "Médio" é a regra de 450 reescalada pela razão efetivo/esperado (premissa, editável em W35).

Sheet Ranking
A1: Pos. | B1: Seção | C1: Seção agregada | D1: Aptos (BU) | E1: Esperado | F1: Efetivo | G1: Taxa | H1: Efetivo − esperado | I1: Desvio | J1: Faixa efetiva
A2: 1 | B2: =INDEX('Por secao'!$A$2:$A$29,MATCH($A2,'Por secao'!$V$2:$V$29,0)) -> 3315 | C2: =IF(INDEX('Por secao'!$L$2:$L$29,MATCH($A2,'Por secao'!$V$2:$V$29,0))="","—",INDEX('Por secao'!$L$2:$L$29,MATCH($A2,'Por secao'!$V$2:$V$29,0))) -> 3778 | D2: =INDEX('Por secao'!$P$2:$P$29,MATCH($A2,'Por secao'!$V$2:$V$29,0)) -> 790 | E2: =INDEX('Por secao'!$N$2:$N$29,MATCH($A2,'Por secao'!$V$2:$V$29,0)) -> 586 | F2: =INDEX('Por secao'!$Q$2:$Q$29,MATCH($A2,'Por secao'!$V$2:$V$29,0)) -> 536 | G2: =INDEX('Por secao'!$S$2:$S$29,MATCH($A2,'Por secao'!$V$2:$V$29,0)) -> 0.67848101 | H2: =INDEX('Por secao'!$T$2:$T$29,MATCH($A2,'Por secao'!$V$2:$V$29,0)) -> -50 | I2: =INDEX('Por secao'!$U$2:$U$29,MATCH($A2,'Por secao'!$V$2:$V$29,0)) -> -0.085324232 | J2: =INDEX('Por secao'!$W$2:$W$29,MATCH($A2,'Por secao'!$V$2:$V$29,0)) -> Alto
A3: 2 | B3: =INDEX('Por secao'!$A$2:$A$29,MATCH($A3,'Por secao'!$V$2:$V$29,0)) -> 3322 | C3: =IF(INDEX('Por secao'!$L$2:$L$29,MATCH($A3,'Por secao'!$V$2:$V$29,0))="","—",INDEX('Por secao'!$L$2:$L$29,MATCH($A3,'Por secao'!$V$2:$V$29,0))) -> 3752 | D3: =INDEX('Por secao'!$P$2:$P$29,MATCH($A3,'Por secao'!$V$2:$V$29,0)) -> 792 | E3: =INDEX('Por secao'!$N$2:$N$29,MATCH($A3,'Por secao'!$V$2:$V$29,0)) -> 588 | F3: =INDEX('Por secao'!$Q$2:$Q$29,MATCH($A3,'Por secao'!$V$2:$V$29,0)) -> 503 | G3: =INDEX('Por secao'!$S$2:$S$29,MATCH($A3,'Por secao'!$V$2:$V$29,0)) -> 0.63510101 | H3: =INDEX('Por secao'!$T$2:$T$29,MATCH($A3,'Por secao'!$V$2:$V$29,0)) -> -85 | I3: =INDEX('Por secao'!$U$2:$U$29,MATCH($A3,'Por secao'!$V$2:$V$29,0)) -> -0.14455782 | J3: =INDEX('Por secao'!$W$2:$W$29,MATCH($A3,'Por secao'!$V$2:$V$29,0)) -> Alto
A4: 3 | B4: =INDEX('Por secao'!$A$2:$A$29,MATCH($A4,'Por secao'!$V$2:$V$29,0)) -> 3313 | C4: =IF(INDEX('Por secao'!$L$2:$L$29,MATCH($A4,'Por secao'!$V$2:$V$29,0))="","—",INDEX('Por secao'!$L$2:$L$29,MATCH($A4,'Por secao'!$V$2:$V$29,0))) -> 3889 | D4: =INDEX('Por secao'!$P$2:$P$29,MATCH($A4,'Por secao'!$V$2:$V$29,0)) -> 792 | E4: =INDEX('Por secao'!$N$2:$N$29,MATCH($A4,'Por secao'!$V$2:$V$29,0)) -> 590 | F4: =INDEX('Por secao'!$Q$2:$Q$29,MATCH($A4,'Por secao'!$V$2:$V$29,0)) -> 492 | G4: =INDEX('Por secao'!$S$2:$S$29,MATCH($A4,'Por secao'!$V$2:$V$29,0)) -> 0.62121212 | H4: =INDEX('Por secao'!$T$2:$T$29,MATCH($A4,'Por secao'!$V$2:$V$29,0)) -> -98 | I4: =INDEX('Por secao'!$U$2:$U$29,MATCH($A4,'Por secao'!$V$2:$V$29,0)) -> -0.16610169 | J4: =INDEX('Por secao'!$W$2:$W$29,MATCH($A4,'Por secao'!$V$2:$V$29,0)) -> Alto
A5: 4 | B5: =INDEX('Por secao'!$A$2:$A$29,MATCH($A5,'Por secao'!$V$2:$V$29,0)) -> 3311 | C5: =IF(INDEX('Por secao'!$L$2:$L$29,MATCH($A5,'Por secao'!$V$2:$V$29,0))="","—",INDEX('Por secao'!$L$2:$L$29,MATCH($A5,'Por secao'!$V$2:$V$29,0))) -> 3913 | D5: =INDEX('Por secao'!$P$2:$P$29,MATCH($A5,'Por secao'!$V$2:$V$29,0)) -> 626 | E5: =INDEX('Por secao'!$N$2:$N$29,MATCH($A5,'Por secao'!$V$2:$V$29,0)) -> 466 | F5: =INDEX('Por secao'!$Q$2:$Q$29,MATCH($A5,'Por secao'!$V$2:$V$29,0)) -> 384 | G5: =INDEX('Por secao'!$S$2:$S$29,MATCH($A5,'Por secao'!$V$2:$V$29,0)) -> 0.61341853 | H5: =INDEX('Por secao'!$T$2:$T$29,MATCH($A5,'Por secao'!$V$2:$V$29,0)) -> -82 | I5: =INDEX('Por secao'!$U$2:$U$29,MATCH($A5,'Por secao'!$V$2:$V$29,0)) -> -0.17596567 | J5: =INDEX('Por secao'!$W$2:$W$29,MATCH($A5,'Por secao'!$V$2:$V$29,0)) -> Médio
A6: 5 | B6: =INDEX('Por secao'!$A$2:$A$29,MATCH($A6,'Por secao'!$V$2:$V$29,0)) -> 3302 | C6: =IF(INDEX('Por secao'!$L$2:$L$29,MATCH($A6,'Por secao'!$V$2:$V$29,0))="","—",INDEX('Por secao'!$L$2:$L$29,MATCH($A6,'Por secao'!$V$2:$V$29,0))) -> 3181 | D6: =INDEX('Por secao'!$P$2:$P$29,MATCH($A6,'Por secao'!$V$2:$V$29,0)) -> 763 | E6: =INDEX('Por secao'!$N$2:$N$29,MATCH($A6,'Por secao'!$V$2:$V$29,0)) -> 518 | F6: =INDEX('Por secao'!$Q$2:$Q$29,MATCH($A6,'Por secao'!$V$2:$V$29,0)) -> 373 | G6: =INDEX('Por secao'!$S$2:$S$29,MATCH($A6,'Por secao'!$V$2:$V$29,0)) -> 0.48885976 | H6: =INDEX('Por secao'!$T$2:$T$29,MATCH($A6,'Por secao'!$V$2:$V$29,0)) -> -145 | I6: =INDEX('Por secao'!$U$2:$U$29,MATCH($A6,'Por secao'!$V$2:$V$29,0)) -> -0.27992278 | J6: =INDEX('Por secao'!$W$2:$W$29,MATCH($A6,'Por secao'!$V$2:$V$29,0)) -> Médio
