Workbook

Sheet Resumo
A1: Mesários — 1º turno 04/10/2026 · RDS Hall 2 · presença consolidada (planilha × lista Elo de 30/09 × boletins de identificação de 04/10)
A3: Total de mesários | B3: =COUNTA(Mesarios!D2:D112) -> 111
A4: Presentes (SIM) | B4: =COUNTIF(Mesarios!$M$2:$M$112,"SIM") -> 92
A5: Ausentes (NAO) | B5: =COUNTIF(Mesarios!$M$2:$M$112,"NAO") -> 19
A6: Planilha SIM, mas ausente nos boletins | B6: =COUNTIF(Mesarios!$N$2:$N$112,"Planilha SIM*") -> 2
A7: Planilha NAO, mas presente nos boletins | B7: =COUNTIF(Mesarios!$N$2:$N$112,"Planilha NAO*") -> 0
A8: Planilha sem dado ("0006/2026" ou "-"), preenchido pelo boletim | B8: =COUNTIF(Mesarios!$N$2:$N$112,"Planilha sem dado*") -> 0
A9: Conferência: presentes + ausentes = total | B9: =IF(B4+B5=B3,"OK","DIVERGE") -> OK
A10: Seções (mesas) | B10: =COUNTA('Por secao'!A2:A29) -> 28
A11: Mesas com os 4 presentes | B11: =COUNTIF('Por secao'!G2:G29,4) -> 13
A12: Mesas com só 3 presentes | B12: =COUNTIF('Por secao'!G2:G29,3) -> 10
A13: Mesas com 2 ou menos presentes | B13: =COUNTIF('Por secao'!G2:G29,"<=2") -> 5
A14: Mesas com só 3 designados | B14: =COUNTIF('Por secao'!B2:B29,3) -> 1
A15: Mesas sem Presidente designado | B15: ='Por secao'!C30 -> 0
A16: Nota | B16: A coluna "Presença" original (E) foi mantida intacta. Em 16 linhas ela trazia "0006/2026" ou "-", que são valores da coluna Edital do relatório Elo, não presença; os boletins de identificação preenchem esses casos. A coluna M "Presença consolidada" (SIM = título registrado na abertura ou no fechamento de algum boletim) passou a alimentar todas as contagens deste arquivo. Onde a planilha e o boletim divergem, ver coluna N e a aba "Divergências". Totais do PDF Elo de 30/09: Total 111 · Confirmados 98 · Sem resposta 12 · Pedido de dispensa 1.
A17: Mesários fora da lista que assinaram boletim | B17: =COUNTA('Fora da lista'!A2:A10) -> 1
A18: Observação | B18: A contagem por seção (aba "Por secao") é por pessoa designada. Quem atuou em outra urna (ex.: Ludmila, Liliane, Cíntia, Ana Paula, Brenda) está descrito na aba "Boletins".

Sheet Mesarios
A1: Seção | B1: Função | C1: E-mail | D1: Nome | E1: Presença (planilha original) | F1: Chave (auxiliar) | G1: Título de eleitor | H1: Sit. mesário (Elo 30/09) | I1: Resposta (Elo 30/09) | J1: Edital | K1: Abertura (boletim) | L1: Fechamento (boletim) | M1: Presença consolidada | N1: Conferência × coluna Presença original | O1: Observação
A2: 511 | B2: Presidente | C2: Felipegustavo.ie@outlook.com | D2: FELIPE PEREIRA DE SOUZA GUSTAVO | E2: SIM | F2: =A2&"|"&B2 -> 511|Presidente | G2: 221940340213 | H2: Nomeado | I2: Confirmado | J2: 0006/2026 | K2: Sim | L2: Assinou | M2: SIM | N2: OK
A3: 511 | B3: 1º Mesário | C3: Ericcount19@hotmail.com | D3: ERIC DA SILVA MEDEIROS | E3: SIM | F3: =A3&"|"&B3 -> 511|1º Mesário | G3: 087303060701 | H3: Nomeado | I3: Confirmado | J3: 0006/2026 | K3: Sim | L3: Assinou | M3: SIM | N3: OK
A4: 511 | B4: 2º Mesário | C4: ludmilamaiamaciel@gmail.com | D4: LUDMILA MAIA MACIEL | E4: SIM | F4: =A4&"|"&B4 -> 511|2º Mesário | G4: 175842820256 | H4: Nomeado | I4: Confirmado | J4: 0006/2026 | K4: Sim, também na urna 3442 | L4: Assinou (urna 3442) | M4: SIM | N4: OK | O4: Aparece também em boletim de outra urna
A5: 511 | B5: 1º Secretário | C5: beabertocco@gmail.com | D5: BEATRIZ CARACANHA BERTOCCO | E5: SIM | F5: =A5&"|"&B5 -> 511|1º Secretário | G5: 087118000698 | H5: Nomeado | I5: Confirmado | J5: 0006/2026 | K5: Sim | L5: Assinou | M5: SIM | N5: OK
A6: 512 | B6: Presidente | C6: anaclaudiamazurok@gmail.com | D6: ANA CLAUDIA MAZUROK | E6: NAO | F6: =A6&"|"&B6 -> 512|Presidente | G6: 017860252038 | H6: Convocado | I6: Sem resposta | J6: - | K6: Não | L6: Não consta | M6: NAO | N6: OK
A7: 512 | B7: 1º Mesário | C7: caiorossiter@gmail.com | D7: CAIO CESAR ROSSITER | E7: SIM | F7: =A7&"|"&B7 -> 512|1º Mesário | G7: 024563471619 | H7: Nomeado | I7: Confirmado | J7: 0006/2026 | K7: Sim | L7: Assinou | M7: SIM | N7: OK
A8: 512 | B8: 2º Mesário | C8: camilamouramartins1987@gmail.com | D8: CAMILA MOURA MARTINS | E8: SIM | F8: =A8&"|"&B8 -> 512|2º Mesário | G8: 339405340116 | H8: Nomeado | I8: Confirmado | J8: 0006/2026 | K8: Sim | L8: Assinou | M8: SIM | N8: OK
A9: 512 | B9: 1º Secretário | C9: tbbfelix@gmail.com | D9: THAISA BERNARDES BUENO FELIX | E9: SIM | F9: =A9&"|"&B9 -> 512|1º Secretário | G9: 437733520116 | H9: Nomeado | I9: Confirmado | J9: 0006/2026 | K9: Não | L9: Não consta | M9: NAO | N9: Planilha SIM, mas ausente nos boletins | O9: Elo: Confirmado em 30/09, mas não consta em nenhum boletim
A10: 513 | B10: Presidente | C10: bianca.goulart@itamaraty.gov.br | D10: BIANCA ARAGONE RODRIGUES GOULART | E10: SIM | F10: =A10&"|"&B10 -> 513|Presidente | G10: 354520980191 | H10: Nomeado | I10: Sem resposta | J10: 0006/2026 | K10: Não | L10: Não consta | M10: NAO | N10: Planilha SIM, mas ausente nos boletins
A11: 513 | B11: 1º Mesário | C11: Luizsmania1@gmail.com | D11: LUIZ HENRIQUE DE SOUSA SMANIA | E11: SIM | F11: =A11&"|"&B11 -> 513|1º Mesário | G11: 459992490108 | H11: Nomeado | I11: Confirmado | J11: 0006/2026 | K11: Sim | L11: Assinou | M11: SIM | N11: OK
A12: 513 | B12: 2º Mesário | C12: isabelabattisti@gmail.com | D12: ISABELA FERNANDES BATTISTI PETRIS | E12: SIM | F12: =A12&"|"&B12 -> 513|2º Mesário | G12: 467362570124 | H12: Nomeado | I12: Sem resposta | J12: 0006/2026 | K12: Sim | L12: Assinou | M12: SIM | N12: OK | O12: Elo: Sem resposta em 30/09, mas compareceu
A13: 513 | B13: 1º Secretário | C13: aline.barros@outlook.com | D13: ALINE BARROS DE LIRA | E13: NAO | F13: =A13&"|"&B13 -> 513|1º Secretário | G13: 270991160167 | H13: Convocado | I13: Sem resposta | J13: - | K13: Não | L13: Não consta | M13: NAO | N13: OK
A14: 517 | B14: Presidente | C14: DAIANELEALG@GMAIL.COM | D14: DAIANE LEAL GOMES | E14: SIM | F14: =A14&"|"&B14 -> 517|Presidente | G14: 175857340221 | H14: Nomeado | I14: Confirmado | J14: 0006/2026 | K14: Sim | L14: Não consta | M14: SIM | N14: OK
A15: 517 | B15: 1º Mesário | C15: cinthia_ralmeida2@hotmail.com | D15: CINTHIA RODRIGUES DE ALMEIDA | E15: SIM | F15: =A15&"|"&B15 -> 517|1º Mesário | G15: 354752050175 | H15: Convocado | I15: Sem resposta | J15: - | K15: Sim | L15: Assinou | M15: SIM | N15: OK | O15: Elo: Sem resposta em 30/09, mas compareceu
A16: 517 | B16: 2º Mesário | C16: rafaelrodrigues2011@gmail.com | D16: RAFAEL DRUMMOND RODRIGUES | E16: SIM | F16: =A16&"|"&B16 -> 517|2º Mesário | G16: 196716430281 | H16: Convocado | I16: Sem resposta | J16: - | K16: Sim | L16: Assinou | M16: SIM | N16: OK | O16: Elo: Sem resposta em 30/09, mas compareceu
A17: 517 | B17: 1º Secretário | C17: tucanamariana@gmail.com | D17: MARIANA MACIEL DOS SANTOS SOUZA | E17: SIM | F17: =A17&"|"&B17 -> 517|1º Secretário | G17: 154661270299 | H17: Nomeado | I17: Confirmado | J17: 0006/2026 | K17: Sim | L17: Assinou | M17: SIM | N17: OK
A18: 1160 | B18: Presidente | C18: pamela.silva@itamaraty.gov.br | D18: PAMELA NASCIMENTO DA SILVA | E18: 0006/2026 | F18: =A18&"|"&B18 -> 1160|Presidente | G18: 150286960310 | H18: Nomeado | I18: Confirmado | J18: 0006/2026 | K18: Sim | L18: Assinou | M18: SIM
A19: 1160 | B19: 1º Mesário | C19: arthurgf96@gmail.com | D19: ARTHUR GRIZ FERREIRA | E19: 0006/2026 | F19: =A19&"|"&B19 -> 1160|1º Mesário | G19: 092144330809 | H19: Nomeado | I19: Confirmado | J19: 0006/2026 | K19: Sim | L19: Assinou | M19: SIM
A20: 1160 | B20: 2º Mesário | C20: crislainedealmeida@hotmail.com | D20: CRISLAINE DE SOUZA ALMEIDA | E20: 0006/2026 | F20: =A20&"|"&B20 -> 1160|2º Mesário | G20: 409193130159 | H20: Nomeado | I20: Confirmado | J20: 0006/2026 | K20: Sim | L20: Assinou | M20: SIM
A21: 1160 | B21: 1º Secretário | C21: cintiadosantos4@gmail.com | D21: CINTIA DOS SANTOS | E21: 0006/2026 | F21: =A21&"|"&B21 -> 1160|1º Secretário | G21: 228274860191 | H21: Nomeado | I21: Confirmado | J21: 0006/2026 | K21: Sim, também na urna 512 | L21: Assinou; Assinou (urna 512) | M21: SIM | O21: Aparece também em boletim de outra urna
A22: 1352 | B22: Presidente | C22: nayara.mendes@itamaraty.gov.br | D22: NAYARA GIROTO MENDES | E22: SIM | F22: =A22&"|"&B22 -> 1352|Presidente | G22: 355815510167 | H22: Nomeado | I22: Confirmado | J22: 0006/2026 | K22: Sim | L22: Assinou | M22: SIM | N22: OK
A23: 1352 | B23: 1º Mesário | C23: jessicaoliveira9316@gmail.com | D23: JESSICA DE OLIVEIRA | E23: SIM | F23: =A23&"|"&B23 -> 1352|1º Mesário | G23: 106070350450 | H23: Nomeado | I23: Confirmado | J23: 0006/2026 | K23: Sim | L23: Assinou | M23: SIM | N23: OK
A24: 1352 | B24: 2º Mesário | C24: ana.spelias@gmail.com | D24: ANA PAULA DA SILVA ELIAS | E24: SIM | F24: =A24&"|"&B24 -> 1352|2º Mesário | G24: 407856270175 | H24: Nomeado | I24: Confirmado | J24: 0006/2026 | K24: Sim | L24: Assinou (urna 3179) | M24: SIM | N24: OK | O24: Aparece também em boletim de outra urna
A25: 1352 | B25: 1º Secretário | C25: dener.asm@gmail.com | D25: DENER AUGUSTO SALES MACHADO | E25: SIM | F25: =A25&"|"&B25 -> 1352|1º Secretário | G25: 109790750485 | H25: Nomeado | I25: Confirmado | J25: 0006/2026 | K25: Sim | L25: Assinou | M25: SIM | N25: OK
A26: 3054 | B26: Presidente | C26: fabiola.malta@itamaraty.gov.br | D26: FABIOLA CRISTIANE DA SILVA MALTA | E26: SIM | F26: =A26&"|"&B26 -> 3054|Presidente | G26: 006435662011 | H26: Nomeado | I26: Confirmado | J26: 0006/2026 | K26: Sim | L26: Assinou | M26: SIM | N26: OK
A27: 3054 | B27: 1º Mesário | C27: wellingtons24.santos@gmail.com | D27: WELLINGTON DOS SANTOS | E27: SIM | F27: =A27&"|"&B27 -> 3054|1º Mesário | G27: 426020000167 | H27: Nomeado | I27: Confirmado | J27: 0006/2026 | K27: Sim | L27: Assinou | M27: SIM | N27: OK
A28: 3054 | B28: 2º Mesário | C28: almeidaedi@gmail.com | D28: EDINEIA DE ALMEIDA GOMES | E28: NAO | F28: =A28&"|"&B28 -> 3054|2º Mesário | G28: 266846740124 | H28: Nomeado | I28: Confirmado | J28: 0006/2026 | K28: Não | L28: Não consta | M28: NAO | N28: OK | O28: Elo: Confirmado em 30/09, mas não consta em nenhum boletim
A29: 3054 | B29: 1º Secretário | C29: gabrielsoares2111@gmail.com | D29: GABRIEL SOARES DE CARVALHO | E29: NAO | F29: =A29&"|"&B29 -> 3054|1º Secretário | G29: 215721420205 | H29: Nomeado | I29: Confirmado | J29: 0006/2026 | K29: Sim | L29: Assinou | M29: SIM
A30: 3078 | B30: Presidente | C30: tulio.neves@itamaraty.gov.br | D30: TULIO CARLOS DE MOURA NEVES | E30: SIM | F30: =A30&"|"&B30 -> 3078|Presidente | G30: 000122531007 | H30: Nomeado | I30: Confirmado | J30: 0006/2026 | K30: Sim | L30: Assinou | M30: SIM | N30: OK
A31: 3078 | B31: 1º Mesário | C31: tfregnani@outlook.com | D31: TATIANE CRISTINA FREGNANI | E31: SIM | F31: =A31&"|"&B31 -> 3078|1º Mesário | G31: 262347330141 | H31: Nomeado | I31: Confirmado | J31: 0006/2026 | K31: Sim | L31: Assinou | M31: SIM | N31: OK
A32: 3078 | B32: 2º Mesário | C32: danielalmelo@gmail.com | D32: DANIELA LIMA DE MELO CARETTE | E32: SIM | F32: =A32&"|"&B32 -> 3078|2º Mesário | G32: 254243240108 | H32: Nomeado | I32: Confirmado | J32: 0006/2026 | K32: Sim | L32: Assinou | M32: SIM | N32: OK
A33: 3078 | B33: 1º Secretário | C33: passos.matheus@gmail.com | D33: MATHEUS PASSOS MENDES | E33: SIM | F33: =A33&"|"&B33 -> 3078|1º Secretário | G33: 381115100116 | H33: Nomeado | I33: Confirmado | J33: 0006/2026 | K33: Sim | L33: Assinou | M33: SIM | N33: OK
A34: 3108 | B34: Presidente | C34: fernanda@brazilirelandchamber.com | D34: FERNANDA LIMA HERMANSON CARVALHO LOPES | E34: SIM | F34: =A34&"|"&B34 -> 3108|Presidente | G34: 363200640191 | H34: Nomeado | I34: Confirmado | J34: 0006/2026 | K34: Sim | L34: Não consta | M34: SIM | N34: OK
A35: 3108 | B35: 1º Mesário | C35: daniel20022304@gmail.com | D35: DANIEL DOS SANTOS JORGE | E35: SIM | F35: =A35&"|"&B35 -> 3108|1º Mesário | G35: 442676540191 | H35: Nomeado | I35: Confirmado | J35: 0006/2026 | K35: Não | L35: Não consta | M35: NAO | O35: Elo: Confirmado em 30/09, mas não consta em nenhum boletim
A36: 3108 | B36: 2º Mesário | C36: ingridmach@hotmail.com | D36: INGRID MACHADO DOS REIS | E36: SIM | F36: =A36&"|"&B36 -> 3108|2º Mesário | G36: 369375360108 | H36: Nomeado | I36: Confirmado | J36: 0006/2026 | K36: Sim | L36: Assinou | M36: SIM | N36: OK
A37: 3108 | B37: 1º Secretário | C37: dulliusdaniela@gmail.com | D37: DANIELA HADWIG DULLIUS | E37: SIM | F37: =A37&"|"&B37 -> 3108|1º Secretário | G37: 103022060469 | H37: Nomeado | I37: Confirmado | J37: 0006/2026 | K37: Sim | L37: Assinou | M37: SIM | N37: OK
A38: 3142 | B38: Presidente | C38: beatrizgilli@hotmail.com | D38: BEATRIZ GILLI HADG KARKACHI | E38: SIM | F38: =A38&"|"&B38 -> 3142|Presidente | G38: 335145160175 | H38: Nomeado | I38: Confirmado | J38: 0006/2026 | K38: Sim | L38: Assinou | M38: SIM | N38: OK
A39: 3142 | B39: 1º Mesário | C39: anabellacastroie@gmail.com | D39: ANABELLA ALVES DE CASTRO | E39: SIM | F39: =A39&"|"&B39 -> 3142|1º Mesário | G39: 091189510396 | H39: Nomeado | I39: Confirmado | J39: 0006/2026 | K39: Sim | L39: Assinou | M39: SIM | N39: OK
A40: 3142 | B40: 2º Mesário | C40: juli_tico@hotmail.com | D40: JULIANA CASSIA TAVARES DE SOUSA | E40: SIM | F40: =A40&"|"&B40 -> 3142|2º Mesário | G40: 323422120183 | H40: Nomeado | I40: Confirmado | J40: 0006/2026 | K40: Sim | L40: Assinou | M40: SIM | N40: OK
...

Sheet Presenca por secao
A1: Seção | B1: Presidente | C1: Pres. | D1: 1º Mesário | E1: Pres. | F1: 2º Mesário | G1: Pres. | H1: 1º Secretário | I1: Pres. | J1: Presentes | K1: Ausentes | L1: Outros | M1: Alerta | N1: Eleitores esperados | O1: Faixa
A2: ='Por secao'!A2 -> 511 | B2: =IFERROR(INDEX(Mesarios!$D$2:$D$112,MATCH($A2&"|"&B$1,Mesarios!$F$2:$F$112,0)),"VAGO") -> FELIPE PEREIRA DE SOUZA GUSTAVO | C2: =IFERROR(INDEX(Mesarios!$M$2:$M$112,MATCH($A2&"|"&B$1,Mesarios!$F$2:$F$112,0)),"VAGO") -> SIM | D2: =IFERROR(INDEX(Mesarios!$D$2:$D$112,MATCH($A2&"|"&D$1,Mesarios!$F$2:$F$112,0)),"VAGO") -> ERIC DA SILVA MEDEIROS | E2: =IFERROR(INDEX(Mesarios!$M$2:$M$112,MATCH($A2&"|"&D$1,Mesarios!$F$2:$F$112,0)),"VAGO") -> SIM | F2: =IFERROR(INDEX(Mesarios!$D$2:$D$112,MATCH($A2&"|"&F$1,Mesarios!$F$2:$F$112,0)),"VAGO") -> LUDMILA MAIA MACIEL | G2: =IFERROR(INDEX(Mesarios!$M$2:$M$112,MATCH($A2&"|"&F$1,Mesarios!$F$2:$F$112,0)),"VAGO") -> SIM | H2: =IFERROR(INDEX(Mesarios!$D$2:$D$112,MATCH($A2&"|"&H$1,Mesarios!$F$2:$F$112,0)),"VAGO") -> BEATRIZ CARACANHA BERTOCCO | I2: =IFERROR(INDEX(Mesarios!$M$2:$M$112,MATCH($A2&"|"&H$1,Mesarios!$F$2:$F$112,0)),"VAGO") -> SIM | J2: =COUNTIF(C2:I2,"SIM") -> 4 | K2: =COUNTIF(C2:I2,"NAO") -> 0 | L2: =COUNTIF(C2:I2,"0006/2026")+COUNTIF(C2:I2,"-") -> 0 | M2: =IF(J2>=4,"Mesa completa",IF(J2=3,"Falta 1","ATENÇÃO: só "&J2&" presentes")) -> Mesa completa | N2: ='Por secao'!N2 -> 375 | O2: ='Por secao'!O2 -> Baixo
A3: ='Por secao'!A3 -> 512 | B3: =IFERROR(INDEX(Mesarios!$D$2:$D$112,MATCH($A3&"|"&B$1,Mesarios!$F$2:$F$112,0)),"VAGO") -> ANA CLAUDIA MAZUROK | C3: =IFERROR(INDEX(Mesarios!$M$2:$M$112,MATCH($A3&"|"&B$1,Mesarios!$F$2:$F$112,0)),"VAGO") -> NAO | D3: =IFERROR(INDEX(Mesarios!$D$2:$D$112,MATCH($A3&"|"&D$1,Mesarios!$F$2:$F$112,0)),"VAGO") -> CAIO CESAR ROSSITER | E3: =IFERROR(INDEX(Mesarios!$M$2:$M$112,MATCH($A3&"|"&D$1,Mesarios!$F$2:$F$112,0)),"VAGO") -> SIM | F3: =IFERROR(INDEX(Mesarios!$D$2:$D$112,MATCH($A3&"|"&F$1,Mesarios!$F$2:$F$112,0)),"VAGO") -> CAMILA MOURA MARTINS | G3: =IFERROR(INDEX(Mesarios!$M$2:$M$112,MATCH($A3&"|"&F$1,Mesarios!$F$2:$F$112,0)),"VAGO") -> SIM | H3: =IFERROR(INDEX(Mesarios!$D$2:$D$112,MATCH($A3&"|"&H$1,Mesarios!$F$2:$F$112,0)),"VAGO") -> THAISA BERNARDES BUENO FELIX | I3: =IFERROR(INDEX(Mesarios!$M$2:$M$112,MATCH($A3&"|"&H$1,Mesarios!$F$2:$F$112,0)),"VAGO") -> NAO | J3: =COUNTIF(C3:I3,"SIM") -> 2 | K3: =COUNTIF(C3:I3,"NAO") -> 2 | L3: =COUNTIF(C3:I3,"0006/2026")+COUNTIF(C3:I3,"-") -> 0 | M3: =IF(J3>=4,"Mesa completa",IF(J3=3,"Falta 1","ATENÇÃO: só "&J3&" presentes")) -> ATENÇÃO: só 2 presentes | N3: ='Por secao'!N3 -> 355 | O3: ='Por secao'!O3 -> Baixo
A4: ='Por secao'!A4 -> 513 | B4: =IFERROR(INDEX(Mesarios!$D$2:$D$112,MATCH($A4&"|"&B$1,Mesarios!$F$2:$F$112,0)),"VAGO") -> BIANCA ARAGONE RODRIGUES GOULART | C4: =IFERROR(INDEX(Mesarios!$M$2:$M$112,MATCH($A4&"|"&B$1,Mesarios!$F$2:$F$112,0)),"VAGO") -> NAO | D4: =IFERROR(INDEX(Mesarios!$D$2:$D$112,MATCH($A4&"|"&D$1,Mesarios!$F$2:$F$112,0)),"VAGO") -> LUIZ HENRIQUE DE SOUSA SMANIA | E4: =IFERROR(INDEX(Mesarios!$M$2:$M$112,MATCH($A4&"|"&D$1,Mesarios!$F$2:$F$112,0)),"VAGO") -> SIM | F4: =IFERROR(INDEX(Mesarios!$D$2:$D$112,MATCH($A4&"|"&F$1,Mesarios!$F$2:$F$112,0)),"VAGO") -> ISABELA FERNANDES BATTISTI PETRIS | G4: =IFERROR(INDEX(Mesarios!$M$2:$M$112,MATCH($A4&"|"&F$1,Mesarios!$F$2:$F$112,0)),"VAGO") -> SIM | H4: =IFERROR(INDEX(Mesarios!$D$2:$D$112,MATCH($A4&"|"&H$1,Mesarios!$F$2:$F$112,0)),"VAGO") -> ALINE BARROS DE LIRA | I4: =IFERROR(INDEX(Mesarios!$M$2:$M$112,MATCH($A4&"|"&H$1,Mesarios!$F$2:$F$112,0)),"VAGO") -> NAO | J4: =COUNTIF(C4:I4,"SIM") -> 2 | K4: =COUNTIF(C4:I4,"NAO") -> 2 | L4: =COUNTIF(C4:I4,"0006/2026")+COUNTIF(C4:I4,"-") -> 0 | M4: =IF(J4>=4,"Mesa completa",IF(J4=3,"Falta 1","ATENÇÃO: só "&J4&" presentes")) -> ATENÇÃO: só 2 presentes | N4: ='Por secao'!N4 -> 351 | O4: ='Por secao'!O4 -> Baixo
A5: ='Por secao'!A5 -> 517 | B5: =IFERROR(INDEX(Mesarios!$D$2:$D$112,MATCH($A5&"|"&B$1,Mesarios!$F$2:$F$112,0)),"VAGO") -> DAIANE LEAL GOMES | C5: =IFERROR(INDEX(Mesarios!$M$2:$M$112,MATCH($A5&"|"&B$1,Mesarios!$F$2:$F$112,0)),"VAGO") -> SIM | D5: =IFERROR(INDEX(Mesarios!$D$2:$D$112,MATCH($A5&"|"&D$1,Mesarios!$F$2:$F$112,0)),"VAGO") -> CINTHIA RODRIGUES DE ALMEIDA | E5: =IFERROR(INDEX(Mesarios!$M$2:$M$112,MATCH($A5&"|"&D$1,Mesarios!$F$2:$F$112,0)),"VAGO") -> SIM | F5: =IFERROR(INDEX(Mesarios!$D$2:$D$112,MATCH($A5&"|"&F$1,Mesarios!$F$2:$F$112,0)),"VAGO") -> RAFAEL DRUMMOND RODRIGUES | G5: =IFERROR(INDEX(Mesarios!$M$2:$M$112,MATCH($A5&"|"&F$1,Mesarios!$F$2:$F$112,0)),"VAGO") -> SIM | H5: =IFERROR(INDEX(Mesarios!$D$2:$D$112,MATCH($A5&"|"&H$1,Mesarios!$F$2:$F$112,0)),"VAGO") -> MARIANA MACIEL DOS SANTOS SOUZA | I5: =IFERROR(INDEX(Mesarios!$M$2:$M$112,MATCH($A5&"|"&H$1,Mesarios!$F$2:$F$112,0)),"VAGO") -> SIM | J5: =COUNTIF(C5:I5,"SIM") -> 4 | K5: =COUNTIF(C5:I5,"NAO") -> 0 | L5: =COUNTIF(C5:I5,"0006/2026")+COUNTIF(C5:I5,"-") -> 0 | M5: =IF(J5>=4,"Mesa completa",IF(J5=3,"Falta 1","ATENÇÃO: só "&J5&" presentes")) -> Mesa completa | N5: ='Por secao'!N5 -> 348 | O5: ='Por secao'!O5 -> Baixo
A6: ='Por secao'!A6 -> 1160 | B6: =IFERROR(INDEX(Mesarios!$D$2:$D$112,MATCH($A6&"|"&B$1,Mesarios!$F$2:$F$112,0)),"VAGO") -> PAMELA NASCIMENTO DA SILVA | C6: =IFERROR(INDEX(Mesarios!$M$2:$M$112,MATCH($A6&"|"&B$1,Mesarios!$F$2:$F$112,0)),"VAGO") -> SIM | D6: =IFERROR(INDEX(Mesarios!$D$2:$D$112,MATCH($A6&"|"&D$1,Mesarios!$F$2:$F$112,0)),"VAGO") -> ARTHUR GRIZ FERREIRA | E6: =IFERROR(INDEX(Mesarios!$M$2:$M$112,MATCH($A6&"|"&D$1,Mesarios!$F$2:$F$112,0)),"VAGO") -> SIM | F6: =IFERROR(INDEX(Mesarios!$D$2:$D$112,MATCH($A6&"|"&F$1,Mesarios!$F$2:$F$112,0)),"VAGO") -> CRISLAINE DE SOUZA ALMEIDA | G6: =IFERROR(INDEX(Mesarios!$M$2:$M$112,MATCH($A6&"|"&F$1,Mesarios!$F$2:$F$112,0)),"VAGO") -> SIM | H6: =IFERROR(INDEX(Mesarios!$D$2:$D$112,MATCH($A6&"|"&H$1,Mesarios!$F$2:$F$112,0)),"VAGO") -> CINTIA DOS SANTOS | I6: =IFERROR(INDEX(Mesarios!$M$2:$M$112,MATCH($A6&"|"&H$1,Mesarios!$F$2:$F$112,0)),"VAGO") -> SIM | J6: =COUNTIF(C6:I6,"SIM") -> 4 | K6: =COUNTIF(C6:I6,"NAO") -> 0 | L6: =COUNTIF(C6:I6,"0006/2026")+COUNTIF(C6:I6,"-") -> 0 | M6: =IF(J6>=4,"Mesa completa",IF(J6=3,"Falta 1","ATENÇÃO: só "&J6&" presentes")) -> Mesa completa | N6: ='Por secao'!N6 -> 328 | O6: ='Por secao'!O6 -> Baixo
A7: ='Por secao'!A7 -> 1352 | B7: =IFERROR(INDEX(Mesarios!$D$2:$D$112,MATCH($A7&"|"&B$1,Mesarios!$F$2:$F$112,0)),"VAGO") -> NAYARA GIROTO MENDES | C7: =IFERROR(INDEX(Mesarios!$M$2:$M$112,MATCH($A7&"|"&B$1,Mesarios!$F$2:$F$112,0)),"VAGO") -> SIM | D7: =IFERROR(INDEX(Mesarios!$D$2:$D$112,MATCH($A7&"|"&D$1,Mesarios!$F$2:$F$112,0)),"VAGO") -> JESSICA DE OLIVEIRA | E7: =IFERROR(INDEX(Mesarios!$M$2:$M$112,MATCH($A7&"|"&D$1,Mesarios!$F$2:$F$112,0)),"VAGO") -> SIM | F7: =IFERROR(INDEX(Mesarios!$D$2:$D$112,MATCH($A7&"|"&F$1,Mesarios!$F$2:$F$112,0)),"VAGO") -> ANA PAULA DA SILVA ELIAS | G7: =IFERROR(INDEX(Mesarios!$M$2:$M$112,MATCH($A7&"|"&F$1,Mesarios!$F$2:$F$112,0)),"VAGO") -> SIM | H7: =IFERROR(INDEX(Mesarios!$D$2:$D$112,MATCH($A7&"|"&H$1,Mesarios!$F$2:$F$112,0)),"VAGO") -> DENER AUGUSTO SALES MACHADO | I7: =IFERROR(INDEX(Mesarios!$M$2:$M$112,MATCH($A7&"|"&H$1,Mesarios!$F$2:$F$112,0)),"VAGO") -> SIM | J7: =COUNTIF(C7:I7,"SIM") -> 4 | K7: =COUNTIF(C7:I7,"NAO") -> 0 | L7: =COUNTIF(C7:I7,"0006/2026")+COUNTIF(C7:I7,"-") -> 0 | M7: =IF(J7>=4,"Mesa completa",IF(J7=3,"Falta 1","ATENÇÃO: só "&J7&" presentes")) -> Mesa completa | N7: ='Por secao'!N7 -> 328 | O7: ='Por secao'!O7 -> Baixo
A8: ='Por secao'!A8 -> 3054 | B8: =IFERROR(INDEX(Mesarios!$D$2:$D$112,MATCH($A8&"|"&B$1,Mesarios!$F$2:$F$112,0)),"VAGO") -> FABIOLA CRISTIANE DA SILVA MALTA | C8: =IFERROR(INDEX(Mesarios!$M$2:$M$112,MATCH($A8&"|"&B$1,Mesarios!$F$2:$F$112,0)),"VAGO") -> SIM | D8: =IFERROR(INDEX(Mesarios!$D$2:$D$112,MATCH($A8&"|"&D$1,Mesarios!$F$2:$F$112,0)),"VAGO") -> WELLINGTON DOS SANTOS | E8: =IFERROR(INDEX(Mesarios!$M$2:$M$112,MATCH($A8&"|"&D$1,Mesarios!$F$2:$F$112,0)),"VAGO") -> SIM | F8: =IFERROR(INDEX(Mesarios!$D$2:$D$112,MATCH($A8&"|"&F$1,Mesarios!$F$2:$F$112,0)),"VAGO") -> EDINEIA DE ALMEIDA GOMES | G8: =IFERROR(INDEX(Mesarios!$M$2:$M$112,MATCH($A8&"|"&F$1,Mesarios!$F$2:$F$112,0)),"VAGO") -> NAO | H8: =IFERROR(INDEX(Mesarios!$D$2:$D$112,MATCH($A8&"|"&H$1,Mesarios!$F$2:$F$112,0)),"VAGO") -> GABRIEL SOARES DE CARVALHO | I8: =IFERROR(INDEX(Mesarios!$M$2:$M$112,MATCH($A8&"|"&H$1,Mesarios!$F$2:$F$112,0)),"VAGO") -> SIM | J8: =COUNTIF(C8:I8,"SIM") -> 3 | K8: =COUNTIF(C8:I8,"NAO") -> 1 | L8: =COUNTIF(C8:I8,"0006/2026")+COUNTIF(C8:I8,"-") -> 0 | M8: =IF(J8>=4,"Mesa completa",IF(J8=3,"Falta 1","ATENÇÃO: só "&J8&" presentes")) -> Falta 1 | N8: ='Por secao'!N8 -> 325 | O8: ='Por secao'!O8 -> Baixo
A9: ='Por secao'!A9 -> 3078 | B9: =IFERROR(INDEX(Mesarios!$D$2:$D$112,MATCH($A9&"|"&B$1,Mesarios!$F$2:$F$112,0)),"VAGO") -> TULIO CARLOS DE MOURA NEVES | C9: =IFERROR(INDEX(Mesarios!$M$2:$M$112,MATCH($A9&"|"&B$1,Mesarios!$F$2:$F$112,0)),"VAGO") -> SIM | D9: =IFERROR(INDEX(Mesarios!$D$2:$D$112,MATCH($A9&"|"&D$1,Mesarios!$F$2:$F$112,0)),"VAGO") -> TATIANE CRISTINA FREGNANI | E9: =IFERROR(INDEX(Mesarios!$M$2:$M$112,MATCH($A9&"|"&D$1,Mesarios!$F$2:$F$112,0)),"VAGO") -> SIM | F9: =IFERROR(INDEX(Mesarios!$D$2:$D$112,MATCH($A9&"|"&F$1,Mesarios!$F$2:$F$112,0)),"VAGO") -> DANIELA LIMA DE MELO CARETTE | G9: =IFERROR(INDEX(Mesarios!$M$2:$M$112,MATCH($A9&"|"&F$1,Mesarios!$F$2:$F$112,0)),"VAGO") -> SIM | H9: =IFERROR(INDEX(Mesarios!$D$2:$D$112,MATCH($A9&"|"&H$1,Mesarios!$F$2:$F$112,0)),"VAGO") -> MATHEUS PASSOS MENDES | I9: =IFERROR(INDEX(Mesarios!$M$2:$M$112,MATCH($A9&"|"&H$1,Mesarios!$F$2:$F$112,0)),"VAGO") -> SIM | J9: =COUNTIF(C9:I9,"SIM") -> 4 | K9: =COUNTIF(C9:I9,"NAO") -> 0 | L9: =COUNTIF(C9:I9,"0006/2026")+COUNTIF(C9:I9,"-") -> 0 | M9: =IF(J9>=4,"Mesa completa",IF(J9=3,"Falta 1","ATENÇÃO: só "&J9&" presentes")) -> Mesa completa | N9: ='Por secao'!N9 -> 311 | O9: ='Por secao'!O9 -> Baixo
A10: ='Por secao'!A10 -> 3108 | B10: =IFERROR(INDEX(Mesarios!$D$2:$D$112,MATCH($A10&"|"&B$1,Mesarios!$F$2:$F$112,0)),"VAGO") -> FERNANDA LIMA HERMANSON CARVALHO LOPES | C10: =IFERROR(INDEX(Mesarios!$M$2:$M$112,MATCH($A10&"|"&B$1,Mesarios!$F$2:$F$112,0)),"VAGO") -> SIM | D10: =IFERROR(INDEX(Mesarios!$D$2:$D$112,MATCH($A10&"|"&D$1,Mesarios!$F$2:$F$112,0)),"VAGO") -> DANIEL DOS SANTOS JORGE | E10: =IFERROR(INDEX(Mesarios!$M$2:$M$112,MATCH($A10&"|"&D$1,Mesarios!$F$2:$F$112,0)),"VAGO") -> NAO | F10: =IFERROR(INDEX(Mesarios!$D$2:$D$112,MATCH($A10&"|"&F$1,Mesarios!$F$2:$F$112,0)),"VAGO") -> INGRID MACHADO DOS REIS | G10: =IFERROR(INDEX(Mesarios!$M$2:$M$112,MATCH($A10&"|"&F$1,Mesarios!$F$2:$F$112,0)),"VAGO") -> SIM | H10: =IFERROR(INDEX(Mesarios!$D$2:$D$112,MATCH($A10&"|"&H$1,Mesarios!$F$2:$F$112,0)),"VAGO") -> DANIELA HADWIG DULLIUS | I10: =IFERROR(INDEX(Mesarios!$M$2:$M$112,MATCH($A10&"|"&H$1,Mesarios!$F$2:$F$112,0)),"VAGO") -> SIM | J10: =COUNTIF(C10:I10,"SIM") -> 3 | K10: =COUNTIF(C10:I10,"NAO") -> 1 | L10: =COUNTIF(C10:I10,"0006/2026")+COUNTIF(C10:I10,"-") -> 0 | M10: =IF(J10>=4,"Mesa completa",IF(J10=3,"Falta 1","ATENÇÃO: só "&J10&" presentes")) -> Falta 1 | N10: ='Por secao'!N10 -> 467 | O10: ='Por secao'!O10 -> Médio
A11: ='Por secao'!A11 -> 3142 | B11: =IFERROR(INDEX(Mesarios!$D$2:$D$112,MATCH($A11&"|"&B$1,Mesarios!$F$2:$F$112,0)),"VAGO") -> BEATRIZ GILLI HADG KARKACHI | C11: =IFERROR(INDEX(Mesarios!$M$2:$M$112,MATCH($A11&"|"&B$1,Mesarios!$F$2:$F$112,0)),"VAGO") -> SIM | D11: =IFERROR(INDEX(Mesarios!$D$2:$D$112,MATCH($A11&"|"&D$1,Mesarios!$F$2:$F$112,0)),"VAGO") -> ANABELLA ALVES DE CASTRO | E11: =IFERROR(INDEX(Mesarios!$M$2:$M$112,MATCH($A11&"|"&D$1,Mesarios!$F$2:$F$112,0)),"VAGO") -> SIM | F11: =IFERROR(INDEX(Mesarios!$D$2:$D$112,MATCH($A11&"|"&F$1,Mesarios!$F$2:$F$112,0)),"VAGO") -> JULIANA CASSIA TAVARES DE SOUSA | G11: =IFERROR(INDEX(Mesarios!$M$2:$M$112,MATCH($A11&"|"&F$1,Mesarios!$F$2:$F$112,0)),"VAGO") -> SIM | H11: =IFERROR(INDEX(Mesarios!$D$2:$D$112,MATCH($A11&"|"&H$1,Mesarios!$F$2:$F$112,0)),"VAGO") -> LINCOLN CUBAS GUEDES | I11: =IFERROR(INDEX(Mesarios!$M$2:$M$112,MATCH($A11&"|"&H$1,Mesarios!$F$2:$F$112,0)),"VAGO") -> NAO | J11: =COUNTIF(C11:I11,"SIM") -> 3 | K11: =COUNTIF(C11:I11,"NAO") -> 1 | L11: =COUNTIF(C11:I11,"0006/2026")+COUNTIF(C11:I11,"-") -> 0 | M11: =IF(J11>=4,"Mesa completa",IF(J11=3,"Falta 1","ATENÇÃO: só "&J11&" presentes")) -> Falta 1 | N11: ='Por secao'!N11 -> 466 | O11: ='Por secao'!O11 -> Médio
A12: ='Por secao'!A12 -> 3161 | B12: =IFERROR(INDEX(Mesarios!$D$2:$D$112,MATCH($A12&"|"&B$1,Mesarios!$F$2:$F$112,0)),"VAGO") -> MARCELA TIYOKO PASSOS KONDO | C12: =IFERROR(INDEX(Mesarios!$M$2:$M$112,MATCH($A12&"|"&B$1,Mesarios!$F$2:$F$112,0)),"VAGO") -> NAO | D12: =IFERROR(INDEX(Mesarios!$D$2:$D$112,MATCH($A12&"|"&D$1,Mesarios!$F$2:$F$112,0)),"VAGO") -> TALITA MORTARI MONTYSUMA | E12: =IFERROR(INDEX(Mesarios!$M$2:$M$112,MATCH($A12&"|"&D$1,Mesarios!$F$2:$F$112,0)),"VAGO") -> SIM | F12: =IFERROR(INDEX(Mesarios!$D$2:$D$112,MATCH($A12&"|"&F$1,Mesarios!$F$2:$F$112,0)),"VAGO") -> NASTASSJA VERONICA LOUSADA GOMES | G12: =IFERROR(INDEX(Mesarios!$M$2:$M$112,MATCH($A12&"|"&F$1,Mesarios!$F$2:$F$112,0)),"VAGO") -> SIM | H12: =IFERROR(INDEX(Mesarios!$D$2:$D$112,MATCH($A12&"|"&H$1,Mesarios!$F$2:$F$112,0)),"VAGO") -> ANTHONY EDWARD DA SILVA AGAPITO | I12: =IFERROR(INDEX(Mesarios!$M$2:$M$112,MATCH($A12&"|"&H$1,Mesarios!$F$2:$F$112,0)),"VAGO") -> SIM | J12: =COUNTIF(C12:I12,"SIM") -> 3 | K12: =COUNTIF(C12:I12,"NAO") -> 1 | L12: =COUNTIF(C12:I12,"0006/2026")+COUNTIF(C12:I12,"-") -> 0 | M12: =IF(J12>=4,"Mesa completa",IF(J12=3,"Falta 1","ATENÇÃO: só "&J12&" presentes")) -> Falta 1 | N12: ='Por secao'!N12 -> 504 | O12: ='Por secao'!O12 -> Médio
A13: ='Por secao'!A13 -> 3179 | B13: =IFERROR(INDEX(Mesarios!$D$2:$D$112,MATCH($A13&"|"&B$1,Mesarios!$F$2:$F$112,0)),"VAGO") -> ELTON APARECIDO ROCHA | C13: =IFERROR(INDEX(Mesarios!$M$2:$M$112,MATCH($A13&"|"&B$1,Mesarios!$F$2:$F$112,0)),"VAGO") -> SIM | D13: =IFERROR(INDEX(Mesarios!$D$2:$D$112,MATCH($A13&"|"&D$1,Mesarios!$F$2:$F$112,0)),"VAGO") -> ANDERSON SILVERIO DE OLIVEIRA | E13: =IFERROR(INDEX(Mesarios!$M$2:$M$112,MATCH($A13&"|"&D$1,Mesarios!$F$2:$F$112,0)),"VAGO") -> NAO | F13: =IFERROR(INDEX(Mesarios!$D$2:$D$112,MATCH($A13&"|"&F$1,Mesarios!$F$2:$F$112,0)),"VAGO") -> JUSSARA VENEZA SOARES | G13: =IFERROR(INDEX(Mesarios!$M$2:$M$112,MATCH($A13&"|"&F$1,Mesarios!$F$2:$F$112,0)),"VAGO") -> NAO | H13: =IFERROR(INDEX(Mesarios!$D$2:$D$112,MATCH($A13&"|"&H$1,Mesarios!$F$2:$F$112,0)),"VAGO") -> TAYNA STETELI PERON LOPES SILVA | I13: =IFERROR(INDEX(Mesarios!$M$2:$M$112,MATCH($A13&"|"&H$1,Mesarios!$F$2:$F$112,0)),"VAGO") -> SIM | J13: =COUNTIF(C13:I13,"SIM") -> 2 | K13: =COUNTIF(C13:I13,"NAO") -> 2 | L13: =COUNTIF(C13:I13,"0006/2026")+COUNTIF(C13:I13,"-") -> 0 | M13: =IF(J13>=4,"Mesa completa",IF(J13=3,"Falta 1","ATENÇÃO: só "&J13&" presentes")) -> ATENÇÃO: só 2 presentes | N13: ='Por secao'!N13 -> 423 | O13: ='Por secao'!O13 -> Baixo
... A29: ='Por secao'!A29 -> 3862 | B29: =IFERROR(INDEX(Mesarios!$D$2:$D$112,MATCH($A29&"|"&B$1,Mesarios!$F$2:$F$112,0)),"VAGO") -> EMILLY LAÍSE PARDO XAVIER | C29: =IFERROR(INDEX(Mesarios!$M$2:$M$112,MATCH($A29&"|"&B$1,Mesarios!$F$2:$F$112,0)),"VAGO") -> SIM | D29: =IFERROR(INDEX(Mesarios!$D$2:$D$112,MATCH($A29&"|"&D$1,Mesarios!$F$2:$F$112,0)),"VAGO") -> BRUNA MARIA DE ALMEIDA CABRAL | E29: =IFERROR(INDEX(Mesarios!$M$2:$M$112,MATCH($A29&"|"&D$1,Mesarios!$F$2:$F$112,0)),"VAGO") -> SIM | F29: =IFERROR(INDEX(Mesarios!$D$2:$D$112,MATCH($A29&"|"&F$1,Mesarios!$F$2:$F$112,0)),"VAGO") -> VAGO | G29: =IFERROR(INDEX(Mesarios!$M$2:$M$112,MATCH($A29&"|"&F$1,Mesarios!$F$2:$F$112,0)),"VAGO") -> VAGO | H29: =IFERROR(INDEX(Mesarios!$D$2:$D$112,MATCH($A29&"|"&H$1,Mesarios!$F$2:$F$112,0)),"VAGO") -> IVANI BATISTA DE FREITAS MONTEIRO | I29: =IFERROR(INDEX(Mesarios!$M$2:$M$112,MATCH($A29&"|"&H$1,Mesarios!$F$2:$F$112,0)),"VAGO") -> SIM | J29: =COUNTIF(C29:I29,"SIM") -> 3 | K29: =COUNTIF(C29:I29,"NAO") -> 0 | L29: =COUNTIF(C29:I29,"0006/2026")+COUNTIF(C29:I29,"-") -> 0 | M29: =IF(J29>=4,"Mesa completa",IF(J29=3,"Falta 1","ATENÇÃO: só "&J29&" presentes")) -> Falta 1 | N29: ='Por secao'!N29 -> 296 | O29: ='Por secao'!O29 -> Baixo
A30: Total | J30: =SUM(J2:J29) -> 92 | K30: =SUM(K2:K29) -> 19 | L30: =SUM(L2:L29) -> 0 | M30: =COUNTIF(M2:M29,"Mesa completa")&" completas · "&COUNTIF(M2:M29,"Falta 1")&" falta 1 · "&COUNTIF(M2:M29,"ATENÇÃO*")&" em atenção" -> 13 completas · 10 falta 1 · 5 em atenção
A32: Leitura: nomes e presença vêm da aba Mesarios (coluna Presença). SIM = presente (verde) · NAO = ausente (vermelho) · 0006/2026 (amarelo) · "-" = sem registro (cinza) · VAGO = função sem mesário designado. Editar só a aba Mesarios; esta aba recalcula sozinha.

Sheet Por secao
A1: Seção | B1: Designados | C1: Presidente | D1: 1º Mesário | E1: 2º Mesário | F1: 1º Secretário | G1: Presentes (SIM) | H1: Ausentes (NAO) | I1: Outros (sem dado) | J1: Função vaga | K1: Alerta | L1: Seção agregada | M1: Aptos na urna | N1: Eleitores esperados | O1: Faixa
A2: 511 | B2: =COUNTIFS(Mesarios!$A$2:$A$112,$A2) -> 4 | C2: =IF(COUNTIFS(Mesarios!$A$2:$A$112,$A2,Mesarios!$B$2:$B$112,C$1)>0,"✓","VAGO") -> ✓ | D2: =IF(COUNTIFS(Mesarios!$A$2:$A$112,$A2,Mesarios!$B$2:$B$112,D$1)>0,"✓","VAGO") -> ✓ | E2: =IF(COUNTIFS(Mesarios!$A$2:$A$112,$A2,Mesarios!$B$2:$B$112,E$1)>0,"✓","VAGO") -> ✓ | F2: =IF(COUNTIFS(Mesarios!$A$2:$A$112,$A2,Mesarios!$B$2:$B$112,F$1)>0,"✓","VAGO") -> ✓ | G2: =COUNTIFS(Mesarios!$A$2:$A$112,$A2,Mesarios!$M$2:$M$112,"SIM") -> 4 | H2: =COUNTIFS(Mesarios!$A$2:$A$112,$A2,Mesarios!$M$2:$M$112,"NAO") -> 0 | I2: =COUNTIFS(Mesarios!$A$2:$A$112,$A2,Mesarios!$M$2:$M$112,"0006/2026")+COUNTIFS(Mesarios!$A$2:$A$112,$A2,Mesarios!$M$2:$M$112,"-") -> 0 | J2: =COUNTIF(C2:F2,"VAGO") -> 0 | K2: =IF(B2<4,"Mesa com "&B2&" designados","")&IF(AND(B2<4,G2<3)," · ","")&IF(G2<3,"Só "&G2&" presentes","") | L2: 1100 | M2: 582 | N2: 375 | O2: =IF(N2>=$N$34,"Alto",IF(N2>=$N$35,"Médio","Baixo")) -> Baixo
A3: 512 | B3: =COUNTIFS(Mesarios!$A$2:$A$112,$A3) -> 4 | C3: =IF(COUNTIFS(Mesarios!$A$2:$A$112,$A3,Mesarios!$B$2:$B$112,C$1)>0,"✓","VAGO") -> ✓ | D3: =IF(COUNTIFS(Mesarios!$A$2:$A$112,$A3,Mesarios!$B$2:$B$112,D$1)>0,"✓","VAGO") -> ✓ | E3: =IF(COUNTIFS(Mesarios!$A$2:$A$112,$A3,Mesarios!$B$2:$B$112,E$1)>0,"✓","VAGO") -> ✓ | F3: =IF(COUNTIFS(Mesarios!$A$2:$A$112,$A3,Mesarios!$B$2:$B$112,F$1)>0,"✓","VAGO") -> ✓ | G3: =COUNTIFS(Mesarios!$A$2:$A$112,$A3,Mesarios!$M$2:$M$112,"SIM") -> 2 | H3: =COUNTIFS(Mesarios!$A$2:$A$112,$A3,Mesarios!$M$2:$M$112,"NAO") -> 2 | I3: =COUNTIFS(Mesarios!$A$2:$A$112,$A3,Mesarios!$M$2:$M$112,"0006/2026")+COUNTIFS(Mesarios!$A$2:$A$112,$A3,Mesarios!$M$2:$M$112,"-") -> 0 | J3: =COUNTIF(C3:F3,"VAGO") -> 0 | K3: =IF(B3<4,"Mesa com "&B3&" designados","")&IF(AND(B3<4,G3<3)," · ","")&IF(G3<3,"Só "&G3&" presentes","") -> Só 2 presentes | L3: 2855 | M3: 476 | N3: 355 | O3: =IF(N3>=$N$34,"Alto",IF(N3>=$N$35,"Médio","Baixo")) -> Baixo
A4: 513 | B4: =COUNTIFS(Mesarios!$A$2:$A$112,$A4) -> 4 | C4: =IF(COUNTIFS(Mesarios!$A$2:$A$112,$A4,Mesarios!$B$2:$B$112,C$1)>0,"✓","VAGO") -> ✓ | D4: =IF(COUNTIFS(Mesarios!$A$2:$A$112,$A4,Mesarios!$B$2:$B$112,D$1)>0,"✓","VAGO") -> ✓ | E4: =IF(COUNTIFS(Mesarios!$A$2:$A$112,$A4,Mesarios!$B$2:$B$112,E$1)>0,"✓","VAGO") -> ✓ | F4: =IF(COUNTIFS(Mesarios!$A$2:$A$112,$A4,Mesarios!$B$2:$B$112,F$1)>0,"✓","VAGO") -> ✓ | G4: =COUNTIFS(Mesarios!$A$2:$A$112,$A4,Mesarios!$M$2:$M$112,"SIM") -> 2 | H4: =COUNTIFS(Mesarios!$A$2:$A$112,$A4,Mesarios!$M$2:$M$112,"NAO") -> 2 | I4: =COUNTIFS(Mesarios!$A$2:$A$112,$A4,Mesarios!$M$2:$M$112,"0006/2026")+COUNTIFS(Mesarios!$A$2:$A$112,$A4,Mesarios!$M$2:$M$112,"-") -> 0 | J4: =COUNTIF(C4:F4,"VAGO") -> 0 | K4: =IF(B4<4,"Mesa com "&B4&" designados","")&IF(AND(B4<4,G4<3)," · ","")&IF(G4<3,"Só "&G4&" presentes","") -> Só 2 presentes | L4: 1105 | M4: 502 | N4: 351 | O4: =IF(N4>=$N$34,"Alto",IF(N4>=$N$35,"Médio","Baixo")) -> Baixo
A5: 517 | B5: =COUNTIFS(Mesarios!$A$2:$A$112,$A5) -> 4 | C5: =IF(COUNTIFS(Mesarios!$A$2:$A$112,$A5,Mesarios!$B$2:$B$112,C$1)>0,"✓","VAGO") -> ✓ | D5: =IF(COUNTIFS(Mesarios!$A$2:$A$112,$A5,Mesarios!$B$2:$B$112,D$1)>0,"✓","VAGO") -> ✓ | E5: =IF(COUNTIFS(Mesarios!$A$2:$A$112,$A5,Mesarios!$B$2:$B$112,E$1)>0,"✓","VAGO") -> ✓ | F5: =IF(COUNTIFS(Mesarios!$A$2:$A$112,$A5,Mesarios!$B$2:$B$112,F$1)>0,"✓","VAGO") -> ✓ | G5: =COUNTIFS(Mesarios!$A$2:$A$112,$A5,Mesarios!$M$2:$M$112,"SIM") -> 4 | H5: =COUNTIFS(Mesarios!$A$2:$A$112,$A5,Mesarios!$M$2:$M$112,"NAO") -> 0 | I5: =COUNTIFS(Mesarios!$A$2:$A$112,$A5,Mesarios!$M$2:$M$112,"0006/2026")+COUNTIFS(Mesarios!$A$2:$A$112,$A5,Mesarios!$M$2:$M$112,"-") -> 0 | J5: =COUNTIF(C5:F5,"VAGO") -> 0 | K5: =IF(B5<4,"Mesa com "&B5&" designados","")&IF(AND(B5<4,G5<3)," · ","")&IF(G5<3,"Só "&G5&" presentes","") | L5: 1292 | M5: 513 | N5: 348 | O5: =IF(N5>=$N$34,"Alto",IF(N5>=$N$35,"Médio","Baixo")) -> Baixo
A6: 1160 | B6: =COUNTIFS(Mesarios!$A$2:$A$112,$A6) -> 4 | C6: =IF(COUNTIFS(Mesarios!$A$2:$A$112,$A6,Mesarios!$B$2:$B$112,C$1)>0,"✓","VAGO") -> ✓ | D6: =IF(COUNTIFS(Mesarios!$A$2:$A$112,$A6,Mesarios!$B$2:$B$112,D$1)>0,"✓","VAGO") -> ✓ | E6: =IF(COUNTIFS(Mesarios!$A$2:$A$112,$A6,Mesarios!$B$2:$B$112,E$1)>0,"✓","VAGO") -> ✓ | F6: =IF(COUNTIFS(Mesarios!$A$2:$A$112,$A6,Mesarios!$B$2:$B$112,F$1)>0,"✓","VAGO") -> ✓ | G6: =COUNTIFS(Mesarios!$A$2:$A$112,$A6,Mesarios!$M$2:$M$112,"SIM") -> 4 | H6: =COUNTIFS(Mesarios!$A$2:$A$112,$A6,Mesarios!$M$2:$M$112,"NAO") -> 0 | I6: =COUNTIFS(Mesarios!$A$2:$A$112,$A6,Mesarios!$M$2:$M$112,"0006/2026")+COUNTIFS(Mesarios!$A$2:$A$112,$A6,Mesarios!$M$2:$M$112,"-") -> 0 | J6: =COUNTIF(C6:F6,"VAGO") -> 0 | K6: =IF(B6<4,"Mesa com "&B6&" designados","")&IF(AND(B6<4,G6<3)," · ","")&IF(G6<3,"Só "&G6&" presentes","") | L6: 3845 | M6: 473 | N6: 328 | O6: =IF(N6>=$N$34,"Alto",IF(N6>=$N$35,"Médio","Baixo")) -> Baixo
A7: 1352 | B7: =COUNTIFS(Mesarios!$A$2:$A$112,$A7) -> 4 | C7: =IF(COUNTIFS(Mesarios!$A$2:$A$112,$A7,Mesarios!$B$2:$B$112,C$1)>0,"✓","VAGO") -> ✓ | D7: =IF(COUNTIFS(Mesarios!$A$2:$A$112,$A7,Mesarios!$B$2:$B$112,D$1)>0,"✓","VAGO") -> ✓ | E7: =IF(COUNTIFS(Mesarios!$A$2:$A$112,$A7,Mesarios!$B$2:$B$112,E$1)>0,"✓","VAGO") -> ✓ | F7: =IF(COUNTIFS(Mesarios!$A$2:$A$112,$A7,Mesarios!$B$2:$B$112,F$1)>0,"✓","VAGO") -> ✓ | G7: =COUNTIFS(Mesarios!$A$2:$A$112,$A7,Mesarios!$M$2:$M$112,"SIM") -> 4 | H7: =COUNTIFS(Mesarios!$A$2:$A$112,$A7,Mesarios!$M$2:$M$112,"NAO") -> 0 | I7: =COUNTIFS(Mesarios!$A$2:$A$112,$A7,Mesarios!$M$2:$M$112,"0006/2026")+COUNTIFS(Mesarios!$A$2:$A$112,$A7,Mesarios!$M$2:$M$112,"-") -> 0 | J7: =COUNTIF(C7:F7,"VAGO") -> 0 | K7: =IF(B7<4,"Mesa com "&B7&" designados","")&IF(AND(B7<4,G7<3)," · ","")&IF(G7<3,"Só "&G7&" presentes","") | L7: 522 | M7: 462 | N7: 328 | O7: =IF(N7>=$N$34,"Alto",IF(N7>=$N$35,"Médio","Baixo")) -> Baixo
A8: 3054 | B8: =COUNTIFS(Mesarios!$A$2:$A$112,$A8) -> 4 | C8: =IF(COUNTIFS(Mesarios!$A$2:$A$112,$A8,Mesarios!$B$2:$B$112,C$1)>0,"✓","VAGO") -> ✓ | D8: =IF(COUNTIFS(Mesarios!$A$2:$A$112,$A8,Mesarios!$B$2:$B$112,D$1)>0,"✓","VAGO") -> ✓ | E8: =IF(COUNTIFS(Mesarios!$A$2:$A$112,$A8,Mesarios!$B$2:$B$112,E$1)>0,"✓","VAGO") -> ✓ | F8: =IF(COUNTIFS(Mesarios!$A$2:$A$112,$A8,Mesarios!$B$2:$B$112,F$1)>0,"✓","VAGO") -> ✓ | G8: =COUNTIFS(Mesarios!$A$2:$A$112,$A8,Mesarios!$M$2:$M$112,"SIM") -> 3 | H8: =COUNTIFS(Mesarios!$A$2:$A$112,$A8,Mesarios!$M$2:$M$112,"NAO") -> 1 | I8: =COUNTIFS(Mesarios!$A$2:$A$112,$A8,Mesarios!$M$2:$M$112,"0006/2026")+COUNTIFS(Mesarios!$A$2:$A$112,$A8,Mesarios!$M$2:$M$112,"-") -> 0 | J8: =COUNTIF(C8:F8,"VAGO") -> 0 | K8: =IF(B8<4,"Mesa com "&B8&" designados","")&IF(AND(B8<4,G8<3)," · ","")&IF(G8<3,"Só "&G8&" presentes","") | L8: 1099 | M8: 454 | N8: 325 | O8: =IF(N8>=$N$34,"Alto",IF(N8>=$N$35,"Médio","Baixo")) -> Baixo
A9: 3078 | B9: =COUNTIFS(Mesarios!$A$2:$A$112,$A9) -> 4 | C9: =IF(COUNTIFS(Mesarios!$A$2:$A$112,$A9,Mesarios!$B$2:$B$112,C$1)>0,"✓","VAGO") -> ✓ | D9: =IF(COUNTIFS(Mesarios!$A$2:$A$112,$A9,Mesarios!$B$2:$B$112,D$1)>0,"✓","VAGO") -> ✓ | E9: =IF(COUNTIFS(Mesarios!$A$2:$A$112,$A9,Mesarios!$B$2:$B$112,E$1)>0,"✓","VAGO") -> ✓ | F9: =IF(COUNTIFS(Mesarios!$A$2:$A$112,$A9,Mesarios!$B$2:$B$112,F$1)>0,"✓","VAGO") -> ✓ | G9: =COUNTIFS(Mesarios!$A$2:$A$112,$A9,Mesarios!$M$2:$M$112,"SIM") -> 4 | H9: =COUNTIFS(Mesarios!$A$2:$A$112,$A9,Mesarios!$M$2:$M$112,"NAO") -> 0 | I9: =COUNTIFS(Mesarios!$A$2:$A$112,$A9,Mesarios!$M$2:$M$112,"0006/2026")+COUNTIFS(Mesarios!$A$2:$A$112,$A9,Mesarios!$M$2:$M$112,"-") -> 0 | J9: =COUNTIF(C9:F9,"VAGO") -> 0 | K9: =IF(B9<4,"Mesa com "&B9&" designados","")&IF(AND(B9<4,G9<3)," · ","")&IF(G9<3,"Só "&G9&" presentes","") | L9: 2847 | M9: 429 | N9: 311 | O9: =IF(N9>=$N$34,"Alto",IF(N9>=$N$35,"Médio","Baixo")) -> Baixo
A10: 3108 | B10: =COUNTIFS(Mesarios!$A$2:$A$112,$A10) -> 4 | C10: =IF(COUNTIFS(Mesarios!$A$2:$A$112,$A10,Mesarios!$B$2:$B$112,C$1)>0,"✓","VAGO") -> ✓ | D10: =IF(COUNTIFS(Mesarios!$A$2:$A$112,$A10,Mesarios!$B$2:$B$112,D$1)>0,"✓","VAGO") -> ✓ | E10: =IF(COUNTIFS(Mesarios!$A$2:$A$112,$A10,Mesarios!$B$2:$B$112,E$1)>0,"✓","VAGO") -> ✓ | F10: =IF(COUNTIFS(Mesarios!$A$2:$A$112,$A10,Mesarios!$B$2:$B$112,F$1)>0,"✓","VAGO") -> ✓ | G10: =COUNTIFS(Mesarios!$A$2:$A$112,$A10,Mesarios!$M$2:$M$112,"SIM") -> 3 | H10: =COUNTIFS(Mesarios!$A$2:$A$112,$A10,Mesarios!$M$2:$M$112,"NAO") -> 1 | I10: =COUNTIFS(Mesarios!$A$2:$A$112,$A10,Mesarios!$M$2:$M$112,"0006/2026")+COUNTIFS(Mesarios!$A$2:$A$112,$A10,Mesarios!$M$2:$M$112,"-") -> 0 | J10: =COUNTIF(C10:F10,"VAGO") -> 0 | K10: =IF(B10<4,"Mesa com "&B10&" designados","")&IF(AND(B10<4,G10<3)," · ","")&IF(G10<3,"Só "&G10&" presentes","") | L10: 3422 | M10: 756 | N10: 467 | O10: =IF(N10>=$N$34,"Alto",IF(N10>=$N$35,"Médio","Baixo")) -> Médio
A11: 3142 | B11: =COUNTIFS(Mesarios!$A$2:$A$112,$A11) -> 4 | C11: =IF(COUNTIFS(Mesarios!$A$2:$A$112,$A11,Mesarios!$B$2:$B$112,C$1)>0,"✓","VAGO") -> ✓ | D11: =IF(COUNTIFS(Mesarios!$A$2:$A$112,$A11,Mesarios!$B$2:$B$112,D$1)>0,"✓","VAGO") -> ✓ | E11: =IF(COUNTIFS(Mesarios!$A$2:$A$112,$A11,Mesarios!$B$2:$B$112,E$1)>0,"✓","VAGO") -> ✓ | F11: =IF(COUNTIFS(Mesarios!$A$2:$A$112,$A11,Mesarios!$B$2:$B$112,F$1)>0,"✓","VAGO") -> ✓ | G11: =COUNTIFS(Mesarios!$A$2:$A$112,$A11,Mesarios!$M$2:$M$112,"SIM") -> 3 | H11: =COUNTIFS(Mesarios!$A$2:$A$112,$A11,Mesarios!$M$2:$M$112,"NAO") -> 1 | I11: =COUNTIFS(Mesarios!$A$2:$A$112,$A11,Mesarios!$M$2:$M$112,"0006/2026")+COUNTIFS(Mesarios!$A$2:$A$112,$A11,Mesarios!$M$2:$M$112,"-") -> 0 | J11: =COUNTIF(C11:F11,"VAGO") -> 0 | K11: =IF(B11<4,"Mesa com "&B11&" designados","")&IF(AND(B11<4,G11<3)," · ","")&IF(G11<3,"Só "&G11&" presentes","") | L11: 1278 | M11: 793 | N11: 466 | O11: =IF(N11>=$N$34,"Alto",IF(N11>=$N$35,"Médio","Baixo")) -> Médio
A12: 3161 | B12: =COUNTIFS(Mesarios!$A$2:$A$112,$A12) -> 4 | C12: =IF(COUNTIFS(Mesarios!$A$2:$A$112,$A12,Mesarios!$B$2:$B$112,C$1)>0,"✓","VAGO") -> ✓ | D12: =IF(COUNTIFS(Mesarios!$A$2:$A$112,$A12,Mesarios!$B$2:$B$112,D$1)>0,"✓","VAGO") -> ✓ | E12: =IF(COUNTIFS(Mesarios!$A$2:$A$112,$A12,Mesarios!$B$2:$B$112,E$1)>0,"✓","VAGO") -> ✓ | F12: =IF(COUNTIFS(Mesarios!$A$2:$A$112,$A12,Mesarios!$B$2:$B$112,F$1)>0,"✓","VAGO") -> ✓ | G12: =COUNTIFS(Mesarios!$A$2:$A$112,$A12,Mesarios!$M$2:$M$112,"SIM") -> 3 | H12: =COUNTIFS(Mesarios!$A$2:$A$112,$A12,Mesarios!$M$2:$M$112,"NAO") -> 1 | I12: =COUNTIFS(Mesarios!$A$2:$A$112,$A12,Mesarios!$M$2:$M$112,"0006/2026")+COUNTIFS(Mesarios!$A$2:$A$112,$A12,Mesarios!$M$2:$M$112,"-") -> 0 | J12: =COUNTIF(C12:F12,"VAGO") -> 0 | K12: =IF(B12<4,"Mesa com "&B12&" designados","")&IF(AND(B12<4,G12<3)," · ","")&IF(G12<3,"Só "&G12&" presentes","") | L12: 3307 | M12: 791 | N12: 504 | O12: =IF(N12>=$N$34,"Alto",IF(N12>=$N$35,"Médio","Baixo")) -> Médio
A13: 3179 | B13: =COUNTIFS(Mesarios!$A$2:$A$112,$A13) -> 4 | C13: =IF(COUNTIFS(Mesarios!$A$2:$A$112,$A13,Mesarios!$B$2:$B$112,C$1)>0,"✓","VAGO") -> ✓ | D13: =IF(COUNTIFS(Mesarios!$A$2:$A$112,$A13,Mesarios!$B$2:$B$112,D$1)>0,"✓","VAGO") -> ✓ | E13: =IF(COUNTIFS(Mesarios!$A$2:$A$112,$A13,Mesarios!$B$2:$B$112,E$1)>0,"✓","VAGO") -> ✓ | F13: =IF(COUNTIFS(Mesarios!$A$2:$A$112,$A13,Mesarios!$B$2:$B$112,F$1)>0,"✓","VAGO") -> ✓ | G13: =COUNTIFS(Mesarios!$A$2:$A$112,$A13,Mesarios!$M$2:$M$112,"SIM") -> 2 | H13: =COUNTIFS(Mesarios!$A$2:$A$112,$A13,Mesarios!$M$2:$M$112,"NAO") -> 2 | I13: =COUNTIFS(Mesarios!$A$2:$A$112,$A13,Mesarios!$M$2:$M$112,"0006/2026")+COUNTIFS(Mesarios!$A$2:$A$112,$A13,Mesarios!$M$2:$M$112,"-") -> 0 | J13: =COUNTIF(C13:F13,"VAGO") -> 0 | K13: =IF(B13<4,"Mesa com "&B13&" designados","")&IF(AND(B13<4,G13<3)," · ","")&IF(G13<3,"Só "&G13&" presentes","") -> Só 2 presentes | L13: 530 | M13: 676 | N13: 423 | O13: =IF(N13>=$N$34,"Alto",IF(N13>=$N$35,"Médio","Baixo")) -> Baixo
... A19: 3306 | B19: =COUNTIFS(Mesarios!$A$2:$A$112,$A19) -> 4 | C19: =IF(COUNTIFS(Mesarios!$A$2:$A$112,$A19,Mesarios!$B$2:$B$112,C$1)>0,"✓","VAGO") -> ✓ | D19: =IF(COUNTIFS(Mesarios!$A$2:$A$112,$A19,Mesarios!$B$2:$B$112,D$1)>0,"✓","VAGO") -> ✓ | E19: =IF(COUNTIFS(Mesarios!$A$2:$A$112,$A19,Mesarios!$B$2:$B$112,E$1)>0,"✓","VAGO") -> ✓ | F19: =IF(COUNTIFS(Mesarios!$A$2:$A$112,$A19,Mesarios!$B$2:$B$112,F$1)>0,"✓","VAGO") -> ✓ | G19: =COUNTIFS(Mesarios!$A$2:$A$112,$A19,Mesarios!$M$2:$M$112,"SIM") -> 4 | H19: =COUNTIFS(Mesarios!$A$2:$A$112,$A19,Mesarios!$M$2:$M$112,"NAO") -> 0 | I19: =COUNTIFS(Mesarios!$A$2:$A$112,$A19,Mesarios!$M$2:$M$112,"0006/2026")+COUNTIFS(Mesarios!$A$2:$A$112,$A19,Mesarios!$M$2:$M$112,"-") -> 0 | J19: =COUNTIF(C19:F19,"VAGO") -> 0 | K19: =IF(B19<4,"Mesa com "&B19&" designados","")&IF(AND(B19<4,G19<3)," · ","")&IF(G19<3,"Só "&G19&" presentes","") | L19: 518 | M19: 766 | N19: 515 | O19: =IF(N19>=$N$34,"Alto",IF(N19>=$N$35,"Médio","Baixo")) -> Médio
A20: 3308 | B20: =COUNTIFS(Mesarios!$A$2:$A$112,$A20) -> 4 | C20: =IF(COUNTIFS(Mesarios!$A$2:$A$112,$A20,Mesarios!$B$2:$B$112,C$1)>0,"✓","VAGO") -> ✓ | D20: =IF(COUNTIFS(Mesarios!$A$2:$A$112,$A20,Mesarios!$B$2:$B$112,D$1)>0,"✓","VAGO") -> ✓ | E20: =IF(COUNTIFS(Mesarios!$A$2:$A$112,$A20,Mesarios!$B$2:$B$112,E$1)>0,"✓","VAGO") -> ✓ | F20: =IF(COUNTIFS(Mesarios!$A$2:$A$112,$A20,Mesarios!$B$2:$B$112,F$1)>0,"✓","VAGO") -> ✓ | G20: =COUNTIFS(Mesarios!$A$2:$A$112,$A20,Mesarios!$M$2:$M$112,"SIM") -> 3 | H20: =COUNTIFS(Mesarios!$A$2:$A$112,$A20,Mesarios!$M$2:$M$112,"NAO") -> 1 | I20: =COUNTIFS(Mesarios!$A$2:$A$112,$A20,Mesarios!$M$2:$M$112,"0006/2026")+COUNTIFS(Mesarios!$A$2:$A$112,$A20,Mesarios!$M$2:$M$112,"-") -> 0 | J20: =COUNTIF(C20:F20,"VAGO") -> 0 | K20: =IF(B20<4,"Mesa com "&B20&" designados","")&IF(AND(B20<4,G20<3)," · ","")&IF(G20<3,"Só "&G20&" presentes","") | M20: 399 | N20: 295 | O20: =IF(N20>=$N$34,"Alto",IF(N20>=$N$35,"Médio","Baixo")) -> Baixo
A21: 3309 | B21: =COUNTIFS(Mesarios!$A$2:$A$112,$A21) -> 4 | C21: =IF(COUNTIFS(Mesarios!$A$2:$A$112,$A21,Mesarios!$B$2:$B$112,C$1)>0,"✓","VAGO") -> ✓ | D21: =IF(COUNTIFS(Mesarios!$A$2:$A$112,$A21,Mesarios!$B$2:$B$112,D$1)>0,"✓","VAGO") -> ✓ | E21: =IF(COUNTIFS(Mesarios!$A$2:$A$112,$A21,Mesarios!$B$2:$B$112,E$1)>0,"✓","VAGO") -> ✓ | F21: =IF(COUNTIFS(Mesarios!$A$2:$A$112,$A21,Mesarios!$B$2:$B$112,F$1)>0,"✓","VAGO") -> ✓ | G21: =COUNTIFS(Mesarios!$A$2:$A$112,$A21,Mesarios!$M$2:$M$112,"SIM") -> 4 | H21: =COUNTIFS(Mesarios!$A$2:$A$112,$A21,Mesarios!$M$2:$M$112,"NAO") -> 0 | I21: =COUNTIFS(Mesarios!$A$2:$A$112,$A21,Mesarios!$M$2:$M$112,"0006/2026")+COUNTIFS(Mesarios!$A$2:$A$112,$A21,Mesarios!$M$2:$M$112,"-") -> 0 | J21: =COUNTIF(C21:F21,"VAGO") -> 0 | K21: =IF(B21<4,"Mesa com "&B21&" designados","")&IF(AND(B21<4,G21<3)," · ","")&IF(G21<3,"Só "&G21&" presentes","") | L21: 1314 | M21: 615 | N21: 395 | O21: =IF(N21>=$N$34,"Alto",IF(N21>=$N$35,"Médio","Baixo")) -> Baixo
A22: 3311 | B22: =COUNTIFS(Mesarios!$A$2:$A$112,$A22) -> 4 | C22: =IF(COUNTIFS(Mesarios!$A$2:$A$112,$A22,Mesarios!$B$2:$B$112,C$1)>0,"✓","VAGO") -> ✓ | D22: =IF(COUNTIFS(Mesarios!$A$2:$A$112,$A22,Mesarios!$B$2:$B$112,D$1)>0,"✓","VAGO") -> ✓ | E22: =IF(COUNTIFS(Mesarios!$A$2:$A$112,$A22,Mesarios!$B$2:$B$112,E$1)>0,"✓","VAGO") -> ✓ | F22: =IF(COUNTIFS(Mesarios!$A$2:$A$112,$A22,Mesarios!$B$2:$B$112,F$1)>0,"✓","VAGO") -> ✓ | G22: =COUNTIFS(Mesarios!$A$2:$A$112,$A22,Mesarios!$M$2:$M$112,"SIM") -> 4 | H22: =COUNTIFS(Mesarios!$A$2:$A$112,$A22,Mesarios!$M$2:$M$112,"NAO") -> 0 | I22: =COUNTIFS(Mesarios!$A$2:$A$112,$A22,Mesarios!$M$2:$M$112,"0006/2026")+COUNTIFS(Mesarios!$A$2:$A$112,$A22,Mesarios!$M$2:$M$112,"-") -> 0 | J22: =COUNTIF(C22:F22,"VAGO") -> 0 | K22: =IF(B22<4,"Mesa com "&B22&" designados","")&IF(AND(B22<4,G22<3)," · ","")&IF(G22<3,"Só "&G22&" presentes","") | L22: 3913 | M22: 630 | N22: 466 | O22: =IF(N22>=$N$34,"Alto",IF(N22>=$N$35,"Médio","Baixo")) -> Médio
A23: 3313 | B23: =COUNTIFS(Mesarios!$A$2:$A$112,$A23) -> 4 | C23: =IF(COUNTIFS(Mesarios!$A$2:$A$112,$A23,Mesarios!$B$2:$B$112,C$1)>0,"✓","VAGO") -> ✓ | D23: =IF(COUNTIFS(Mesarios!$A$2:$A$112,$A23,Mesarios!$B$2:$B$112,D$1)>0,"✓","VAGO") -> ✓ | E23: =IF(COUNTIFS(Mesarios!$A$2:$A$112,$A23,Mesarios!$B$2:$B$112,E$1)>0,"✓","VAGO") -> ✓ | F23: =IF(COUNTIFS(Mesarios!$A$2:$A$112,$A23,Mesarios!$B$2:$B$112,F$1)>0,"✓","VAGO") -> ✓ | G23: =COUNTIFS(Mesarios!$A$2:$A$112,$A23,Mesarios!$M$2:$M$112,"SIM") -> 4 | H23: =COUNTIFS(Mesarios!$A$2:$A$112,$A23,Mesarios!$M$2:$M$112,"NAO") -> 0 | I23: =COUNTIFS(Mesarios!$A$2:$A$112,$A23,Mesarios!$M$2:$M$112,"0006/2026")+COUNTIFS(Mesarios!$A$2:$A$112,$A23,Mesarios!$M$2:$M$112,"-") -> 0 | J23: =COUNTIF(C23:F23,"VAGO") -> 0 | K23: =IF(B23<4,"Mesa com "&B23&" designados","")&IF(AND(B23<4,G23<3)," · ","")&IF(G23<3,"Só "&G23&" presentes","") | L23: 3889 | M23: 797 | N23: 590 | O23: =IF(N23>=$N$34,"Alto",IF(N23>=$N$35,"Médio","Baixo")) -> Alto
A24: 3315 | B24: =COUNTIFS(Mesarios!$A$2:$A$112,$A24) -> 4 | C24: =IF(COUNTIFS(Mesarios!$A$2:$A$112,$A24,Mesarios!$B$2:$B$112,C$1)>0,"✓","VAGO") -> ✓ | D24: =IF(COUNTIFS(Mesarios!$A$2:$A$112,$A24,Mesarios!$B$2:$B$112,D$1)>0,"✓","VAGO") -> ✓ | E24: =IF(COUNTIFS(Mesarios!$A$2:$A$112,$A24,Mesarios!$B$2:$B$112,E$1)>0,"✓","VAGO") -> ✓ | F24: =IF(COUNTIFS(Mesarios!$A$2:$A$112,$A24,Mesarios!$B$2:$B$112,F$1)>0,"✓","VAGO") -> ✓ | G24: =COUNTIFS(Mesarios!$A$2:$A$112,$A24,Mesarios!$M$2:$M$112,"SIM") -> 2 | H24: =COUNTIFS(Mesarios!$A$2:$A$112,$A24,Mesarios!$M$2:$M$112,"NAO") -> 2 | I24: =COUNTIFS(Mesarios!$A$2:$A$112,$A24,Mesarios!$M$2:$M$112,"0006/2026")+COUNTIFS(Mesarios!$A$2:$A$112,$A24,Mesarios!$M$2:$M$112,"-") -> 0 | J24: =COUNTIF(C24:F24,"VAGO") -> 0 | K24: =IF(B24<4,"Mesa com "&B24&" designados","")&IF(AND(B24<4,G24<3)," · ","")&IF(G24<3,"Só "&G24&" presentes","") -> Só 2 presentes | L24: 3778 | M24: 792 | N24: 586 | O24: =IF(N24>=$N$34,"Alto",IF(N24>=$N$35,"Médio","Baixo")) -> Alto
A25: 3322 | B25: =COUNTIFS(Mesarios!$A$2:$A$112,$A25) -> 4 | C25: =IF(COUNTIFS(Mesarios!$A$2:$A$112,$A25,Mesarios!$B$2:$B$112,C$1)>0,"✓","VAGO") -> ✓ | D25: =IF(COUNTIFS(Mesarios!$A$2:$A$112,$A25,Mesarios!$B$2:$B$112,D$1)>0,"✓","VAGO") -> ✓ | E25: =IF(COUNTIFS(Mesarios!$A$2:$A$112,$A25,Mesarios!$B$2:$B$112,E$1)>0,"✓","VAGO") -> ✓ | F25: =IF(COUNTIFS(Mesarios!$A$2:$A$112,$A25,Mesarios!$B$2:$B$112,F$1)>0,"✓","VAGO") -> ✓ | G25: =COUNTIFS(Mesarios!$A$2:$A$112,$A25,Mesarios!$M$2:$M$112,"SIM") -> 3 | H25: =COUNTIFS(Mesarios!$A$2:$A$112,$A25,Mesarios!$M$2:$M$112,"NAO") -> 1 | I25: =COUNTIFS(Mesarios!$A$2:$A$112,$A25,Mesarios!$M$2:$M$112,"0006/2026")+COUNTIFS(Mesarios!$A$2:$A$112,$A25,Mesarios!$M$2:$M$112,"-") -> 0 | J25: =COUNTIF(C25:F25,"VAGO") -> 0 | K25: =IF(B25<4,"Mesa com "&B25&" designados","")&IF(AND(B25<4,G25<3)," · ","")&IF(G25<3,"Só "&G25&" presentes","") | L25: 3752 | M25: 794 | N25: 588 | O25: =IF(N25>=$N$34,"Alto",IF(N25>=$N$35,"Médio","Baixo")) -> Alto
A26: 3442 | B26: =COUNTIFS(Mesarios!$A$2:$A$112,$A26) -> 4 | C26: =IF(COUNTIFS(Mesarios!$A$2:$A$112,$A26,Mesarios!$B$2:$B$112,C$1)>0,"✓","VAGO") -> ✓ | D26: =IF(COUNTIFS(Mesarios!$A$2:$A$112,$A26,Mesarios!$B$2:$B$112,D$1)>0,"✓","VAGO") -> ✓ | E26: =IF(COUNTIFS(Mesarios!$A$2:$A$112,$A26,Mesarios!$B$2:$B$112,E$1)>0,"✓","VAGO") -> ✓ | F26: =IF(COUNTIFS(Mesarios!$A$2:$A$112,$A26,Mesarios!$B$2:$B$112,F$1)>0,"✓","VAGO") -> ✓ | G26: =COUNTIFS(Mesarios!$A$2:$A$112,$A26,Mesarios!$M$2:$M$112,"SIM") -> 2 | H26: =COUNTIFS(Mesarios!$A$2:$A$112,$A26,Mesarios!$M$2:$M$112,"NAO") -> 2 | I26: =COUNTIFS(Mesarios!$A$2:$A$112,$A26,Mesarios!$M$2:$M$112,"0006/2026")+COUNTIFS(Mesarios!$A$2:$A$112,$A26,Mesarios!$M$2:$M$112,"-") -> 0 | J26: =COUNTIF(C26:F26,"VAGO") -> 0 | K26: =IF(B26<4,"Mesa com "&B26&" designados","")&IF(AND(B26<4,G26<3)," · ","")&IF(G26<3,"Só "&G26&" presentes","") -> Só 2 presentes | M26: 398 | N26: 295 | O26: =IF(N26>=$N$34,"Alto",IF(N26>=$N$35,"Médio","Baixo")) -> Baixo
A27: 3688 | B27: =COUNTIFS(Mesarios!$A$2:$A$112,$A27) -> 4 | C27: =IF(COUNTIFS(Mesarios!$A$2:$A$112,$A27,Mesarios!$B$2:$B$112,C$1)>0,"✓","VAGO") -> ✓ | D27: =IF(COUNTIFS(Mesarios!$A$2:$A$112,$A27,Mesarios!$B$2:$B$112,D$1)>0,"✓","VAGO") -> ✓ | E27: =IF(COUNTIFS(Mesarios!$A$2:$A$112,$A27,Mesarios!$B$2:$B$112,E$1)>0,"✓","VAGO") -> ✓ | F27: =IF(COUNTIFS(Mesarios!$A$2:$A$112,$A27,Mesarios!$B$2:$B$112,F$1)>0,"✓","VAGO") -> ✓ | G27: =COUNTIFS(Mesarios!$A$2:$A$112,$A27,Mesarios!$M$2:$M$112,"SIM") -> 3 | H27: =COUNTIFS(Mesarios!$A$2:$A$112,$A27,Mesarios!$M$2:$M$112,"NAO") -> 1 | I27: =COUNTIFS(Mesarios!$A$2:$A$112,$A27,Mesarios!$M$2:$M$112,"0006/2026")+COUNTIFS(Mesarios!$A$2:$A$112,$A27,Mesarios!$M$2:$M$112,"-") -> 0 | J27: =COUNTIF(C27:F27,"VAGO") -> 0 | K27: =IF(B27<4,"Mesa com "&B27&" designados","")&IF(AND(B27<4,G27<3)," · ","")&IF(G27<3,"Só "&G27&" presentes","") | M27: 400 | N27: 296 | O27: =IF(N27>=$N$34,"Alto",IF(N27>=$N$35,"Médio","Baixo")) -> Baixo
A28: 3832 | B28: =COUNTIFS(Mesarios!$A$2:$A$112,$A28) -> 4 | C28: =IF(COUNTIFS(Mesarios!$A$2:$A$112,$A28,Mesarios!$B$2:$B$112,C$1)>0,"✓","VAGO") -> ✓ | D28: =IF(COUNTIFS(Mesarios!$A$2:$A$112,$A28,Mesarios!$B$2:$B$112,D$1)>0,"✓","VAGO") -> ✓ | E28: =IF(COUNTIFS(Mesarios!$A$2:$A$112,$A28,Mesarios!$B$2:$B$112,E$1)>0,"✓","VAGO") -> ✓ | F28: =IF(COUNTIFS(Mesarios!$A$2:$A$112,$A28,Mesarios!$B$2:$B$112,F$1)>0,"✓","VAGO") -> ✓ | G28: =COUNTIFS(Mesarios!$A$2:$A$112,$A28,Mesarios!$M$2:$M$112,"SIM") -> 4 | H28: =COUNTIFS(Mesarios!$A$2:$A$112,$A28,Mesarios!$M$2:$M$112,"NAO") -> 0 | I28: =COUNTIFS(Mesarios!$A$2:$A$112,$A28,Mesarios!$M$2:$M$112,"0006/2026")+COUNTIFS(Mesarios!$A$2:$A$112,$A28,Mesarios!$M$2:$M$112,"-") -> 0 | J28: =COUNTIF(C28:F28,"VAGO") -> 0 | K28: =IF(B28<4,"Mesa com "&B28&" designados","")&IF(AND(B28<4,G28<3)," · ","")&IF(G28<3,"Só "&G28&" presentes","") | M28: 400 | N28: 296 | O28: =IF(N28>=$N$34,"Alto",IF(N28>=$N$35,"Médio","Baixo")) -> Baixo
A29: 3862 | B29: =COUNTIFS(Mesarios!$A$2:$A$112,$A29) -> 3 | C29: =IF(COUNTIFS(Mesarios!$A$2:$A$112,$A29,Mesarios!$B$2:$B$112,C$1)>0,"✓","VAGO") -> ✓ | D29: =IF(COUNTIFS(Mesarios!$A$2:$A$112,$A29,Mesarios!$B$2:$B$112,D$1)>0,"✓","VAGO") -> ✓ | E29: =IF(COUNTIFS(Mesarios!$A$2:$A$112,$A29,Mesarios!$B$2:$B$112,E$1)>0,"✓","VAGO") -> VAGO | F29: =IF(COUNTIFS(Mesarios!$A$2:$A$112,$A29,Mesarios!$B$2:$B$112,F$1)>0,"✓","VAGO") -> ✓ | G29: =COUNTIFS(Mesarios!$A$2:$A$112,$A29,Mesarios!$M$2:$M$112,"SIM") -> 3 | H29: =COUNTIFS(Mesarios!$A$2:$A$112,$A29,Mesarios!$M$2:$M$112,"NAO") -> 0 | I29: =COUNTIFS(Mesarios!$A$2:$A$112,$A29,Mesarios!$M$2:$M$112,"0006/2026")+COUNTIFS(Mesarios!$A$2:$A$112,$A29,Mesarios!$M$2:$M$112,"-") -> 0 | J29: =COUNTIF(C29:F29,"VAGO") -> 1 | K29: =IF(B29<4,"Mesa com "&B29&" designados","")&IF(AND(B29<4,G29<3)," · ","")&IF(G29<3,"Só "&G29&" presentes","") -> Mesa com 3 designados | M29: 400 | N29: 296 | O29: =IF(N29>=$N$34,"Alto",IF(N29>=$N$35,"Médio","Baixo")) -> Baixo
A30: Total | B30: =SUM(B2:B29) -> 111 | C30: =COUNTIF(C2:C29,"VAGO") -> 0 | D30: =COUNTIF(D2:D29,"VAGO") -> 0 | E30: =COUNTIF(E2:E29,"VAGO") -> 1 | F30: =COUNTIF(F2:F29,"VAGO") -> 0 | G30: =SUM(G2:G29) -> 92 | H30: =SUM(H2:H29) -> 19 | I30: =SUM(I2:I29) -> 0 | J30: =SUM(J2:J29) -> 1 | M30: =SUM(M2:M29) -> 16794 | N30: =SUM(N2:N29) -> 11499 | O30: =COUNTIF(O2:O29,"Alto")&" A · "&COUNTIF(O2:O29,"Médio")&" M · "&COUNTIF(O2:O29,"Baixo")&" B" -> 3 A · 8 M · 17 B
A32: Fonte: Justiça Eleitoral, Elo/Convoca+ — "Relatório de Mesários por Situação", Zona 001/ZZ, Local 1015 RDS Hall 2, emitido 30/09/2026 13:42. Colunas G–I lidas da coluna "Presença consolidada" (M) da aba Mesarios (SIM / NAO), que cruza a lista Elo de 30/09 com os boletins de identificação de 04/10; ver aba "Divergências".
A33: Eleitores esperados: comparecimento esperado por urna (seção principal + agregada), já descontada a abstenção — base B do projeto (taxa de 2022 do condado de origem de cada seção), total 11.499 sobre 16.794 aptos. Fonte: repositório hamadmkalaf/dublineleicoesfinal, data/decisoes.json ("mesas"), de saidas/dados.json (CSVs oficiais do TSE). Premissa não oficial: não é previsão do TSE.
A34: Faixa: regra de classes do projeto (decisoes.json → "classes"): as 3 maiores urnas = Alto (vermelho); esperado ≥ 450 = Médio (amarelo); abaixo = Baixo (verde). Limiares editáveis em N34:N35. | M34: Limiar "Alto" (3ª maior urna) | N34: =LARGE(N2:N29,3) -> 586
M35: Limiar "Médio" | N35: 450

Sheet Boletins
A1: Seção | B1: Designados (lista Elo) | C1: Registrados na abertura | D1: Registrados no fechamento | E1: Atuaram na urna (abertura ∪ fechamento) | F1: Designados ausentes | G1: De outra seção | H1: Fora da lista | I1: Observação
A2: 511 | B2: 4 | C2: 4 | D2: 3 | E2: 4 | F2: 0 | G2: 0 | H2: 0 | I2: 4 de 4 na abertura; Ludmila fechou em 3442.
A3: 512 | B3: 4 | C3: 3 | D3: 3 | E3: 3 | F3: 2 | G3: 1 | H3: 0 | I3: Ana Claudia ausente. Thaisa (planilha SIM) não aparece. Cíntia (1160) registrada também aqui.
A4: 513 | B4: 4 | C4: 2 | D4: 2 | E4: 2 | F4: 2 | G4: 0 | H4: 0 | I4: Só 2 registrados. Bianca (Presidente) não aparece; planilha marcava SIM.
A5: 517 | B5: 4 | C5: 4 | D5: 3 | E5: 4 | F5: 0 | G5: 0 | H5: 0 | I5: Daiane (Presidente) só na abertura.
A6: 1160 | B6: 4 | C6: 4 | D6: 4 | E6: 4 | F6: 0 | G6: 0 | H6: 0 | I6: 4 de 4. Cíntia também registrada em 512.
A7: 1352 | B7: 4 | C7: 4 | D7: 3 | E7: 4 | F7: 0 | G7: 0 | H7: 0 | I7: Ana Paula fechou em 3179.
A8: 3054 | B8: 4 | C8: 3 | D8: 4 | E8: 4 | F8: 1 | G8: 1 | H8: 0 | I8: Edineia ausente. Brenda (3322) assinou o fechamento aqui.
A9: 3078 | B9: 4 | C9: 4 | D9: 4 | E9: 4 | F9: 0 | G9: 0 | H9: 0 | I9: 4 de 4.
A10: 3108 | B10: 4 | C10: 3 | D10: 2 | E10: 3 | F10: 1 | G10: 0 | H10: 0 | I10: Fernanda (Presidente) só na abertura.
A11: 3142 | B11: 4 | C11: 3 | D11: 3 | E11: 3 | F11: 1 | G11: 0 | H11: 0 | I11: Lincoln (1º Secretário, planilha SIM) não aparece.
A12: 3161 | B12: 4 | C12: 3 | D12: 2 | E12: 3 | F12: 1 | G12: 0 | H12: 0 | I12: Presidente (Marcela) ausente. Assinatura de Nastassja rasurada.
A13: 3179 | B13: 4 | C13: 2 | D13: 3 | E13: 3 | F13: 2 | G13: 1 | H13: 0 | I13: Ana Paula (1352) assinou o fechamento aqui. Anderson ausente; Jussara pediu dispensa.
... A29: 3862 | B29: 3 | C29: 3 | D29: 3 | E29: 3 | F29: 0 | G29: 0 | H29: 0 | I29: Urna só com 3 designados (sem 2º Mesário); 3 de 3.
A30: Total | B30: =SUM(B2:B29) -> 111 | C30: =SUM(C2:C29) -> 95 | D30: =SUM(D2:D29) -> 88 | E30: =SUM(E2:E29) -> 97 | F30: =SUM(F2:F29) -> 20 | G30: =SUM(G2:G29) -> 5 | H30: =SUM(H2:H29) -> 1
A32: Fonte: fotos dos boletins de identificação de mesários (urna, 04/10/2026), lidas por OCR dos títulos impressos e conferidas visualmente; casadas com o título de eleitor da lista Elo/Convoca+ de 30/09. "Registrado" = título impresso na abertura/fechamento. Assinatura foi conferida à vista.

Sheet Divergências
A1: Seção | B1: Função | C1: Nome | D1: Planilha (E) | E1: Boletim (M) | F1: Tipo | G1: Observação
A2: 512 | B2: 1º Secretário | C2: THAISA BERNARDES BUENO FELIX | D2: SIM | E2: NAO | F2: Planilha SIM, mas ausente nos boletins | G2: Elo: Confirmado em 30/09, mas não consta em nenhum boletim
A3: 513 | B3: Presidente | C3: BIANCA ARAGONE RODRIGUES GOULART | D3: SIM | E3: NAO | F3: Planilha SIM, mas ausente nos boletins
A4: 3108 | B4: 1º Mesário | C4: DANIEL DOS SANTOS JORGE | D4: SIM | E4: NAO | F4: Planilha SIM, mas ausente nos boletins | G4: Elo: Confirmado em 30/09, mas não consta em nenhum boletim
A5: 3142 | B5: 1º Secretário | C5: LINCOLN CUBAS GUEDES | D5: SIM | E5: NAO | F5: Planilha SIM, mas ausente nos boletins | G5: Elo: Confirmado em 30/09, mas não consta em nenhum boletim
A6: 3308 | B6: Presidente | C6: KAIQUE AQUINO OLIVEIRA | D6: SIM | E6: NAO | F6: Planilha SIM, mas ausente nos boletins | G6: Elo: Confirmado em 30/09, mas não consta em nenhum boletim
A7: 3315 | B7: Presidente | C7: JAIR DE ASSUNÇÃO CORREIA FILHO | D7: SIM | E7: NAO | F7: Planilha SIM, mas ausente nos boletins | G7: Elo: Confirmado em 30/09, mas não consta em nenhum boletim
A8: 3315 | B8: 1º Secretário | C8: ALANE GERSSICA DE ANDRADE DO NASCIMENTO | D8: SIM | E8: NAO | F8: Planilha SIM, mas ausente nos boletins | G8: Elo: Confirmado em 30/09, mas não consta em nenhum boletim
A9: 3054 | B9: 1º Secretário | C9: GABRIEL SOARES DE CARVALHO | D9: NAO | E9: SIM | F9: Planilha NAO, mas presente nos boletins
A10: 3322 | B10: 1º Mesário | C10: BRENDA ALVES DA SILVA | D10: NAO | E10: SIM | F10: Planilha NAO, mas presente nos boletins | G10: Atuou em urna diferente da designada; Registrado só no fechamento
A11: 3688 | B11: 1º Secretário | C11: LAURO SILVA RAMOS | D11: NAO | E11: SIM | F11: Planilha NAO, mas presente nos boletins
A12: 1160 | B12: Presidente | C12: PAMELA NASCIMENTO DA SILVA | D12: 0006/2026 | E12: SIM | F12: Planilha sem dado ("0006/2026"); preenchido pelo boletim
A13: 1160 | B13: 1º Mesário | C13: ARTHUR GRIZ FERREIRA | D13: 0006/2026 | E13: SIM | F13: Planilha sem dado ("0006/2026"); preenchido pelo boletim
A14: 1160 | B14: 2º Mesário | C14: CRISLAINE DE SOUZA ALMEIDA | D14: 0006/2026 | E14: SIM | F14: Planilha sem dado ("0006/2026"); preenchido pelo boletim
A15: 1160 | B15: 1º Secretário | C15: CINTIA DOS SANTOS | D15: 0006/2026 | E15: SIM | F15: Planilha sem dado ("0006/2026"); preenchido pelo boletim | G15: Aparece também em boletim de outra urna
A16: 3245 | B16: Presidente | C16: MARIANA JURANDIR GASPARETTI | D16: 0006/2026 | E16: SIM | F16: Planilha sem dado ("0006/2026"); preenchido pelo boletim | G16: Fechamento da urna sem nomes nem assinaturas
A17: 3245 | B17: 1º Mesário | C17: JOAO GABRIEL BARBOSA CESAR | D17: 0006/2026 | E17: SIM | F17: Planilha sem dado ("0006/2026"); preenchido pelo boletim | G17: Fechamento da urna sem nomes nem assinaturas
A18: 3245 | B18: 2º Mesário | C18: TALITA DE ARAUJO CARVALHO | D18: 0006/2026 | E18: SIM | F18: Planilha sem dado ("0006/2026"); preenchido pelo boletim | G18: Fechamento da urna sem nomes nem assinaturas
A19: 3245 | B19: 1º Secretário | C19: VINICIUS ARAUJO DE OLIVEIRA | D19: - | E19: NAO | F19: Planilha sem dado ("-"); preenchido pelo boletim
A20: 3305 | B20: Presidente | C20: SARA RODRIGUES GOMES | D20: 0006/2026 | E20: NAO | F20: Planilha sem dado ("0006/2026"); preenchido pelo boletim | G20: Elo: Confirmado em 30/09, mas não consta em nenhum boletim
A21: 3305 | B21: 1º Mesário | C21: MARIA HELENA DE FRANÇA MELLO ALVES | D21: 0006/2026 | E21: SIM | F21: Planilha sem dado ("0006/2026"); preenchido pelo boletim
A22: 3305 | B22: 2º Mesário | C22: FÁBIO MARCELO DA TRINDADE | D22: 0006/2026 | E22: SIM | F22: Planilha sem dado ("0006/2026"); preenchido pelo boletim
