Workbook

Sheet Expectativa
A1: Seção | B1: Nome | C1: Expectativa | E1: Resumo
A2: ='Mesários'!A2 | B2: ='Mesários'!C2 | C2: ='Mesários'!I2 | E2: Deve comparecer | F2: =COUNTIF('Mesários'!$I$2:$I$113,"Deve comparecer")
A3: ='Mesários'!A3 | B3: ='Mesários'!C3 | C3: ='Mesários'!I3 | E3: Confirmar | F3: =COUNTIF('Mesários'!$I$2:$I$113,"Confirmar")
A4: ='Mesários'!A4 | B4: ='Mesários'!C4 | C4: ='Mesários'!I4 | E4: Não deve comparecer | F4: =COUNTIF('Mesários'!$I$2:$I$113,"Não deve comparecer")
A5: ='Mesários'!A5 | B5: ='Mesários'!C5 | C5: ='Mesários'!I5 | E5: Vago | F5: =COUNTIF('Mesários'!$I$2:$I$113,"Vago")
A6: ='Mesários'!A6 | B6: ='Mesários'!C6 | C6: ='Mesários'!I6 | E6: Total | F6: =SUM(F2:F5)
A7: ='Mesários'!A7 | B7: ='Mesários'!C7 | C7: ='Mesários'!I7
A8: ='Mesários'!A8 | B8: ='Mesários'!C8 | C8: ='Mesários'!I8
A9: ='Mesários'!A9 | B9: ='Mesários'!C9 | C9: ='Mesários'!I9
A10: ='Mesários'!A10 | B10: ='Mesários'!C10 | C10: ='Mesários'!I10
A11: ='Mesários'!A11 | B11: ='Mesários'!C11 | C11: ='Mesários'!I11
A12: ='Mesários'!A12 | B12: ='Mesários'!C12 | C12: ='Mesários'!I12
A13: ='Mesários'!A13 | B13: ='Mesários'!C13 | C13: ='Mesários'!I13
A14: ='Mesários'!A14 | B14: ='Mesários'!C14 | C14: ='Mesários'!I14
A15: ='Mesários'!A15 | B15: ='Mesários'!C15 | C15: ='Mesários'!I15
A16: ='Mesários'!A16 | B16: ='Mesários'!C16 | C16: ='Mesários'!I16
A17: ='Mesários'!A17 | B17: ='Mesários'!C17 | C17: ='Mesários'!I17
A18: ='Mesários'!A18 | B18: ='Mesários'!C18 | C18: ='Mesários'!I18
... A113: ='Mesários'!A113 | B113: ='Mesários'!C113 | C113: ='Mesários'!I113

Sheet Mesários
A1: Seção | B1: Função | C1: Nome | D1: E-mail | E1: Título de eleitor | F1: Presença 1º turno | G1: Resposta 2º turno | H1: ID no formulário | I1: Expectativa | J1: Ordem (auxiliar)
A2: 511 | B2: Presidente | C2: FELIPE PEREIRA DE SOUZA GUSTAVO | D2: Felipegustavo.ie@outlook.com | E2: 221940340213 | F2: SIM | I2: =IF(G2="SIM","Deve comparecer",IF(G2="NÃO","Não deve comparecer",IF(F2="SIM","Confirmar","Não deve comparecer"))) | J2: =IF(I2="Deve comparecer","",MATCH(A2,'Por seção'!$A$2:$A$29,0)*10+1)
A3: 511 | B3: 1º Mesário | C3: ERIC DA SILVA MEDEIROS | D3: Ericcount19@hotmail.com | E3: 087303060701 | F3: SIM | I3: =IF(G3="SIM","Deve comparecer",IF(G3="NÃO","Não deve comparecer",IF(F3="SIM","Confirmar","Não deve comparecer"))) | J3: =IF(I3="Deve comparecer","",MATCH(A3,'Por seção'!$A$2:$A$29,0)*10+2)
A4: 511 | B4: 2º Mesário | C4: LUDMILA MAIA MACIEL | D4: ludmilamaiamaciel@gmail.com | E4: 175842820256 | F4: SIM | I4: =IF(G4="SIM","Deve comparecer",IF(G4="NÃO","Não deve comparecer",IF(F4="SIM","Confirmar","Não deve comparecer"))) | J4: =IF(I4="Deve comparecer","",MATCH(A4,'Por seção'!$A$2:$A$29,0)*10+4)
A5: 511 | B5: 1º Secretário | C5: BEATRIZ CARACANHA BERTOCCO | D5: beabertocco@gmail.com | E5: 087118000698 | F5: SIM | G5: SIM | H5: 29 | I5: =IF(G5="SIM","Deve comparecer",IF(G5="NÃO","Não deve comparecer",IF(F5="SIM","Confirmar","Não deve comparecer"))) | J5: =IF(I5="Deve comparecer","",MATCH(A5,'Por seção'!$A$2:$A$29,0)*10+3)
A6: 512 | B6: Presidente | C6: ANA CLAUDIA MAZUROK | D6: anaclaudiamazurok@gmail.com | E6: 017860252038 | F6: NÃO | I6: =IF(G6="SIM","Deve comparecer",IF(G6="NÃO","Não deve comparecer",IF(F6="SIM","Confirmar","Não deve comparecer"))) | J6: =IF(I6="Deve comparecer","",MATCH(A6,'Por seção'!$A$2:$A$29,0)*10+1)
A7: 512 | B7: 1º Mesário | C7: CAIO CESAR ROSSITER | D7: caiorossiter@gmail.com | E7: 024563471619 | F7: SIM | G7: SIM | H7: 68, 69 | I7: =IF(G7="SIM","Deve comparecer",IF(G7="NÃO","Não deve comparecer",IF(F7="SIM","Confirmar","Não deve comparecer"))) | J7: =IF(I7="Deve comparecer","",MATCH(A7,'Por seção'!$A$2:$A$29,0)*10+2)
A8: 512 | B8: 2º Mesário | C8: CAMILA MOURA MARTINS | D8: camilamouramartins1987@gmail.com | E8: 339405340116 | F8: SIM | G8: SIM | H8: 19 | I8: =IF(G8="SIM","Deve comparecer",IF(G8="NÃO","Não deve comparecer",IF(F8="SIM","Confirmar","Não deve comparecer"))) | J8: =IF(I8="Deve comparecer","",MATCH(A8,'Por seção'!$A$2:$A$29,0)*10+4)
A9: 512 | B9: 1º Secretário | C9: THAISA BERNARDES BUENO FELIX | D9: tbbfelix@gmail.com | E9: 437733520116 | F9: NÃO | I9: =IF(G9="SIM","Deve comparecer",IF(G9="NÃO","Não deve comparecer",IF(F9="SIM","Confirmar","Não deve comparecer"))) | J9: =IF(I9="Deve comparecer","",MATCH(A9,'Por seção'!$A$2:$A$29,0)*10+3)
A10: 513 | B10: Presidente | C10: BIANCA ARAGONE RODRIGUES GOULART | D10: bianca.goulart@itamaraty.gov.br | E10: 354520980191 | F10: NÃO | I10: =IF(G10="SIM","Deve comparecer",IF(G10="NÃO","Não deve comparecer",IF(F10="SIM","Confirmar","Não deve comparecer"))) | J10: =IF(I10="Deve comparecer","",MATCH(A10,'Por seção'!$A$2:$A$29,0)*10+1)
A11: 513 | B11: 1º Mesário | C11: LUIZ HENRIQUE DE SOUSA SMANIA | D11: Luizsmania1@gmail.com | E11: 459992490108 | F11: SIM | G11: SIM | H11: 51 | I11: =IF(G11="SIM","Deve comparecer",IF(G11="NÃO","Não deve comparecer",IF(F11="SIM","Confirmar","Não deve comparecer"))) | J11: =IF(I11="Deve comparecer","",MATCH(A11,'Por seção'!$A$2:$A$29,0)*10+2)
A12: 513 | B12: 2º Mesário | C12: ISABELA FERNANDES BATTISTI PETRIS | D12: isabelabattisti@gmail.com | E12: 467362570124 | F12: SIM | I12: =IF(G12="SIM","Deve comparecer",IF(G12="NÃO","Não deve comparecer",IF(F12="SIM","Confirmar","Não deve comparecer"))) | J12: =IF(I12="Deve comparecer","",MATCH(A12,'Por seção'!$A$2:$A$29,0)*10+4)
A13: 513 | B13: 1º Secretário | C13: ALINE BARROS DE LIRA | D13: aline.barros@outlook.com | E13: 270991160167 | F13: NÃO | I13: =IF(G13="SIM","Deve comparecer",IF(G13="NÃO","Não deve comparecer",IF(F13="SIM","Confirmar","Não deve comparecer"))) | J13: =IF(I13="Deve comparecer","",MATCH(A13,'Por seção'!$A$2:$A$29,0)*10+3)
A14: 517 | B14: Presidente | C14: DAIANE LEAL GOMES | D14: DAIANELEALG@GMAIL.COM | E14: 175857340221 | F14: SIM | G14: SIM | H14: 30, 35 | I14: =IF(G14="SIM","Deve comparecer",IF(G14="NÃO","Não deve comparecer",IF(F14="SIM","Confirmar","Não deve comparecer"))) | J14: =IF(I14="Deve comparecer","",MATCH(A14,'Por seção'!$A$2:$A$29,0)*10+1)
A15: 517 | B15: 1º Mesário | C15: CINTHIA RODRIGUES DE ALMEIDA | D15: cinthia_ralmeida2@hotmail.com | E15: 354752050175 | F15: SIM | G15: SIM | H15: 74 | I15: =IF(G15="SIM","Deve comparecer",IF(G15="NÃO","Não deve comparecer",IF(F15="SIM","Confirmar","Não deve comparecer"))) | J15: =IF(I15="Deve comparecer","",MATCH(A15,'Por seção'!$A$2:$A$29,0)*10+2)
A16: 517 | B16: 2º Mesário | C16: RAFAEL DRUMMOND RODRIGUES | D16: rafaelrodrigues2011@gmail.com | E16: 196716430281 | F16: SIM | G16: SIM | H16: 52 | I16: =IF(G16="SIM","Deve comparecer",IF(G16="NÃO","Não deve comparecer",IF(F16="SIM","Confirmar","Não deve comparecer"))) | J16: =IF(I16="Deve comparecer","",MATCH(A16,'Por seção'!$A$2:$A$29,0)*10+4)
A17: 517 | B17: 1º Secretário | C17: MARIANA MACIEL DOS SANTOS SOUZA | D17: tucanamariana@gmail.com | E17: 154661270299 | F17: SIM | G17: SIM | H17: 15 | I17: =IF(G17="SIM","Deve comparecer",IF(G17="NÃO","Não deve comparecer",IF(F17="SIM","Confirmar","Não deve comparecer"))) | J17: =IF(I17="Deve comparecer","",MATCH(A17,'Por seção'!$A$2:$A$29,0)*10+3)
A18: 1160 | B18: Presidente | C18: PAMELA NASCIMENTO DA SILVA | D18: pamela.silva@itamaraty.gov.br | E18: 150286960310 | F18: SIM | I18: =IF(G18="SIM","Deve comparecer",IF(G18="NÃO","Não deve comparecer",IF(F18="SIM","Confirmar","Não deve comparecer"))) | J18: =IF(I18="Deve comparecer","",MATCH(A18,'Por seção'!$A$2:$A$29,0)*10+1)
A19: 1160 | B19: 1º Mesário | C19: ARTHUR GRIZ FERREIRA | D19: arthurgf96@gmail.com | E19: 092144330809 | F19: SIM | I19: =IF(G19="SIM","Deve comparecer",IF(G19="NÃO","Não deve comparecer",IF(F19="SIM","Confirmar","Não deve comparecer"))) | J19: =IF(I19="Deve comparecer","",MATCH(A19,'Por seção'!$A$2:$A$29,0)*10+2)
A20: 1160 | B20: 2º Mesário | C20: CRISLAINE DE SOUZA ALMEIDA | D20: crislainedealmeida@hotmail.com | E20: 409193130159 | F20: SIM | G20: NÃO | H20: 60 | I20: =IF(G20="SIM","Deve comparecer",IF(G20="NÃO","Não deve comparecer",IF(F20="SIM","Confirmar","Não deve comparecer"))) | J20: =IF(I20="Deve comparecer","",MATCH(A20,'Por seção'!$A$2:$A$29,0)*10+4)
A21: 1160 | B21: 1º Secretário | C21: CINTIA DOS SANTOS | D21: cintiadosantos4@gmail.com | E21: 228274860191 | F21: SIM | G21: SIM | H21: 57 | I21: =IF(G21="SIM","Deve comparecer",IF(G21="NÃO","Não deve comparecer",IF(F21="SIM","Confirmar","Não deve comparecer"))) | J21: =IF(I21="Deve comparecer","",MATCH(A21,'Por seção'!$A$2:$A$29,0)*10+3)
A22: 1352 | B22: Presidente | C22: NAYARA GIROTO MENDES | D22: nayara.mendes@itamaraty.gov.br | E22: 355815510167 | F22: SIM | I22: =IF(G22="SIM","Deve comparecer",IF(G22="NÃO","Não deve comparecer",IF(F22="SIM","Confirmar","Não deve comparecer"))) | J22: =IF(I22="Deve comparecer","",MATCH(A22,'Por seção'!$A$2:$A$29,0)*10+1)
A23: 1352 | B23: 1º Mesário | C23: JESSICA DE OLIVEIRA | D23: jessicaoliveira9316@gmail.com | E23: 106070350450 | F23: SIM | G23: SIM | H23: 2 | I23: =IF(G23="SIM","Deve comparecer",IF(G23="NÃO","Não deve comparecer",IF(F23="SIM","Confirmar","Não deve comparecer"))) | J23: =IF(I23="Deve comparecer","",MATCH(A23,'Por seção'!$A$2:$A$29,0)*10+2)
A24: 1352 | B24: 2º Mesário | C24: ANA PAULA DA SILVA ELIAS | D24: ana.spelias@gmail.com | E24: 407856270175 | F24: SIM | G24: SIM | H24: 14 | I24: =IF(G24="SIM","Deve comparecer",IF(G24="NÃO","Não deve comparecer",IF(F24="SIM","Confirmar","Não deve comparecer"))) | J24: =IF(I24="Deve comparecer","",MATCH(A24,'Por seção'!$A$2:$A$29,0)*10+4)
A25: 1352 | B25: 1º Secretário | C25: DENER AUGUSTO SALES MACHADO | D25: dener.asm@gmail.com | E25: 109790750485 | F25: SIM | G25: NÃO | H25: 54 | I25: =IF(G25="SIM","Deve comparecer",IF(G25="NÃO","Não deve comparecer",IF(F25="SIM","Confirmar","Não deve comparecer"))) | J25: =IF(I25="Deve comparecer","",MATCH(A25,'Por seção'!$A$2:$A$29,0)*10+3)
A26: 3054 | B26: Presidente | C26: FABIOLA CRISTIANE DA SILVA MALTA | D26: fabiola.malta@itamaraty.gov.br | E26: 006435662011 | F26: SIM | I26: =IF(G26="SIM","Deve comparecer",IF(G26="NÃO","Não deve comparecer",IF(F26="SIM","Confirmar","Não deve comparecer"))) | J26: =IF(I26="Deve comparecer","",MATCH(A26,'Por seção'!$A$2:$A$29,0)*10+1)
A27: 3054 | B27: 1º Mesário | C27: WELLINGTON DOS SANTOS | D27: wellingtons24.santos@gmail.com | E27: 426020000167 | F27: SIM | G27: NÃO | H27: 64 | I27: =IF(G27="SIM","Deve comparecer",IF(G27="NÃO","Não deve comparecer",IF(F27="SIM","Confirmar","Não deve comparecer"))) | J27: =IF(I27="Deve comparecer","",MATCH(A27,'Por seção'!$A$2:$A$29,0)*10+2)
A28: 3054 | B28: 2º Mesário | C28: EDINEIA DE ALMEIDA GOMES | D28: almeidaedi@gmail.com | E28: 266846740124 | F28: NÃO | I28: =IF(G28="SIM","Deve comparecer",IF(G28="NÃO","Não deve comparecer",IF(F28="SIM","Confirmar","Não deve comparecer"))) | J28: =IF(I28="Deve comparecer","",MATCH(A28,'Por seção'!$A$2:$A$29,0)*10+4)
A29: 3054 | B29: 1º Secretário | C29: GABRIEL SOARES DE CARVALHO | D29: gabrielsoares2111@gmail.com | E29: 215721420205 | F29: SIM | I29: =IF(G29="SIM","Deve comparecer",IF(G29="NÃO","Não deve comparecer",IF(F29="SIM","Confirmar","Não deve comparecer"))) | J29: =IF(I29="Deve comparecer","",MATCH(A29,'Por seção'!$A$2:$A$29,0)*10+3)
A30: 3078 | B30: Presidente | C30: TULIO CARLOS DE MOURA NEVES | D30: tulio.neves@itamaraty.gov.br | E30: 000122531007 | F30: SIM | I30: =IF(G30="SIM","Deve comparecer",IF(G30="NÃO","Não deve comparecer",IF(F30="SIM","Confirmar","Não deve comparecer"))) | J30: =IF(I30="Deve comparecer","",MATCH(A30,'Por seção'!$A$2:$A$29,0)*10+1)
A31: 3078 | B31: 1º Mesário | C31: TATIANE CRISTINA FREGNANI | D31: tfregnani@outlook.com | E31: 262347330141 | F31: SIM | G31: SIM | H31: 44 | I31: =IF(G31="SIM","Deve comparecer",IF(G31="NÃO","Não deve comparecer",IF(F31="SIM","Confirmar","Não deve comparecer"))) | J31: =IF(I31="Deve comparecer","",MATCH(A31,'Por seção'!$A$2:$A$29,0)*10+2)
A32: 3078 | B32: 2º Mesário | C32: DANIELA LIMA DE MELO CARETTE | D32: danielalmelo@gmail.com | E32: 254243240108 | F32: SIM | G32: SIM | H32: 1 | I32: =IF(G32="SIM","Deve comparecer",IF(G32="NÃO","Não deve comparecer",IF(F32="SIM","Confirmar","Não deve comparecer"))) | J32: =IF(I32="Deve comparecer","",MATCH(A32,'Por seção'!$A$2:$A$29,0)*10+4)
A33: 3078 | B33: 1º Secretário | C33: MATHEUS PASSOS MENDES | D33: passos.matheus@gmail.com | E33: 381115100116 | F33: SIM | I33: =IF(G33="SIM","Deve comparecer",IF(G33="NÃO","Não deve comparecer",IF(F33="SIM","Confirmar","Não deve comparecer"))) | J33: =IF(I33="Deve comparecer","",MATCH(A33,'Por seção'!$A$2:$A$29,0)*10+3)
A34: 3108 | B34: Presidente | C34: FERNANDA LIMA HERMANSON CARVALHO LOPES | D34: fernanda@brazilirelandchamber.com | E34: 363200640191 | F34: SIM | G34: SIM | H34: 59 | I34: =IF(G34="SIM","Deve comparecer",IF(G34="NÃO","Não deve comparecer",IF(F34="SIM","Confirmar","Não deve comparecer"))) | J34: =IF(I34="Deve comparecer","",MATCH(A34,'Por seção'!$A$2:$A$29,0)*10+1)
A35: 3108 | B35: 1º Mesário | C35: DANIEL DOS SANTOS JORGE | D35: daniel20022304@gmail.com | E35: 442676540191 | F35: NÃO | I35: =IF(G35="SIM","Deve comparecer",IF(G35="NÃO","Não deve comparecer",IF(F35="SIM","Confirmar","Não deve comparecer"))) | J35: =IF(I35="Deve comparecer","",MATCH(A35,'Por seção'!$A$2:$A$29,0)*10+2)
A36: 3108 | B36: 2º Mesário | C36: INGRID MACHADO DOS REIS | D36: ingridmach@hotmail.com | E36: 369375360108 | F36: SIM | G36: SIM | H36: 43 | I36: =IF(G36="SIM","Deve comparecer",IF(G36="NÃO","Não deve comparecer",IF(F36="SIM","Confirmar","Não deve comparecer"))) | J36: =IF(I36="Deve comparecer","",MATCH(A36,'Por seção'!$A$2:$A$29,0)*10+4)
A37: 3108 | B37: 1º Secretário | C37: DANIELA HADWIG DULLIUS | D37: dulliusdaniela@gmail.com | E37: 103022060469 | F37: SIM | I37: =IF(G37="SIM","Deve comparecer",IF(G37="NÃO","Não deve comparecer",IF(F37="SIM","Confirmar","Não deve comparecer"))) | J37: =IF(I37="Deve comparecer","",MATCH(A37,'Por seção'!$A$2:$A$29,0)*10+3)
A38: 3142 | B38: Presidente | C38: BEATRIZ GILLI HADG KARKACHI | D38: beatrizgilli@hotmail.com | E38: 335145160175 | F38: SIM | G38: SIM | H38: 47 | I38: =IF(G38="SIM","Deve comparecer",IF(G38="NÃO","Não deve comparecer",IF(F38="SIM","Confirmar","Não deve comparecer"))) | J38: =IF(I38="Deve comparecer","",MATCH(A38,'Por seção'!$A$2:$A$29,0)*10+1)
A39: 3142 | B39: 1º Mesário | C39: ANABELLA ALVES DE CASTRO | D39: anabellacastroie@gmail.com | E39: 091189510396 | F39: SIM | G39: SIM | H39: 56 | I39: =IF(G39="SIM","Deve comparecer",IF(G39="NÃO","Não deve comparecer",IF(F39="SIM","Confirmar","Não deve comparecer"))) | J39: =IF(I39="Deve comparecer","",MATCH(A39,'Por seção'!$A$2:$A$29,0)*10+2)
A40: 3142 | B40: 2º Mesário | C40: JULIANA CASSIA TAVARES DE SOUSA | D40: juli_tico@hotmail.com | E40: 323422120183 | F40: SIM | G40: SIM | H40: 16 | I40: =IF(G40="SIM","Deve comparecer",IF(G40="NÃO","Não deve comparecer",IF(F40="SIM","Confirmar","Não deve comparecer"))) | J40: =IF(I40="Deve comparecer","",MATCH(A40,'Por seção'!$A$2:$A$29,0)*10+4)
...

Sheet Funções a preencher
A1: Seção | B1: Função | C1: Nome do designado | D1: Sugestão de ação | F1: A preencher | G1: =COUNT('Mesários'!$J$2:$J$113)
A2: =IFERROR(INDEX('Mesários'!$A$2:$A$113,MATCH(SMALL('Mesários'!$J$2:$J$113,1),'Mesários'!$J$2:$J$113,0)),"") | B2: =IFERROR(INDEX('Mesários'!$B$2:$B$113,MATCH(SMALL('Mesários'!$J$2:$J$113,1),'Mesários'!$J$2:$J$113,0)),"") | C2: =IFERROR(INDEX('Mesários'!$C$2:$C$113,MATCH(SMALL('Mesários'!$J$2:$J$113,1),'Mesários'!$J$2:$J$113,0)),"") | D2: =IFERROR(CHOOSE(MATCH(INDEX('Mesários'!$I$2:$I$113,MATCH(SMALL('Mesários'!$J$2:$J$113,1),'Mesários'!$J$2:$J$113,0)),{"Confirmar","Não deve comparecer","Vago"},0),"Contatar para confirmar presença","Recrutar substituto","Recrutar mesário (função vaga)"),"")
A3: =IFERROR(INDEX('Mesários'!$A$2:$A$113,MATCH(SMALL('Mesários'!$J$2:$J$113,2),'Mesários'!$J$2:$J$113,0)),"") | B3: =IFERROR(INDEX('Mesários'!$B$2:$B$113,MATCH(SMALL('Mesários'!$J$2:$J$113,2),'Mesários'!$J$2:$J$113,0)),"") | C3: =IFERROR(INDEX('Mesários'!$C$2:$C$113,MATCH(SMALL('Mesários'!$J$2:$J$113,2),'Mesários'!$J$2:$J$113,0)),"") | D3: =IFERROR(CHOOSE(MATCH(INDEX('Mesários'!$I$2:$I$113,MATCH(SMALL('Mesários'!$J$2:$J$113,2),'Mesários'!$J$2:$J$113,0)),{"Confirmar","Não deve comparecer","Vago"},0),"Contatar para confirmar presença","Recrutar substituto","Recrutar mesário (função vaga)"),"")
A4: =IFERROR(INDEX('Mesários'!$A$2:$A$113,MATCH(SMALL('Mesários'!$J$2:$J$113,3),'Mesários'!$J$2:$J$113,0)),"") | B4: =IFERROR(INDEX('Mesários'!$B$2:$B$113,MATCH(SMALL('Mesários'!$J$2:$J$113,3),'Mesários'!$J$2:$J$113,0)),"") | C4: =IFERROR(INDEX('Mesários'!$C$2:$C$113,MATCH(SMALL('Mesários'!$J$2:$J$113,3),'Mesários'!$J$2:$J$113,0)),"") | D4: =IFERROR(CHOOSE(MATCH(INDEX('Mesários'!$I$2:$I$113,MATCH(SMALL('Mesários'!$J$2:$J$113,3),'Mesários'!$J$2:$J$113,0)),{"Confirmar","Não deve comparecer","Vago"},0),"Contatar para confirmar presença","Recrutar substituto","Recrutar mesário (função vaga)"),"")
A5: =IFERROR(INDEX('Mesários'!$A$2:$A$113,MATCH(SMALL('Mesários'!$J$2:$J$113,4),'Mesários'!$J$2:$J$113,0)),"") | B5: =IFERROR(INDEX('Mesários'!$B$2:$B$113,MATCH(SMALL('Mesários'!$J$2:$J$113,4),'Mesários'!$J$2:$J$113,0)),"") | C5: =IFERROR(INDEX('Mesários'!$C$2:$C$113,MATCH(SMALL('Mesários'!$J$2:$J$113,4),'Mesários'!$J$2:$J$113,0)),"") | D5: =IFERROR(CHOOSE(MATCH(INDEX('Mesários'!$I$2:$I$113,MATCH(SMALL('Mesários'!$J$2:$J$113,4),'Mesários'!$J$2:$J$113,0)),{"Confirmar","Não deve comparecer","Vago"},0),"Contatar para confirmar presença","Recrutar substituto","Recrutar mesário (função vaga)"),"")
A6: =IFERROR(INDEX('Mesários'!$A$2:$A$113,MATCH(SMALL('Mesários'!$J$2:$J$113,5),'Mesários'!$J$2:$J$113,0)),"") | B6: =IFERROR(INDEX('Mesários'!$B$2:$B$113,MATCH(SMALL('Mesários'!$J$2:$J$113,5),'Mesários'!$J$2:$J$113,0)),"") | C6: =IFERROR(INDEX('Mesários'!$C$2:$C$113,MATCH(SMALL('Mesários'!$J$2:$J$113,5),'Mesários'!$J$2:$J$113,0)),"") | D6: =IFERROR(CHOOSE(MATCH(INDEX('Mesários'!$I$2:$I$113,MATCH(SMALL('Mesários'!$J$2:$J$113,5),'Mesários'!$J$2:$J$113,0)),{"Confirmar","Não deve comparecer","Vago"},0),"Contatar para confirmar presença","Recrutar substituto","Recrutar mesário (função vaga)"),"")
A7: =IFERROR(INDEX('Mesários'!$A$2:$A$113,MATCH(SMALL('Mesários'!$J$2:$J$113,6),'Mesários'!$J$2:$J$113,0)),"") | B7: =IFERROR(INDEX('Mesários'!$B$2:$B$113,MATCH(SMALL('Mesários'!$J$2:$J$113,6),'Mesários'!$J$2:$J$113,0)),"") | C7: =IFERROR(INDEX('Mesários'!$C$2:$C$113,MATCH(SMALL('Mesários'!$J$2:$J$113,6),'Mesários'!$J$2:$J$113,0)),"") | D7: =IFERROR(CHOOSE(MATCH(INDEX('Mesários'!$I$2:$I$113,MATCH(SMALL('Mesários'!$J$2:$J$113,6),'Mesários'!$J$2:$J$113,0)),{"Confirmar","Não deve comparecer","Vago"},0),"Contatar para confirmar presença","Recrutar substituto","Recrutar mesário (função vaga)"),"")
A8: =IFERROR(INDEX('Mesários'!$A$2:$A$113,MATCH(SMALL('Mesários'!$J$2:$J$113,7),'Mesários'!$J$2:$J$113,0)),"") | B8: =IFERROR(INDEX('Mesários'!$B$2:$B$113,MATCH(SMALL('Mesários'!$J$2:$J$113,7),'Mesários'!$J$2:$J$113,0)),"") | C8: =IFERROR(INDEX('Mesários'!$C$2:$C$113,MATCH(SMALL('Mesários'!$J$2:$J$113,7),'Mesários'!$J$2:$J$113,0)),"") | D8: =IFERROR(CHOOSE(MATCH(INDEX('Mesários'!$I$2:$I$113,MATCH(SMALL('Mesários'!$J$2:$J$113,7),'Mesários'!$J$2:$J$113,0)),{"Confirmar","Não deve comparecer","Vago"},0),"Contatar para confirmar presença","Recrutar substituto","Recrutar mesário (função vaga)"),"")
A9: =IFERROR(INDEX('Mesários'!$A$2:$A$113,MATCH(SMALL('Mesários'!$J$2:$J$113,8),'Mesários'!$J$2:$J$113,0)),"") | B9: =IFERROR(INDEX('Mesários'!$B$2:$B$113,MATCH(SMALL('Mesários'!$J$2:$J$113,8),'Mesários'!$J$2:$J$113,0)),"") | C9: =IFERROR(INDEX('Mesários'!$C$2:$C$113,MATCH(SMALL('Mesários'!$J$2:$J$113,8),'Mesários'!$J$2:$J$113,0)),"") | D9: =IFERROR(CHOOSE(MATCH(INDEX('Mesários'!$I$2:$I$113,MATCH(SMALL('Mesários'!$J$2:$J$113,8),'Mesários'!$J$2:$J$113,0)),{"Confirmar","Não deve comparecer","Vago"},0),"Contatar para confirmar presença","Recrutar substituto","Recrutar mesário (função vaga)"),"")
A10: =IFERROR(INDEX('Mesários'!$A$2:$A$113,MATCH(SMALL('Mesários'!$J$2:$J$113,9),'Mesários'!$J$2:$J$113,0)),"") | B10: =IFERROR(INDEX('Mesários'!$B$2:$B$113,MATCH(SMALL('Mesários'!$J$2:$J$113,9),'Mesários'!$J$2:$J$113,0)),"") | C10: =IFERROR(INDEX('Mesários'!$C$2:$C$113,MATCH(SMALL('Mesários'!$J$2:$J$113,9),'Mesários'!$J$2:$J$113,0)),"") | D10: =IFERROR(CHOOSE(MATCH(INDEX('Mesários'!$I$2:$I$113,MATCH(SMALL('Mesários'!$J$2:$J$113,9),'Mesários'!$J$2:$J$113,0)),{"Confirmar","Não deve comparecer","Vago"},0),"Contatar para confirmar presença","Recrutar substituto","Recrutar mesário (função vaga)"),"")
A11: =IFERROR(INDEX('Mesários'!$A$2:$A$113,MATCH(SMALL('Mesários'!$J$2:$J$113,10),'Mesários'!$J$2:$J$113,0)),"") | B11: =IFERROR(INDEX('Mesários'!$B$2:$B$113,MATCH(SMALL('Mesários'!$J$2:$J$113,10),'Mesários'!$J$2:$J$113,0)),"") | C11: =IFERROR(INDEX('Mesários'!$C$2:$C$113,MATCH(SMALL('Mesários'!$J$2:$J$113,10),'Mesários'!$J$2:$J$113,0)),"") | D11: =IFERROR(CHOOSE(MATCH(INDEX('Mesários'!$I$2:$I$113,MATCH(SMALL('Mesários'!$J$2:$J$113,10),'Mesários'!$J$2:$J$113,0)),{"Confirmar","Não deve comparecer","Vago"},0),"Contatar para confirmar presença","Recrutar substituto","Recrutar mesário (função vaga)"),"")
A12: =IFERROR(INDEX('Mesários'!$A$2:$A$113,MATCH(SMALL('Mesários'!$J$2:$J$113,11),'Mesários'!$J$2:$J$113,0)),"") | B12: =IFERROR(INDEX('Mesários'!$B$2:$B$113,MATCH(SMALL('Mesários'!$J$2:$J$113,11),'Mesários'!$J$2:$J$113,0)),"") | C12: =IFERROR(INDEX('Mesários'!$C$2:$C$113,MATCH(SMALL('Mesários'!$J$2:$J$113,11),'Mesários'!$J$2:$J$113,0)),"") | D12: =IFERROR(CHOOSE(MATCH(INDEX('Mesários'!$I$2:$I$113,MATCH(SMALL('Mesários'!$J$2:$J$113,11),'Mesários'!$J$2:$J$113,0)),{"Confirmar","Não deve comparecer","Vago"},0),"Contatar para confirmar presença","Recrutar substituto","Recrutar mesário (função vaga)"),"")
A13: =IFERROR(INDEX('Mesários'!$A$2:$A$113,MATCH(SMALL('Mesários'!$J$2:$J$113,12),'Mesários'!$J$2:$J$113,0)),"") | B13: =IFERROR(INDEX('Mesários'!$B$2:$B$113,MATCH(SMALL('Mesários'!$J$2:$J$113,12),'Mesários'!$J$2:$J$113,0)),"") | C13: =IFERROR(INDEX('Mesários'!$C$2:$C$113,MATCH(SMALL('Mesários'!$J$2:$J$113,12),'Mesários'!$J$2:$J$113,0)),"") | D13: =IFERROR(CHOOSE(MATCH(INDEX('Mesários'!$I$2:$I$113,MATCH(SMALL('Mesários'!$J$2:$J$113,12),'Mesários'!$J$2:$J$113,0)),{"Confirmar","Não deve comparecer","Vago"},0),"Contatar para confirmar presença","Recrutar substituto","Recrutar mesário (função vaga)"),"")
A14: =IFERROR(INDEX('Mesários'!$A$2:$A$113,MATCH(SMALL('Mesários'!$J$2:$J$113,13),'Mesários'!$J$2:$J$113,0)),"") | B14: =IFERROR(INDEX('Mesários'!$B$2:$B$113,MATCH(SMALL('Mesários'!$J$2:$J$113,13),'Mesários'!$J$2:$J$113,0)),"") | C14: =IFERROR(INDEX('Mesários'!$C$2:$C$113,MATCH(SMALL('Mesários'!$J$2:$J$113,13),'Mesários'!$J$2:$J$113,0)),"") | D14: =IFERROR(CHOOSE(MATCH(INDEX('Mesários'!$I$2:$I$113,MATCH(SMALL('Mesários'!$J$2:$J$113,13),'Mesários'!$J$2:$J$113,0)),{"Confirmar","Não deve comparecer","Vago"},0),"Contatar para confirmar presença","Recrutar substituto","Recrutar mesário (função vaga)"),"")
A15: =IFERROR(INDEX('Mesários'!$A$2:$A$113,MATCH(SMALL('Mesários'!$J$2:$J$113,14),'Mesários'!$J$2:$J$113,0)),"") | B15: =IFERROR(INDEX('Mesários'!$B$2:$B$113,MATCH(SMALL('Mesários'!$J$2:$J$113,14),'Mesários'!$J$2:$J$113,0)),"") | C15: =IFERROR(INDEX('Mesários'!$C$2:$C$113,MATCH(SMALL('Mesários'!$J$2:$J$113,14),'Mesários'!$J$2:$J$113,0)),"") | D15: =IFERROR(CHOOSE(MATCH(INDEX('Mesários'!$I$2:$I$113,MATCH(SMALL('Mesários'!$J$2:$J$113,14),'Mesários'!$J$2:$J$113,0)),{"Confirmar","Não deve comparecer","Vago"},0),"Contatar para confirmar presença","Recrutar substituto","Recrutar mesário (função vaga)"),"")
A16: =IFERROR(INDEX('Mesários'!$A$2:$A$113,MATCH(SMALL('Mesários'!$J$2:$J$113,15),'Mesários'!$J$2:$J$113,0)),"") | B16: =IFERROR(INDEX('Mesários'!$B$2:$B$113,MATCH(SMALL('Mesários'!$J$2:$J$113,15),'Mesários'!$J$2:$J$113,0)),"") | C16: =IFERROR(INDEX('Mesários'!$C$2:$C$113,MATCH(SMALL('Mesários'!$J$2:$J$113,15),'Mesários'!$J$2:$J$113,0)),"") | D16: =IFERROR(CHOOSE(MATCH(INDEX('Mesários'!$I$2:$I$113,MATCH(SMALL('Mesários'!$J$2:$J$113,15),'Mesários'!$J$2:$J$113,0)),{"Confirmar","Não deve comparecer","Vago"},0),"Contatar para confirmar presença","Recrutar substituto","Recrutar mesário (função vaga)"),"")
A17: =IFERROR(INDEX('Mesários'!$A$2:$A$113,MATCH(SMALL('Mesários'!$J$2:$J$113,16),'Mesários'!$J$2:$J$113,0)),"") | B17: =IFERROR(INDEX('Mesários'!$B$2:$B$113,MATCH(SMALL('Mesários'!$J$2:$J$113,16),'Mesários'!$J$2:$J$113,0)),"") | C17: =IFERROR(INDEX('Mesários'!$C$2:$C$113,MATCH(SMALL('Mesários'!$J$2:$J$113,16),'Mesários'!$J$2:$J$113,0)),"") | D17: =IFERROR(CHOOSE(MATCH(INDEX('Mesários'!$I$2:$I$113,MATCH(SMALL('Mesários'!$J$2:$J$113,16),'Mesários'!$J$2:$J$113,0)),{"Confirmar","Não deve comparecer","Vago"},0),"Contatar para confirmar presença","Recrutar substituto","Recrutar mesário (função vaga)"),"")
A18: =IFERROR(INDEX('Mesários'!$A$2:$A$113,MATCH(SMALL('Mesários'!$J$2:$J$113,17),'Mesários'!$J$2:$J$113,0)),"") | B18: =IFERROR(INDEX('Mesários'!$B$2:$B$113,MATCH(SMALL('Mesários'!$J$2:$J$113,17),'Mesários'!$J$2:$J$113,0)),"") | C18: =IFERROR(INDEX('Mesários'!$C$2:$C$113,MATCH(SMALL('Mesários'!$J$2:$J$113,17),'Mesários'!$J$2:$J$113,0)),"") | D18: =IFERROR(CHOOSE(MATCH(INDEX('Mesários'!$I$2:$I$113,MATCH(SMALL('Mesários'!$J$2:$J$113,17),'Mesários'!$J$2:$J$113,0)),{"Confirmar","Não deve comparecer","Vago"},0),"Contatar para confirmar presença","Recrutar substituto","Recrutar mesário (função vaga)"),"")
A19: =IFERROR(INDEX('Mesários'!$A$2:$A$113,MATCH(SMALL('Mesários'!$J$2:$J$113,18),'Mesários'!$J$2:$J$113,0)),"") | B19: =IFERROR(INDEX('Mesários'!$B$2:$B$113,MATCH(SMALL('Mesários'!$J$2:$J$113,18),'Mesários'!$J$2:$J$113,0)),"") | C19: =IFERROR(INDEX('Mesários'!$C$2:$C$113,MATCH(SMALL('Mesários'!$J$2:$J$113,18),'Mesários'!$J$2:$J$113,0)),"") | D19: =IFERROR(CHOOSE(MATCH(INDEX('Mesários'!$I$2:$I$113,MATCH(SMALL('Mesários'!$J$2:$J$113,18),'Mesários'!$J$2:$J$113,0)),{"Confirmar","Não deve comparecer","Vago"},0),"Contatar para confirmar presença","Recrutar substituto","Recrutar mesário (função vaga)"),"")
A20: =IFERROR(INDEX('Mesários'!$A$2:$A$113,MATCH(SMALL('Mesários'!$J$2:$J$113,19),'Mesários'!$J$2:$J$113,0)),"") | B20: =IFERROR(INDEX('Mesários'!$B$2:$B$113,MATCH(SMALL('Mesários'!$J$2:$J$113,19),'Mesários'!$J$2:$J$113,0)),"") | C20: =IFERROR(INDEX('Mesários'!$C$2:$C$113,MATCH(SMALL('Mesários'!$J$2:$J$113,19),'Mesários'!$J$2:$J$113,0)),"") | D20: =IFERROR(CHOOSE(MATCH(INDEX('Mesários'!$I$2:$I$113,MATCH(SMALL('Mesários'!$J$2:$J$113,19),'Mesários'!$J$2:$J$113,0)),{"Confirmar","Não deve comparecer","Vago"},0),"Contatar para confirmar presença","Recrutar substituto","Recrutar mesário (função vaga)"),"")
A21: =IFERROR(INDEX('Mesários'!$A$2:$A$113,MATCH(SMALL('Mesários'!$J$2:$J$113,20),'Mesários'!$J$2:$J$113,0)),"") | B21: =IFERROR(INDEX('Mesários'!$B$2:$B$113,MATCH(SMALL('Mesários'!$J$2:$J$113,20),'Mesários'!$J$2:$J$113,0)),"") | C21: =IFERROR(INDEX('Mesários'!$C$2:$C$113,MATCH(SMALL('Mesários'!$J$2:$J$113,20),'Mesários'!$J$2:$J$113,0)),"") | D21: =IFERROR(CHOOSE(MATCH(INDEX('Mesários'!$I$2:$I$113,MATCH(SMALL('Mesários'!$J$2:$J$113,20),'Mesários'!$J$2:$J$113,0)),{"Confirmar","Não deve comparecer","Vago"},0),"Contatar para confirmar presença","Recrutar substituto","Recrutar mesário (função vaga)"),"")
A22: =IFERROR(INDEX('Mesários'!$A$2:$A$113,MATCH(SMALL('Mesários'!$J$2:$J$113,21),'Mesários'!$J$2:$J$113,0)),"") | B22: =IFERROR(INDEX('Mesários'!$B$2:$B$113,MATCH(SMALL('Mesários'!$J$2:$J$113,21),'Mesários'!$J$2:$J$113,0)),"") | C22: =IFERROR(INDEX('Mesários'!$C$2:$C$113,MATCH(SMALL('Mesários'!$J$2:$J$113,21),'Mesários'!$J$2:$J$113,0)),"") | D22: =IFERROR(CHOOSE(MATCH(INDEX('Mesários'!$I$2:$I$113,MATCH(SMALL('Mesários'!$J$2:$J$113,21),'Mesários'!$J$2:$J$113,0)),{"Confirmar","Não deve comparecer","Vago"},0),"Contatar para confirmar presença","Recrutar substituto","Recrutar mesário (função vaga)"),"")
A23: =IFERROR(INDEX('Mesários'!$A$2:$A$113,MATCH(SMALL('Mesários'!$J$2:$J$113,22),'Mesários'!$J$2:$J$113,0)),"") | B23: =IFERROR(INDEX('Mesários'!$B$2:$B$113,MATCH(SMALL('Mesários'!$J$2:$J$113,22),'Mesários'!$J$2:$J$113,0)),"") | C23: =IFERROR(INDEX('Mesários'!$C$2:$C$113,MATCH(SMALL('Mesários'!$J$2:$J$113,22),'Mesários'!$J$2:$J$113,0)),"") | D23: =IFERROR(CHOOSE(MATCH(INDEX('Mesários'!$I$2:$I$113,MATCH(SMALL('Mesários'!$J$2:$J$113,22),'Mesários'!$J$2:$J$113,0)),{"Confirmar","Não deve comparecer","Vago"},0),"Contatar para confirmar presença","Recrutar substituto","Recrutar mesário (função vaga)"),"")
A24: =IFERROR(INDEX('Mesários'!$A$2:$A$113,MATCH(SMALL('Mesários'!$J$2:$J$113,23),'Mesários'!$J$2:$J$113,0)),"") | B24: =IFERROR(INDEX('Mesários'!$B$2:$B$113,MATCH(SMALL('Mesários'!$J$2:$J$113,23),'Mesários'!$J$2:$J$113,0)),"") | C24: =IFERROR(INDEX('Mesários'!$C$2:$C$113,MATCH(SMALL('Mesários'!$J$2:$J$113,23),'Mesários'!$J$2:$J$113,0)),"") | D24: =IFERROR(CHOOSE(MATCH(INDEX('Mesários'!$I$2:$I$113,MATCH(SMALL('Mesários'!$J$2:$J$113,23),'Mesários'!$J$2:$J$113,0)),{"Confirmar","Não deve comparecer","Vago"},0),"Contatar para confirmar presença","Recrutar substituto","Recrutar mesário (função vaga)"),"")
A25: =IFERROR(INDEX('Mesários'!$A$2:$A$113,MATCH(SMALL('Mesários'!$J$2:$J$113,24),'Mesários'!$J$2:$J$113,0)),"") | B25: =IFERROR(INDEX('Mesários'!$B$2:$B$113,MATCH(SMALL('Mesários'!$J$2:$J$113,24),'Mesários'!$J$2:$J$113,0)),"") | C25: =IFERROR(INDEX('Mesários'!$C$2:$C$113,MATCH(SMALL('Mesários'!$J$2:$J$113,24),'Mesários'!$J$2:$J$113,0)),"") | D25: =IFERROR(CHOOSE(MATCH(INDEX('Mesários'!$I$2:$I$113,MATCH(SMALL('Mesários'!$J$2:$J$113,24),'Mesários'!$J$2:$J$113,0)),{"Confirmar","Não deve comparecer","Vago"},0),"Contatar para confirmar presença","Recrutar substituto","Recrutar mesário (função vaga)"),"")
A26: =IFERROR(INDEX('Mesários'!$A$2:$A$113,MATCH(SMALL('Mesários'!$J$2:$J$113,25),'Mesários'!$J$2:$J$113,0)),"") | B26: =IFERROR(INDEX('Mesários'!$B$2:$B$113,MATCH(SMALL('Mesários'!$J$2:$J$113,25),'Mesários'!$J$2:$J$113,0)),"") | C26: =IFERROR(INDEX('Mesários'!$C$2:$C$113,MATCH(SMALL('Mesários'!$J$2:$J$113,25),'Mesários'!$J$2:$J$113,0)),"") | D26: =IFERROR(CHOOSE(MATCH(INDEX('Mesários'!$I$2:$I$113,MATCH(SMALL('Mesários'!$J$2:$J$113,25),'Mesários'!$J$2:$J$113,0)),{"Confirmar","Não deve comparecer","Vago"},0),"Contatar para confirmar presença","Recrutar substituto","Recrutar mesário (função vaga)"),"")
A27: =IFERROR(INDEX('Mesários'!$A$2:$A$113,MATCH(SMALL('Mesários'!$J$2:$J$113,26),'Mesários'!$J$2:$J$113,0)),"") | B27: =IFERROR(INDEX('Mesários'!$B$2:$B$113,MATCH(SMALL('Mesários'!$J$2:$J$113,26),'Mesários'!$J$2:$J$113,0)),"") | C27: =IFERROR(INDEX('Mesários'!$C$2:$C$113,MATCH(SMALL('Mesários'!$J$2:$J$113,26),'Mesários'!$J$2:$J$113,0)),"") | D27: =IFERROR(CHOOSE(MATCH(INDEX('Mesários'!$I$2:$I$113,MATCH(SMALL('Mesários'!$J$2:$J$113,26),'Mesários'!$J$2:$J$113,0)),{"Confirmar","Não deve comparecer","Vago"},0),"Contatar para confirmar presença","Recrutar substituto","Recrutar mesário (função vaga)"),"")
A28: =IFERROR(INDEX('Mesários'!$A$2:$A$113,MATCH(SMALL('Mesários'!$J$2:$J$113,27),'Mesários'!$J$2:$J$113,0)),"") | B28: =IFERROR(INDEX('Mesários'!$B$2:$B$113,MATCH(SMALL('Mesários'!$J$2:$J$113,27),'Mesários'!$J$2:$J$113,0)),"") | C28: =IFERROR(INDEX('Mesários'!$C$2:$C$113,MATCH(SMALL('Mesários'!$J$2:$J$113,27),'Mesários'!$J$2:$J$113,0)),"") | D28: =IFERROR(CHOOSE(MATCH(INDEX('Mesários'!$I$2:$I$113,MATCH(SMALL('Mesários'!$J$2:$J$113,27),'Mesários'!$J$2:$J$113,0)),{"Confirmar","Não deve comparecer","Vago"},0),"Contatar para confirmar presença","Recrutar substituto","Recrutar mesário (função vaga)"),"")
A29: =IFERROR(INDEX('Mesários'!$A$2:$A$113,MATCH(SMALL('Mesários'!$J$2:$J$113,28),'Mesários'!$J$2:$J$113,0)),"") | B29: =IFERROR(INDEX('Mesários'!$B$2:$B$113,MATCH(SMALL('Mesários'!$J$2:$J$113,28),'Mesários'!$J$2:$J$113,0)),"") | C29: =IFERROR(INDEX('Mesários'!$C$2:$C$113,MATCH(SMALL('Mesários'!$J$2:$J$113,28),'Mesários'!$J$2:$J$113,0)),"") | D29: =IFERROR(CHOOSE(MATCH(INDEX('Mesários'!$I$2:$I$113,MATCH(SMALL('Mesários'!$J$2:$J$113,28),'Mesários'!$J$2:$J$113,0)),{"Confirmar","Não deve comparecer","Vago"},0),"Contatar para confirmar presença","Recrutar substituto","Recrutar mesário (função vaga)"),"")
A30: =IFERROR(INDEX('Mesários'!$A$2:$A$113,MATCH(SMALL('Mesários'!$J$2:$J$113,29),'Mesários'!$J$2:$J$113,0)),"") | B30: =IFERROR(INDEX('Mesários'!$B$2:$B$113,MATCH(SMALL('Mesários'!$J$2:$J$113,29),'Mesários'!$J$2:$J$113,0)),"") | C30: =IFERROR(INDEX('Mesários'!$C$2:$C$113,MATCH(SMALL('Mesários'!$J$2:$J$113,29),'Mesários'!$J$2:$J$113,0)),"") | D30: =IFERROR(CHOOSE(MATCH(INDEX('Mesários'!$I$2:$I$113,MATCH(SMALL('Mesários'!$J$2:$J$113,29),'Mesários'!$J$2:$J$113,0)),{"Confirmar","Não deve comparecer","Vago"},0),"Contatar para confirmar presença","Recrutar substituto","Recrutar mesário (função vaga)"),"")
A31: =IFERROR(INDEX('Mesários'!$A$2:$A$113,MATCH(SMALL('Mesários'!$J$2:$J$113,30),'Mesários'!$J$2:$J$113,0)),"") | B31: =IFERROR(INDEX('Mesários'!$B$2:$B$113,MATCH(SMALL('Mesários'!$J$2:$J$113,30),'Mesários'!$J$2:$J$113,0)),"") | C31: =IFERROR(INDEX('Mesários'!$C$2:$C$113,MATCH(SMALL('Mesários'!$J$2:$J$113,30),'Mesários'!$J$2:$J$113,0)),"") | D31: =IFERROR(CHOOSE(MATCH(INDEX('Mesários'!$I$2:$I$113,MATCH(SMALL('Mesários'!$J$2:$J$113,30),'Mesários'!$J$2:$J$113,0)),{"Confirmar","Não deve comparecer","Vago"},0),"Contatar para confirmar presença","Recrutar substituto","Recrutar mesário (função vaga)"),"")
A32: =IFERROR(INDEX('Mesários'!$A$2:$A$113,MATCH(SMALL('Mesários'!$J$2:$J$113,31),'Mesários'!$J$2:$J$113,0)),"") | B32: =IFERROR(INDEX('Mesários'!$B$2:$B$113,MATCH(SMALL('Mesários'!$J$2:$J$113,31),'Mesários'!$J$2:$J$113,0)),"") | C32: =IFERROR(INDEX('Mesários'!$C$2:$C$113,MATCH(SMALL('Mesários'!$J$2:$J$113,31),'Mesários'!$J$2:$J$113,0)),"") | D32: =IFERROR(CHOOSE(MATCH(INDEX('Mesários'!$I$2:$I$113,MATCH(SMALL('Mesários'!$J$2:$J$113,31),'Mesários'!$J$2:$J$113,0)),{"Confirmar","Não deve comparecer","Vago"},0),"Contatar para confirmar presença","Recrutar substituto","Recrutar mesário (função vaga)"),"")
A33: =IFERROR(INDEX('Mesários'!$A$2:$A$113,MATCH(SMALL('Mesários'!$J$2:$J$113,32),'Mesários'!$J$2:$J$113,0)),"") | B33: =IFERROR(INDEX('Mesários'!$B$2:$B$113,MATCH(SMALL('Mesários'!$J$2:$J$113,32),'Mesários'!$J$2:$J$113,0)),"") | C33: =IFERROR(INDEX('Mesários'!$C$2:$C$113,MATCH(SMALL('Mesários'!$J$2:$J$113,32),'Mesários'!$J$2:$J$113,0)),"") | D33: =IFERROR(CHOOSE(MATCH(INDEX('Mesários'!$I$2:$I$113,MATCH(SMALL('Mesários'!$J$2:$J$113,32),'Mesários'!$J$2:$J$113,0)),{"Confirmar","Não deve comparecer","Vago"},0),"Contatar para confirmar presença","Recrutar substituto","Recrutar mesário (função vaga)"),"")
A34: =IFERROR(INDEX('Mesários'!$A$2:$A$113,MATCH(SMALL('Mesários'!$J$2:$J$113,33),'Mesários'!$J$2:$J$113,0)),"") | B34: =IFERROR(INDEX('Mesários'!$B$2:$B$113,MATCH(SMALL('Mesários'!$J$2:$J$113,33),'Mesários'!$J$2:$J$113,0)),"") | C34: =IFERROR(INDEX('Mesários'!$C$2:$C$113,MATCH(SMALL('Mesários'!$J$2:$J$113,33),'Mesários'!$J$2:$J$113,0)),"") | D34: =IFERROR(CHOOSE(MATCH(INDEX('Mesários'!$I$2:$I$113,MATCH(SMALL('Mesários'!$J$2:$J$113,33),'Mesários'!$J$2:$J$113,0)),{"Confirmar","Não deve comparecer","Vago"},0),"Contatar para confirmar presença","Recrutar substituto","Recrutar mesário (função vaga)"),"")
A35: =IFERROR(INDEX('Mesários'!$A$2:$A$113,MATCH(SMALL('Mesários'!$J$2:$J$113,34),'Mesários'!$J$2:$J$113,0)),"") | B35: =IFERROR(INDEX('Mesários'!$B$2:$B$113,MATCH(SMALL('Mesários'!$J$2:$J$113,34),'Mesários'!$J$2:$J$113,0)),"") | C35: =IFERROR(INDEX('Mesários'!$C$2:$C$113,MATCH(SMALL('Mesários'!$J$2:$J$113,34),'Mesários'!$J$2:$J$113,0)),"") | D35: =IFERROR(CHOOSE(MATCH(INDEX('Mesários'!$I$2:$I$113,MATCH(SMALL('Mesários'!$J$2:$J$113,34),'Mesários'!$J$2:$J$113,0)),{"Confirmar","Não deve comparecer","Vago"},0),"Contatar para confirmar presença","Recrutar substituto","Recrutar mesário (função vaga)"),"")
A36: =IFERROR(INDEX('Mesários'!$A$2:$A$113,MATCH(SMALL('Mesários'!$J$2:$J$113,35),'Mesários'!$J$2:$J$113,0)),"") | B36: =IFERROR(INDEX('Mesários'!$B$2:$B$113,MATCH(SMALL('Mesários'!$J$2:$J$113,35),'Mesários'!$J$2:$J$113,0)),"") | C36: =IFERROR(INDEX('Mesários'!$C$2:$C$113,MATCH(SMALL('Mesários'!$J$2:$J$113,35),'Mesários'!$J$2:$J$113,0)),"") | D36: =IFERROR(CHOOSE(MATCH(INDEX('Mesários'!$I$2:$I$113,MATCH(SMALL('Mesários'!$J$2:$J$113,35),'Mesários'!$J$2:$J$113,0)),{"Confirmar","Não deve comparecer","Vago"},0),"Contatar para confirmar presença","Recrutar substituto","Recrutar mesário (função vaga)"),"")
A37: =IFERROR(INDEX('Mesários'!$A$2:$A$113,MATCH(SMALL('Mesários'!$J$2:$J$113,36),'Mesários'!$J$2:$J$113,0)),"") | B37: =IFERROR(INDEX('Mesários'!$B$2:$B$113,MATCH(SMALL('Mesários'!$J$2:$J$113,36),'Mesários'!$J$2:$J$113,0)),"") | C37: =IFERROR(INDEX('Mesários'!$C$2:$C$113,MATCH(SMALL('Mesários'!$J$2:$J$113,36),'Mesários'!$J$2:$J$113,0)),"") | D37: =IFERROR(CHOOSE(MATCH(INDEX('Mesários'!$I$2:$I$113,MATCH(SMALL('Mesários'!$J$2:$J$113,36),'Mesários'!$J$2:$J$113,0)),{"Confirmar","Não deve comparecer","Vago"},0),"Contatar para confirmar presença","Recrutar substituto","Recrutar mesário (função vaga)"),"")
A38: =IFERROR(INDEX('Mesários'!$A$2:$A$113,MATCH(SMALL('Mesários'!$J$2:$J$113,37),'Mesários'!$J$2:$J$113,0)),"") | B38: =IFERROR(INDEX('Mesários'!$B$2:$B$113,MATCH(SMALL('Mesários'!$J$2:$J$113,37),'Mesários'!$J$2:$J$113,0)),"") | C38: =IFERROR(INDEX('Mesários'!$C$2:$C$113,MATCH(SMALL('Mesários'!$J$2:$J$113,37),'Mesários'!$J$2:$J$113,0)),"") | D38: =IFERROR(CHOOSE(MATCH(INDEX('Mesários'!$I$2:$I$113,MATCH(SMALL('Mesários'!$J$2:$J$113,37),'Mesários'!$J$2:$J$113,0)),{"Confirmar","Não deve comparecer","Vago"},0),"Contatar para confirmar presença","Recrutar substituto","Recrutar mesário (função vaga)"),"")
A39: =IFERROR(INDEX('Mesários'!$A$2:$A$113,MATCH(SMALL('Mesários'!$J$2:$J$113,38),'Mesários'!$J$2:$J$113,0)),"") | B39: =IFERROR(INDEX('Mesários'!$B$2:$B$113,MATCH(SMALL('Mesários'!$J$2:$J$113,38),'Mesários'!$J$2:$J$113,0)),"") | C39: =IFERROR(INDEX('Mesários'!$C$2:$C$113,MATCH(SMALL('Mesários'!$J$2:$J$113,38),'Mesários'!$J$2:$J$113,0)),"") | D39: =IFERROR(CHOOSE(MATCH(INDEX('Mesários'!$I$2:$I$113,MATCH(SMALL('Mesários'!$J$2:$J$113,38),'Mesários'!$J$2:$J$113,0)),{"Confirmar","Não deve comparecer","Vago"},0),"Contatar para confirmar presença","Recrutar substituto","Recrutar mesário (função vaga)"),"")
A40: =IFERROR(INDEX('Mesários'!$A$2:$A$113,MATCH(SMALL('Mesários'!$J$2:$J$113,39),'Mesários'!$J$2:$J$113,0)),"") | B40: =IFERROR(INDEX('Mesários'!$B$2:$B$113,MATCH(SMALL('Mesários'!$J$2:$J$113,39),'Mesários'!$J$2:$J$113,0)),"") | C40: =IFERROR(INDEX('Mesários'!$C$2:$C$113,MATCH(SMALL('Mesários'!$J$2:$J$113,39),'Mesários'!$J$2:$J$113,0)),"") | D40: =IFERROR(CHOOSE(MATCH(INDEX('Mesários'!$I$2:$I$113,MATCH(SMALL('Mesários'!$J$2:$J$113,39),'Mesários'!$J$2:$J$113,0)),{"Confirmar","Não deve comparecer","Vago"},0),"Contatar para confirmar presença","Recrutar substituto","Recrutar mesário (função vaga)"),"")
...

Sheet Por seção
A1: Seção | B1: Aptos (BU) | C1: Comparecimento efetivo (BU) | D1: Posição (efetivo) | E1: Faixa efetiva
A2: 3315 | B2: 790 | C2: 536 | D2: 1 | E2: Alto
A3: 3322 | B3: 792 | C3: 503 | D3: 2 | E3: Alto
A4: 3313 | B4: 792 | C4: 492 | D4: 3 | E4: Alto
A5: 3311 | B5: 626 | C5: 384 | D5: 4 | E5: Médio
A6: 3302 | B6: 763 | C6: 373 | D6: 5 | E6: Médio
A7: 3179 | B7: 670 | C7: 349 | D7: 6 | E7: Médio
A8: 3306 | B8: 761 | C8: 345 | D8: 7 | E8: Médio
A9: 3161 | B9: 787 | C9: 328 | D9: 8 | E9: Baixo
A10: 3245 | B10: 778 | C10: 322 | D10: 9 | E10: Baixo
A11: 3108 | B11: 752 | C11: 320 | D11: 10 | E11: Baixo
A12: 3142 | B12: 787 | C12: 318 | D12: 11 | E12: Baixo
A13: 3229 | B13: 601 | C13: 318 | D13: 12 | E13: Baixo
... A29: 3442 | B29: 397 | C29: 134 | D29: 28 | E29: Baixo
A31: Boletins de Urna do 1º turno (04/10/2026), da aba 'Por secao' de 2026.10.12_Mesários_Seções_Atualizadas. Posição = ordem pelo comparecimento efetivo. Faixa efetiva: as 3 maiores = Alto; efetivo ≥ 329 = Médio; abaixo = Baixo. A posição define a ordem da aba 'Funções a preencher'.
